Workbook

Sheet Jan
B1: ='[1]Dia 1 (b)'!C1 -> JANEIRO DE 2024 | K1: Umid. Específica (g.kg-1)
A3: H/D | B3: 1 | C3: 2 | D3: 3 | E3: 4 | F3: 5 | G3: 6 | H3: 7 | I3: 8 | J3: 9 | K3: 10 | L3: 11 | M3: 12 | N3: 13 | O3: 14 | P3: 15 | Q3: 16 | R3: 17 | S3: 18 | T3: 19 | U3: 20 | V3: 21 | W3: 22 | X3: 23 | Y3: 24 | Z3: 25 | AA3: 26 | AB3: 27 | AC3: 28 | AD3: 29 | AE3: 30 | AF3: 31
A4: 1
A5: 2
A6: 3
A7: 4
A8: 5
A9: 6
A10: 7 | B10: ='[1]Dia 1 (b)'!$X16 -> 12.027927 | C10: ='[1]Dia 2 (b)'!$X16 -> 12.89845 | D10: ='[1]Dia 3 (b)'!$X16 -> 15.31981 | E10: ='[1]Dia 4 (b)'!$X16 -> 15.164382 | F10: ='[1]Dia 5 (b)'!$X16 -> 14.866126 | G10: ='[1]Dia 6 (b)'!$X16 -> 14.222854 | H10: ='[1]Dia 7 (b)'!$X16 -> 14.198265 | I10: ='[1]Dia 8 (b)'!$X16 -> 16.224168 | J10: ='[1]Dia 9 (b)'!$X16 -> 16.566283 | K10: ='[1]Dia 10 (b)'!$X16 -> 16.489606 | L10: ='[1]Dia 11 (b)'!$X16 -> 16.741624 | M10: ='[1]Dia 12 (b)'!$X16 -> 16.957825 | N10: ='[1]Dia 13 (b)'!$X16 -> 15.489896 | O10: ='[1]Dia 14 (b)'!$X16 -> 13.138849 | P10: ='[1]Dia 15 (b)'!$X16 -> 17.846404 | Q10: ='[1]Dia 16 (b)'!$X16 -> 16.460523 | R10: ='[1]Dia 17 (b)'!$X16 -> 17.797551 | S10: ='[1]Dia 18 (b)'!$X16 -> 17.276124 | T10: ='[1]Dia 19 (b)'!$X16 -> 14.806554 | U10: ='[1]Dia 20 (b)'!$X16 -> 15.12387 | V10: ='[1]Dia 21 (b)'!$X16 -> 15.809028 | W10: ='[1]Dia 22 (b)'!$X16 -> 14.751695 | X10: ='[1]Dia 23 (b)'!$X16 -> 13.255763 | Y10: ='[1]Dia 24 (b)'!$X16 -> 12.241676 | Z10: ='[1]Dia 25 (b)'!$X16 -> 12.992008 | AA10: ='[1]Dia 26 (b)'!$X16 -> 11.890605 | AB10: ='[1]Dia 27 (b)'!$X16 -> 13.868937 | AC10: ='[1]Dia 28 (b)'!$X16 -> 14.178068 | AD10: ='[1]Dia 29 (b)'!$X16 -> 13.465432 | AE10: ='[1]Dia 30 (b)'!$X16 -> 15.376298 | AF10: ='[1]Dia 31 (b)'!$X16 -> 15.12302
A11: 8 | B11: ='[1]Dia 1 (b)'!$X17 -> 12.490845 | C11: ='[1]Dia 2 (b)'!$X17 -> 12.87485 | D11: ='[1]Dia 3 (b)'!$X17 -> 15.628435 | E11: ='[1]Dia 4 (b)'!$X17 -> 15.652118 | F11: ='[1]Dia 5 (b)'!$X17 -> 14.756437 | G11: ='[1]Dia 6 (b)'!$X17 -> 13.661778 | H11: ='[1]Dia 7 (b)'!$X17 -> 14.473832 | I11: ='[1]Dia 8 (b)'!$X17 -> 15.417817 | J11: ='[1]Dia 9 (b)'!$X17 -> 15.444797 | K11: ='[1]Dia 10 (b)'!$X17 -> 15.931346 | L11: ='[1]Dia 11 (b)'!$X17 -> 17.316516 | M11: ='[1]Dia 12 (b)'!$X17 -> 16.990957 | N11: ='[1]Dia 13 (b)'!$X17 -> 15.986338 | O11: ='[1]Dia 14 (b)'!$X17 -> 13.174783 | P11: ='[1]Dia 15 (b)'!$X17 -> 16.54757 | Q11: ='[1]Dia 16 (b)'!$X17 -> 16.084215 | R11: ='[1]Dia 17 (b)'!$X17 -> 16.773583 | S11: ='[1]Dia 18 (b)'!$X17 -> 17.389222 | T11: ='[1]Dia 19 (b)'!$X17 -> 14.260272 | U11: ='[1]Dia 20 (b)'!$X17 -> 15.411702 | V11: ='[1]Dia 21 (b)'!$X17 -> 15.397807 | W11: ='[1]Dia 22 (b)'!$X17 -> 14.704821 | X11: ='[1]Dia 23 (b)'!$X17 -> 13.514489 | Y11: ='[1]Dia 24 (b)'!$X17 -> 12.646397 | Z11: ='[1]Dia 25 (b)'!$X17 -> 13.156866 | AA11: ='[1]Dia 26 (b)'!$X17 -> 12.287647 | AB11: ='[1]Dia 27 (b)'!$X17 -> 13.921879 | AC11: ='[1]Dia 28 (b)'!$X17 -> 13.926699 | AD11: ='[1]Dia 29 (b)'!$X17 -> 13.118798 | AE11: ='[1]Dia 30 (b)'!$X17 -> 14.467559 | AF11: ='[1]Dia 31 (b)'!$X17 -> 14.974339
A12: 9 | B12: ='[1]Dia 1 (b)'!$X18 -> 12.150237 | C12: ='[1]Dia 2 (b)'!$X18 -> 13.129177 | D12: ='[1]Dia 3 (b)'!$X18 -> 15.582 | E12: ='[1]Dia 4 (b)'!$X18 -> 15.965439 | F12: ='[1]Dia 5 (b)'!$X18 -> 15.12344 | G12: ='[1]Dia 6 (b)'!$X18 -> 14.578493 | H12: ='[1]Dia 7 (b)'!$X18 -> 14.328502 | I12: ='[1]Dia 8 (b)'!$X18 -> 14.86156 | J12: ='[1]Dia 9 (b)'!$X18 -> 15.713409 | K12: ='[1]Dia 10 (b)'!$X18 -> 15.724977 | L12: ='[1]Dia 11 (b)'!$X18 -> 16.646669 | M12: ='[1]Dia 12 (b)'!$X18 -> 16.64589 | N12: ='[1]Dia 13 (b)'!$X18 -> 16.195588 | O12: ='[1]Dia 14 (b)'!$X18 -> 13.655604 | P12: ='[1]Dia 15 (b)'!$X18 -> 17.163899 | Q12: ='[1]Dia 16 (b)'!$X18 -> 15.908222 | R12: ='[1]Dia 17 (b)'!$X18 -> 17.245018 | S12: ='[1]Dia 18 (b)'!$X18 -> 17.329183 | T12: ='[1]Dia 19 (b)'!$X18 -> 14.208808 | U12: ='[1]Dia 20 (b)'!$X18 -> 15.44785 | V12: ='[1]Dia 21 (b)'!$X18 -> 15.67244 | W12: ='[1]Dia 22 (b)'!$X18 -> 15.34081 | X12: ='[1]Dia 23 (b)'!$X18 -> 13.853758 | Y12: ='[1]Dia 24 (b)'!$X18 -> 12.574703 | Z12: ='[1]Dia 25 (b)'!$X18 -> 13.773572 | AA12: ='[1]Dia 26 (b)'!$X18 -> 12.653571 | AB12: ='[1]Dia 27 (b)'!$X18 -> 13.893056 | AC12: ='[1]Dia 28 (b)'!$X18 -> 13.732439 | AD12: ='[1]Dia 29 (b)'!$X18 -> 12.945607 | AE12: ='[1]Dia 30 (b)'!$X18 -> 12.769801 | AF12: ='[1]Dia 31 (b)'!$X18 -> 14.689776
A13: 10 | B13: ='[1]Dia 1 (b)'!$X19 -> 12.461852 | C13: ='[1]Dia 2 (b)'!$X19 -> 13.156931 | D13: ='[1]Dia 3 (b)'!$X19 -> 15.462001 | E13: ='[1]Dia 4 (b)'!$X19 -> 16.288491 | F13: ='[1]Dia 5 (b)'!$X19 -> 14.945193 | G13: ='[1]Dia 6 (b)'!$X19 -> 13.976742 | H13: ='[1]Dia 7 (b)'!$X19 -> 14.137882 | I13: ='[1]Dia 8 (b)'!$X19 -> 13.88572 | J13: ='[1]Dia 9 (b)'!$X19 -> 14.934641 | K13: ='[1]Dia 10 (b)'!$X19 -> 14.925349 | L13: ='[1]Dia 11 (b)'!$X19 -> 16.126699 | M13: ='[1]Dia 12 (b)'!$X19 -> 16.444291 | N13: ='[1]Dia 13 (b)'!$X19 -> 15.288028 | O13: ='[1]Dia 14 (b)'!$X19 -> 14.375978 | P13: ='[1]Dia 15 (b)'!$X19 -> 16.577584 | Q13: ='[1]Dia 16 (b)'!$X19 -> 15.37748 | R13: ='[1]Dia 17 (b)'!$X19 -> 16.14258 | S13: ='[1]Dia 18 (b)'!$X19 -> 16.807754 | T13: ='[1]Dia 19 (b)'!$X19 -> 15.088187 | U13: ='[1]Dia 20 (b)'!$X19 -> 16.481395 | V13: ='[1]Dia 21 (b)'!$X19 -> 15.207773 | W13: ='[1]Dia 22 (b)'!$X19 -> 14.316622 | X13: ='[1]Dia 23 (b)'!$X19 -> 14.117833 | Y13: ='[1]Dia 24 (b)'!$X19 -> 12.704896 | Z13: ='[1]Dia 25 (b)'!$X19 -> 14.976481 | AA13: ='[1]Dia 26 (b)'!$X19 -> 12.954172 | AB13: ='[1]Dia 27 (b)'!$X19 -> 13.866049 | AC13: ='[1]Dia 28 (b)'!$X19 -> 14.023441 | AD13: ='[1]Dia 29 (b)'!$X19 -> 12.923704 | AE13: ='[1]Dia 30 (b)'!$X19 -> 11.974305 | AF13: ='[1]Dia 31 (b)'!$X19 -> 14.428157
A14: 11 | B14: ='[1]Dia 1 (b)'!$X20 -> 13.079153 | C14: ='[1]Dia 2 (b)'!$X20 -> 13.118901 | D14: ='[1]Dia 3 (b)'!$X20 -> 15.221213 | E14: ='[1]Dia 4 (b)'!$X20 -> 16.126697 | F14: ='[1]Dia 5 (b)'!$X20 -> 15.050244 | G14: ='[1]Dia 6 (b)'!$X20 -> 14.04632 | H14: ='[1]Dia 7 (b)'!$X20 -> 14.813889 | I14: ='[1]Dia 8 (b)'!$X20 -> 14.669516 | J14: ='[1]Dia 9 (b)'!$X20 -> 16.498478 | K14: ='[1]Dia 10 (b)'!$X20 -> 14.737001 | L14: ='[1]Dia 11 (b)'!$X20 -> 16.179752 | M14: ='[1]Dia 12 (b)'!$X20 -> 16.601835 | N14: ='[1]Dia 13 (b)'!$X20 -> 14.620228 | O14: ='[1]Dia 14 (b)'!$X20 -> 14.602875 | P14: ='[1]Dia 15 (b)'!$X20 -> 15.579248 | Q14: ='[1]Dia 16 (b)'!$X20 -> 14.983352 | R14: ='[1]Dia 17 (b)'!$X20 -> 16.358822 | S14: ='[1]Dia 18 (b)'!$X20 -> 16.721026 | T14: ='[1]Dia 19 (b)'!$X20 -> 15.203531 | U14: ='[1]Dia 20 (b)'!$X20 -> 17.041511 | V14: ='[1]Dia 21 (b)'!$X20 -> 16.2583 | W14: ='[1]Dia 22 (b)'!$X20 -> 14.181304 | X14: ='[1]Dia 23 (b)'!$X20 -> 13.75712 | Y14: ='[1]Dia 24 (b)'!$X20 -> 13.024903 | Z14: ='[1]Dia 25 (b)'!$X20 -> 13.240098 | AA14: ='[1]Dia 26 (b)'!$X20 -> 12.613595 | AB14: ='[1]Dia 27 (b)'!$X20 -> 14.170996 | AC14: ='[1]Dia 28 (b)'!$X20 -> 12.830185 | AD14: ='[1]Dia 29 (b)'!$X20 -> 12.563802 | AE14: ='[1]Dia 30 (b)'!$X20 -> 10.482733 | AF14: ='[1]Dia 31 (b)'!$X20 -> 13.535526
A15: 12 | B15: ='[1]Dia 1 (b)'!$X21 -> 13.793108 | C15: ='[1]Dia 2 (b)'!$X21 -> 14.480385 | D15: ='[1]Dia 3 (b)'!$X21 -> 14.26188 | E15: ='[1]Dia 4 (b)'!$X21 -> 17.188686 | F15: ='[1]Dia 5 (b)'!$X21 -> 15.270118 | G15: ='[1]Dia 6 (b)'!$X21 -> 15.556384 | H15: ='[1]Dia 7 (b)'!$X21 -> 13.164594 | I15: ='[1]Dia 8 (b)'!$X21 -> 14.143792 | J15: ='[1]Dia 9 (b)'!$X21 -> 15.373884 | K15: ='[1]Dia 10 (b)'!$X21 -> 13.86672 | L15: ='[1]Dia 11 (b)'!$X21 -> 15.914957 | M15: ='[1]Dia 12 (b)'!$X21 -> 16.276564 | N15: ='[1]Dia 13 (b)'!$X21 -> 14.430109 | O15: ='[1]Dia 14 (b)'!$X21 -> 14.897405 | P15: ='[1]Dia 15 (b)'!$X21 -> 15.476272 | Q15: ='[1]Dia 16 (b)'!$X21 -> 14.841312 | R15: ='[1]Dia 17 (b)'!$X21 -> 16.287209 | S15: ='[1]Dia 18 (b)'!$X21 -> 15.476272 | T15: ='[1]Dia 19 (b)'!$X21 -> 14.723846 | U15: ='[1]Dia 20 (b)'!$X21 -> 17.027963 | V15: ='[1]Dia 21 (b)'!$X21 -> 15.695953 | W15: ='[1]Dia 22 (b)'!$X21 -> 14.545259 | X15: ='[1]Dia 23 (b)'!$X21 -> 14.138595 | Y15: ='[1]Dia 24 (b)'!$X21 -> 13.545852 | Z15: ='[1]Dia 25 (b)'!$X21 -> 13.046595 | AA15: ='[1]Dia 26 (b)'!$X21 -> 12.813912 | AB15: ='[1]Dia 27 (b)'!$X21 -> 13.848883 | AC15: ='[1]Dia 28 (b)'!$X21 -> 13.444194 | AD15: ='[1]Dia 29 (b)'!$X21 -> 12.512928 | AE15: ='[1]Dia 30 (b)'!$X21 -> 10.801436 | AF15: ='[1]Dia 31 (b)'!$X21 -> 14.433715
A16: 13 | B16: ='[1]Dia 1 (b)'!$X22 -> 13.667083 | C16: ='[1]Dia 2 (b)'!$X22 -> 14.846194 | D16: ='[1]Dia 3 (b)'!$X22 -> 14.06972 | E16: ='[1]Dia 4 (b)'!$X22 -> 16.468246 | F16: ='[1]Dia 5 (b)'!$X22 -> 15.147318 | G16: ='[1]Dia 6 (b)'!$X22 -> 15.510008 | H16: ='[1]Dia 7 (b)'!$X22 -> 12.319266 | I16: ='[1]Dia 8 (b)'!$X22 -> 13.983061 | J16: ='[1]Dia 9 (b)'!$X22 -> 14.295587 | K16: ='[1]Dia 10 (b)'!$X22 -> 13.293316 | L16: ='[1]Dia 11 (b)'!$X22 -> 15.371552 | M16: ='[1]Dia 12 (b)'!$X22 -> 16.341021 | N16: ='[1]Dia 13 (b)'!$X22 -> 14.307761 | O16: ='[1]Dia 14 (b)'!$X22 -> 14.249228 | P16: ='[1]Dia 15 (b)'!$X22 -> 14.767187 | Q16: ='[1]Dia 16 (b)'!$X22 -> 14.403342 | R16: ='[1]Dia 17 (b)'!$X22 -> 15.107161 | S16: ='[1]Dia 18 (b)'!$X22 -> 15.320463 | T16: ='[1]Dia 19 (b)'!$X22 -> 16.18567 | U16: ='[1]Dia 20 (b)'!$X22 -> 17.288331 | V16: ='[1]Dia 21 (b)'!$X22 -> 16.32998 | W16: ='[1]Dia 22 (b)'!$X22 -> 14.525509 | X16: ='[1]Dia 23 (b)'!$X22 -> 14.152549 | Y16: ='[1]Dia 24 (b)'!$X22 -> 13.547771 | Z16: ='[1]Dia 25 (b)'!$X22 -> 12.486608 | AA16: ='[1]Dia 26 (b)'!$X22 -> 13.834794 | AB16: ='[1]Dia 27 (b)'!$X22 -> 14.392877 | AC16: ='[1]Dia 28 (b)'!$X22 -> 13.909528 | AD16: ='[1]Dia 29 (b)'!$X22 -> 12.835172 | AE16: ='[1]Dia 30 (b)'!$X22 -> 9.3093027 | AF16: ='[1]Dia 31 (b)'!$X22 -> 16.459703
A17: 14 | B17: ='[1]Dia 1 (b)'!$X23 -> 13.625038 | C17: ='[1]Dia 2 (b)'!$X23 -> 15.169757 | D17: ='[1]Dia 3 (b)'!$X23 -> 17.393879 | E17: ='[1]Dia 4 (b)'!$X23 -> 16.893199 | F17: ='[1]Dia 5 (b)'!$X23 -> 15.849296 | G17: ='[1]Dia 6 (b)'!$X23 -> 14.8221 | H17: ='[1]Dia 7 (b)'!$X23 -> 17.316063 | I17: ='[1]Dia 8 (b)'!$X23 -> 14.465039 | J17: ='[1]Dia 9 (b)'!$X23 -> 14.223734 | K17: ='[1]Dia 10 (b)'!$X23 -> 12.968697 | L17: ='[1]Dia 11 (b)'!$X23 -> 15.111625 | M17: ='[1]Dia 12 (b)'!$X23 -> 18.852952 | N17: ='[1]Dia 13 (b)'!$X23 -> 13.782 | O17: ='[1]Dia 14 (b)'!$X23 -> 14.503661 | P17: ='[1]Dia 15 (b)'!$X23 -> 14.356649 | Q17: ='[1]Dia 16 (b)'!$X23 -> 13.638501 | R17: ='[1]Dia 17 (b)'!$X23 -> 14.81534 | S17: ='[1]Dia 18 (b)'!$X23 -> 16.243399 | T17: ='[1]Dia 19 (b)'!$X23 -> 16.15013 | U17: ='[1]Dia 20 (b)'!$X23 -> 17.01521 | V17: ='[1]Dia 21 (b)'!$X23 -> 17.300768 | W17: ='[1]Dia 22 (b)'!$X23 -> 14.183083 | X17: ='[1]Dia 23 (b)'!$X23 -> 13.339331 | Y17: ='[1]Dia 24 (b)'!$X23 -> 13.786075 | Z17: ='[1]Dia 25 (b)'!$X23 -> 13.286277 | AA17: ='[1]Dia 26 (b)'!$X23 -> 12.616367 | AB17: ='[1]Dia 27 (b)'!$X23 -> 14.163775 | AC17: ='[1]Dia 28 (b)'!$X23 -> 13.390636 | AD17: ='[1]Dia 29 (b)'!$X23 -> 11.417736 | AE17: ='[1]Dia 30 (b)'!$X23 -> 9.4242489 | AF17: ='[1]Dia 31 (b)'!$X23 -> 17.069659
A18: 15 | B18: ='[1]Dia 1 (b)'!$X24 -> 13.658852 | C18: ='[1]Dia 2 (b)'!$X24 -> 14.612373 | D18: ='[1]Dia 3 (b)'!$X24 -> 16.705147 | E18: ='[1]Dia 4 (b)'!$X24 -> 15.883645 | F18: ='[1]Dia 5 (b)'!$X24 -> 15.203248 | G18: ='[1]Dia 6 (b)'!$X24 -> 14.854748 | H18: ='[1]Dia 7 (b)'!$X24 -> 17.080649 | I18: ='[1]Dia 8 (b)'!$X24 -> 13.815393 | J18: ='[1]Dia 9 (b)'!$X24 -> 13.784453 | K18: ='[1]Dia 10 (b)'!$X24 -> 12.298297 | L18: ='[1]Dia 11 (b)'!$X24 -> 14.507371 | M18: ='[1]Dia 12 (b)'!$X24 -> 18.137699 | N18: ='[1]Dia 13 (b)'!$X24 -> 13.567626 | O18: ='[1]Dia 14 (b)'!$X24 -> 16.487934 | P18: ='[1]Dia 15 (b)'!$X24 -> 14.455384 | Q18: ='[1]Dia 16 (b)'!$X24 -> 14.240404 | R18: ='[1]Dia 17 (b)'!$X24 -> 19.006543 | S18: ='[1]Dia 18 (b)'!$X24 -> 19.076714 | T18: ='[1]Dia 19 (b)'!$X24 -> 16.658078 | U18: ='[1]Dia 20 (b)'!$X24 -> 17.082821 | V18: ='[1]Dia 21 (b)'!$X24 -> 16.946935 | W18: ='[1]Dia 22 (b)'!$X24 -> 14.223578 | X18: ='[1]Dia 23 (b)'!$X24 -> 12.705534 | Y18: ='[1]Dia 24 (b)'!$X24 -> 13.777537 | Z18: ='[1]Dia 25 (b)'!$X24 -> 12.939979 | AA18: ='[1]Dia 26 (b)'!$X24 -> 12.487892 | AB18: ='[1]Dia 27 (b)'!$X24 -> 15.007342 | AC18: ='[1]Dia 28 (b)'!$X24 -> 12.65236 | AD18: ='[1]Dia 29 (b)'!$X24 -> 10.257794 | AE18: ='[1]Dia 30 (b)'!$X24 -> 9.5058199 | AF18: ='[1]Dia 31 (b)'!$X24 -> 12.040673
A19: 16
A20: 17
A21: 18
A22: 19
A23: 20
A24: 21
A25: 22
A26: 23
A27: 24
B28: NÃO ESTÃO SENDO MAIS INTERPOLADOS AS OBSERVAÇÕES ENTRE AS 16H E 6H.
A30: MÉDIA
A31: DIÁRIA
A34: MÁXIMA
A35: DIÁRIA
A38: MÍNIMA
A39: DIÁRIA
A42: AMPLITUDE
A43: DIÁRIA
H46: MÉDIA | K46: MÁXIMA | N46: MÍNIMA | Q46: AMPLITUDE | T46: MÉDIA | V46: MÉDIA | X46: DIF. DAS
H47: MENSAL | K47: MENSAL | N47: MENSAL | Q47: MENSAL | T47: DAS MÁX. | V47: DAS MÍN. | X47: MÉDIAS

Sheet Fev
B1: ='[2]Dia 1 (b)'!C1 -> FEVEREIRO DE 2024 | K1: Umid. Específica (g.kg-1)
A3: H/D | B3: 1 | C3: 2 | D3: 3 | E3: 4 | F3: 5 | G3: 6 | H3: 7 | I3: 8 | J3: 9 | K3: 10 | L3: 11 | M3: 12 | N3: 13 | O3: 14 | P3: 15 | Q3: 16 | R3: 17 | S3: 18 | T3: 19 | U3: 20 | V3: 21 | W3: 22 | X3: 23 | Y3: 24 | Z3: 25 | AA3: 26 | AB3: 27 | AC3: 28 | AD3: 29
A4: 1
A5: 2
A6: 3
A7: 4
A8: 5
A9: 6
A10: 7 | B10: ='[2]Dia 1 (b)'!$X16 -> 13.838866 | C10: ='[2]Dia 2 (b)'!$X16 -> 14.708345 | D10: ='[2]Dia 3 (b)'!$X16 -> 14.464591 | E10: ='[2]Dia 4 (b)'!$X16 -> 15.501971 | F10: ='[2]Dia 5 (b)'!$X16 -> 14.312973 | G10: ='[2]Dia 6 (b)'!$X16 -> 14.6671 | H10: ='[2]Dia 7 (b)'!$X16 -> 15.153796 | I10: ='[2]Dia 8 (b)'!$X16 -> 15.264912 | J10: ='[2]Dia 9 (b)'!$X16 -> 15.144749 | K10: ='[2]Dia 10 (b)'!$X16 -> 15.760467 | L10: ='[2]Dia 11 (b)'!$X16 -> 15.631344 | M10: ='[2]Dia 12 (b)'!$X16 -> 15.409136 | N10: ='[2]Dia 13 (b)'!$X16 -> 14.716899 | O10: ='[2]Dia 14 (b)'!$X16 -> 15.7176 | P10: ='[2]Dia 15 (b)'!$X16 -> 15.131061 | Q10: ='[2]Dia 16 (b)'!$X16 -> 14.193834 | R10: ='[2]Dia 17 (b)'!$X16 -> 13.664221 | S10: ='[2]Dia 18 (b)'!$X16 -> 14.79269 | T10: ='[2]Dia 19 (b)'!$X16 -> 14.779766 | U10: ='[2]Dia 20 (b)'!$X16 -> 15.864176 | V10: ='[2]Dia 21 (b)'!$X16 -> 15.036901 | W10: ='[2]Dia 22 (b)'!$X16 -> 15.463284 | X10: ='[2]Dia 23 (b)'!$X16 -> 16.649377 | Y10: ='[2]Dia 24 (b)'!$X16 -> 17.277676 | Z10: ='[2]Dia 25 (b)'!$X16 -> 17.515623 | AA10: ='[2]Dia 26 (b)'!$X16 -> 16.290905 | AB10: ='[2]Dia 27 (b)'!$X16 -> 16.660608 | AC10: ='[2]Dia 28 (b)'!$X16 -> 17.196573 | AD10: ='[2]Dia 29 (b)'!$X16 -> 17.763297
A11: 8 | B11: ='[2]Dia 1 (b)'!$X17 -> 13.201324 | C11: ='[2]Dia 2 (b)'!$X17 -> 14.439855 | D11: ='[2]Dia 3 (b)'!$X17 -> 14.581451 | E11: ='[2]Dia 4 (b)'!$X17 -> 14.152757 | F11: ='[2]Dia 5 (b)'!$X17 -> 14.053839 | G11: ='[2]Dia 6 (b)'!$X17 -> 14.991206 | H11: ='[2]Dia 7 (b)'!$X17 -> 15.515924 | I11: ='[2]Dia 8 (b)'!$X17 -> 15.552889 | J11: ='[2]Dia 9 (b)'!$X17 -> 14.895577 | K11: ='[2]Dia 10 (b)'!$X17 -> 15.60193 | L11: ='[2]Dia 11 (b)'!$X17 -> 15.326427 | M11: ='[2]Dia 12 (b)'!$X17 -> 15.249762 | N11: ='[2]Dia 13 (b)'!$X17 -> 14.521351 | O11: ='[2]Dia 14 (b)'!$X17 -> 15.462691 | P11: ='[2]Dia 15 (b)'!$X17 -> 15.308588 | Q11: ='[2]Dia 16 (b)'!$X17 -> 14.658135 | R11: ='[2]Dia 17 (b)'!$X17 -> 12.334497 | S11: ='[2]Dia 18 (b)'!$X17 -> 14.709314 | T11: ='[2]Dia 19 (b)'!$X17 -> 16.017218 | U11: ='[2]Dia 20 (b)'!$X17 -> 17.409616 | V11: ='[2]Dia 21 (b)'!$X17 -> 14.801934 | W11: ='[2]Dia 22 (b)'!$X17 -> 15.618464 | X11: ='[2]Dia 23 (b)'!$X17 -> 16.176649 | Y11: ='[2]Dia 24 (b)'!$X17 -> 18.18773 | Z11: ='[2]Dia 25 (b)'!$X17 -> 17.417966 | AA11: ='[2]Dia 26 (b)'!$X17 -> 15.812303 | AB11: ='[2]Dia 27 (b)'!$X17 -> 16.320065 | AC11: ='[2]Dia 28 (b)'!$X17 -> 17.180778 | AD11: ='[2]Dia 29 (b)'!$X17 -> 16.687861
A12: 9 | B12: ='[2]Dia 1 (b)'!$X18 -> 13.012366 | C12: ='[2]Dia 2 (b)'!$X18 -> 14.117889 | D12: ='[2]Dia 3 (b)'!$X18 -> 14.629607 | E12: ='[2]Dia 4 (b)'!$X18 -> 14.804226 | F12: ='[2]Dia 5 (b)'!$X18 -> 14.812767 | G12: ='[2]Dia 6 (b)'!$X18 -> 14.052356 | H12: ='[2]Dia 7 (b)'!$X18 -> 15.207158 | I12: ='[2]Dia 8 (b)'!$X18 -> 15.663299 | J12: ='[2]Dia 9 (b)'!$X18 -> 14.856753 | K12: ='[2]Dia 10 (b)'!$X18 -> 15.556405 | L12: ='[2]Dia 11 (b)'!$X18 -> 14.176858 | M12: ='[2]Dia 12 (b)'!$X18 -> 15.138878 | N12: ='[2]Dia 13 (b)'!$X18 -> 14.571683 | O12: ='[2]Dia 14 (b)'!$X18 -> 15.162913 | P12: ='[2]Dia 15 (b)'!$X18 -> 15.219868 | Q12: ='[2]Dia 16 (b)'!$X18 -> 14.590327 | R12: ='[2]Dia 17 (b)'!$X18 -> 13.227171 | S12: ='[2]Dia 18 (b)'!$X18 -> 14.917735 | T12: ='[2]Dia 19 (b)'!$X18 -> 14.745545 | U12: ='[2]Dia 20 (b)'!$X18 -> 17.028034 | V12: ='[2]Dia 21 (b)'!$X18 -> 14.635849 | W12: ='[2]Dia 22 (b)'!$X18 -> 15.42783 | X12: ='[2]Dia 23 (b)'!$X18 -> 15.940471 | Y12: ='[2]Dia 24 (b)'!$X18 -> 16.979664 | Z12: ='[2]Dia 25 (b)'!$X18 -> 17.187707 | AA12: ='[2]Dia 26 (b)'!$X18 -> 15.723504 | AB12: ='[2]Dia 27 (b)'!$X18 -> 16.463085 | AC12: ='[2]Dia 28 (b)'!$X18 -> 17.557129 | AD12: ='[2]Dia 29 (b)'!$X18 -> 15.980634
A13: 10 | B13: ='[2]Dia 1 (b)'!$X19 -> 14.372765 | C13: ='[2]Dia 2 (b)'!$X19 -> 15.591592 | D13: ='[2]Dia 3 (b)'!$X19 -> 14.827489 | E13: ='[2]Dia 4 (b)'!$X19 -> 12.23351 | F13: ='[2]Dia 5 (b)'!$X19 -> 12.577258 | G13: ='[2]Dia 6 (b)'!$X19 -> 14.028935 | H13: ='[2]Dia 7 (b)'!$X19 -> 13.974088 | I13: ='[2]Dia 8 (b)'!$X19 -> 15.113545 | J13: ='[2]Dia 9 (b)'!$X19 -> 15.654273 | K13: ='[2]Dia 10 (b)'!$X19 -> 14.746996 | L13: ='[2]Dia 11 (b)'!$X19 -> 13.721826 | M13: ='[2]Dia 12 (b)'!$X19 -> 14.529745 | N13: ='[2]Dia 13 (b)'!$X19 -> 14.656154 | O13: ='[2]Dia 14 (b)'!$X19 -> 15.083304 | P13: ='[2]Dia 15 (b)'!$X19 -> 15.605133 | Q13: ='[2]Dia 16 (b)'!$X19 -> 14.705519 | R13: ='[2]Dia 17 (b)'!$X19 -> 12.824167 | S13: ='[2]Dia 18 (b)'!$X19 -> 14.492165 | T13: ='[2]Dia 19 (b)'!$X19 -> 15.193467 | U13: ='[2]Dia 20 (b)'!$X19 -> 15.920805 | V13: ='[2]Dia 21 (b)'!$X19 -> 14.538027 | W13: ='[2]Dia 22 (b)'!$X19 -> 16.101104 | X13: ='[2]Dia 23 (b)'!$X19 -> 15.60542 | Y13: ='[2]Dia 24 (b)'!$X19 -> 16.275542 | Z13: ='[2]Dia 25 (b)'!$X19 -> 16.93071 | AA13: ='[2]Dia 26 (b)'!$X19 -> 16.62806 | AB13: ='[2]Dia 27 (b)'!$X19 -> 16.067726 | AC13: ='[2]Dia 28 (b)'!$X19 -> 17.879921 | AD13: ='[2]Dia 29 (b)'!$X19 -> 16.905765
A14: 11 | B14: ='[2]Dia 1 (b)'!$X20 -> 13.110151 | C14: ='[2]Dia 2 (b)'!$X20 -> 15.410076 | D14: ='[2]Dia 3 (b)'!$X20 -> 14.801538 | E14: ='[2]Dia 4 (b)'!$X20 -> 12.911986 | F14: ='[2]Dia 5 (b)'!$X20 -> 11.29761 | G14: ='[2]Dia 6 (b)'!$X20 -> 15.150384 | H14: ='[2]Dia 7 (b)'!$X20 -> 13.009003 | I14: ='[2]Dia 8 (b)'!$X20 -> 13.4267 | J14: ='[2]Dia 9 (b)'!$X20 -> 14.771931 | K14: ='[2]Dia 10 (b)'!$X20 -> 14.011061 | L14: ='[2]Dia 11 (b)'!$X20 -> 13.230706 | M14: ='[2]Dia 12 (b)'!$X20 -> 14.942655 | N14: ='[2]Dia 13 (b)'!$X20 -> 15.155027 | O14: ='[2]Dia 14 (b)'!$X20 -> 16.807199 | P14: ='[2]Dia 15 (b)'!$X20 -> 15.637876 | Q14: ='[2]Dia 16 (b)'!$X20 -> 14.138655 | R14: ='[2]Dia 17 (b)'!$X20 -> 13.342905 | S14: ='[2]Dia 18 (b)'!$X20 -> 14.689422 | T14: ='[2]Dia 19 (b)'!$X20 -> 14.994153 | U14: ='[2]Dia 20 (b)'!$X20 -> 17.315318 | V14: ='[2]Dia 21 (b)'!$X20 -> 14.288514 | W14: ='[2]Dia 22 (b)'!$X20 -> 15.408242 | X14: ='[2]Dia 23 (b)'!$X20 -> 16.758343 | Y14: ='[2]Dia 24 (b)'!$X20 -> 16.451652 | Z14: ='[2]Dia 25 (b)'!$X20 -> 16.831738 | AA14: ='[2]Dia 26 (b)'!$X20 -> 16.83845 | AB14: ='[2]Dia 27 (b)'!$X20 -> 16.56575 | AC14: ='[2]Dia 28 (b)'!$X20 -> 17.677965 | AD14: ='[2]Dia 29 (b)'!$X20 -> 17.471102
A15: 12 | B15: ='[2]Dia 1 (b)'!$X21 -> 12.334791 | C15: ='[2]Dia 2 (b)'!$X21 -> 14.716439 | D15: ='[2]Dia 3 (b)'!$X21 -> 15.648213 | E15: ='[2]Dia 4 (b)'!$X21 -> 12.239709 | F15: ='[2]Dia 5 (b)'!$X21 -> 11.209049 | G15: ='[2]Dia 6 (b)'!$X21 -> 14.246546 | H15: ='[2]Dia 7 (b)'!$X21 -> 12.665687 | I15: ='[2]Dia 8 (b)'!$X21 -> 12.970577 | J15: ='[2]Dia 9 (b)'!$X21 -> 16.121758 | K15: ='[2]Dia 10 (b)'!$X21 -> 13.963994 | L15: ='[2]Dia 11 (b)'!$X21 -> 13.021838 | M15: ='[2]Dia 12 (b)'!$X21 -> 14.215733 | N15: ='[2]Dia 13 (b)'!$X21 -> 15.824019 | O15: ='[2]Dia 14 (b)'!$X21 -> 16.155556 | P15: ='[2]Dia 15 (b)'!$X21 -> 15.722224 | Q15: ='[2]Dia 16 (b)'!$X21 -> 14.539355 | R15: ='[2]Dia 17 (b)'!$X21 -> 13.885485 | S15: ='[2]Dia 18 (b)'!$X21 -> 14.566855 | T15: ='[2]Dia 19 (b)'!$X21 -> 13.538665 | U15: ='[2]Dia 20 (b)'!$X21 -> 18.264631 | V15: ='[2]Dia 21 (b)'!$X21 -> 14.946474 | W15: ='[2]Dia 22 (b)'!$X21 -> 15.741954 | X15: ='[2]Dia 23 (b)'!$X21 -> 16.108164 | Y15: ='[2]Dia 24 (b)'!$X21 -> 16.618936 | Z15: ='[2]Dia 25 (b)'!$X21 -> 16.885484 | AA15: ='[2]Dia 26 (b)'!$X21 -> 17.188276 | AB15: ='[2]Dia 27 (b)'!$X21 -> 16.232566 | AC15: ='[2]Dia 28 (b)'!$X21 -> 18.128251 | AD15: ='[2]Dia 29 (b)'!$X21 -> 16.841451
A16: 13 | B16: ='[2]Dia 1 (b)'!$X22 -> 13.257238 | C16: ='[2]Dia 2 (b)'!$X22 -> 16.529861 | D16: ='[2]Dia 3 (b)'!$X22 -> 14.074987 | E16: ='[2]Dia 4 (b)'!$X22 -> 12.86386 | F16: ='[2]Dia 5 (b)'!$X22 -> 13.604816 | G16: ='[2]Dia 6 (b)'!$X22 -> 14.009022 | H16: ='[2]Dia 7 (b)'!$X22 -> 12.562082 | I16: ='[2]Dia 8 (b)'!$X22 -> 15.345086 | J16: ='[2]Dia 9 (b)'!$X22 -> 16.979738 | K16: ='[2]Dia 10 (b)'!$X22 -> 11.867801 | L16: ='[2]Dia 11 (b)'!$X22 -> 13.329633 | M16: ='[2]Dia 12 (b)'!$X22 -> 13.761146 | N16: ='[2]Dia 13 (b)'!$X22 -> 15.445295 | O16: ='[2]Dia 14 (b)'!$X22 -> 17.599298 | P16: ='[2]Dia 15 (b)'!$X22 -> 15.590771 | Q16: ='[2]Dia 16 (b)'!$X22 -> 15.336101 | R16: ='[2]Dia 17 (b)'!$X22 -> 14.5492 | S16: ='[2]Dia 18 (b)'!$X22 -> 15.521336 | T16: ='[2]Dia 19 (b)'!$X22 -> 13.746896 | U16: ='[2]Dia 20 (b)'!$X22 -> 17.483146 | V16: ='[2]Dia 21 (b)'!$X22 -> 16.457261 | W16: ='[2]Dia 22 (b)'!$X22 -> 15.081743 | X16: ='[2]Dia 23 (b)'!$X22 -> 15.956407 | Y16: ='[2]Dia 24 (b)'!$X22 -> 16.945357 | Z16: ='[2]Dia 25 (b)'!$X22 -> 16.651319 | AA16: ='[2]Dia 26 (b)'!$X22 -> 17.195874 | AB16: ='[2]Dia 27 (b)'!$X22 -> 17.454526 | AC16: ='[2]Dia 28 (b)'!$X22 -> 17.755614 | AD16: ='[2]Dia 29 (b)'!$X22 -> 15.08629
A17: 14 | B17: ='[2]Dia 1 (b)'!$X23 -> 13.39693 | C17: ='[2]Dia 2 (b)'!$X23 -> 13.631085 | D17: ='[2]Dia 3 (b)'!$X23 -> 15.114119 | E17: ='[2]Dia 4 (b)'!$X23 -> 15.853856 | F17: ='[2]Dia 5 (b)'!$X23 -> 11.565455 | G17: ='[2]Dia 6 (b)'!$X23 -> 15.661438 | H17: ='[2]Dia 7 (b)'!$X23 -> 16.419093 | I17: ='[2]Dia 8 (b)'!$X23 -> 15.361097 | J17: ='[2]Dia 9 (b)'!$X23 -> 17.322152 | K17: ='[2]Dia 10 (b)'!$X23 -> 15.069224 | L17: ='[2]Dia 11 (b)'!$X23 -> 12.670447 | M17: ='[2]Dia 12 (b)'!$X23 -> 14.369899 | N17: ='[2]Dia 13 (b)'!$X23 -> 15.00485 | O17: ='[2]Dia 14 (b)'!$X23 -> 17.279241 | P17: ='[2]Dia 15 (b)'!$X23 -> 15.419486 | Q17: ='[2]Dia 16 (b)'!$X23 -> 15.530901 | R17: ='[2]Dia 17 (b)'!$X23 -> 14.854394 | S17: ='[2]Dia 18 (b)'!$X23 -> 16.532207 | T17: ='[2]Dia 19 (b)'!$X23 -> 16.433593 | U17: ='[2]Dia 20 (b)'!$X23 -> 15.768568 | V17: ='[2]Dia 21 (b)'!$X23 -> 16.212138 | W17: ='[2]Dia 22 (b)'!$X23 -> 14.476887 | X17: ='[2]Dia 23 (b)'!$X23 -> 15.541275 | Y17: ='[2]Dia 24 (b)'!$X23 -> 16.543522 | Z17: ='[2]Dia 25 (b)'!$X23 -> 16.810263 | AA17: ='[2]Dia 26 (b)'!$X23 -> 17.383407 | AB17: ='[2]Dia 27 (b)'!$X23 -> 16.163287 | AC17: ='[2]Dia 28 (b)'!$X23 -> 20.926177 | AD17: ='[2]Dia 29 (b)'!$X23 -> 14.743466
A18: 15 | B18: ='[2]Dia 1 (b)'!$X24 -> 15.826813 | C18: ='[2]Dia 2 (b)'!$X24 -> 14.349996 | D18: ='[2]Dia 3 (b)'!$X24 -> 15.193642 | E18: ='[2]Dia 4 (b)'!$X24 -> 15.106621 | F18: ='[2]Dia 5 (b)'!$X24 -> 11.949455 | G18: ='[2]Dia 6 (b)'!$X24 -> 15.623564 | H18: ='[2]Dia 7 (b)'!$X24 -> 17.386681 | I18: ='[2]Dia 8 (b)'!$X24 -> 16.09764 | J18: ='[2]Dia 9 (b)'!$X24 -> 16.857863 | K18: ='[2]Dia 10 (b)'!$X24 -> 16.500324 | L18: ='[2]Dia 11 (b)'!$X24 -> 16.434601 | M18: ='[2]Dia 12 (b)'!$X24 -> 13.855674 | N18: ='[2]Dia 13 (b)'!$X24 -> 14.372769 | O18: ='[2]Dia 14 (b)'!$X24 -> 17.24108 | P18: ='[2]Dia 15 (b)'!$X24 -> 15.503522 | Q18: ='[2]Dia 16 (b)'!$X24 -> 15.457525 | R18: ='[2]Dia 17 (b)'!$X24 -> 15.87371 | S18: ='[2]Dia 18 (b)'!$X24 -> 15.689129 | T18: ='[2]Dia 19 (b)'!$X24 -> 17.74486 | U18: ='[2]Dia 20 (b)'!$X24 -> 16.378616 | V18: ='[2]Dia 21 (b)'!$X24 -> 17.301844 | W18: ='[2]Dia 22 (b)'!$X24 -> 16.985904 | X18: ='[2]Dia 23 (b)'!$X24 -> 15.771125 | Y18: ='[2]Dia 24 (b)'!$X24 -> 16.814122 | Z18: ='[2]Dia 25 (b)'!$X24 -> 17.738846 | AA18: ='[2]Dia 26 (b)'!$X24 -> 17.225721 | AB18: ='[2]Dia 27 (b)'!$X24 -> 16.522382 | AC18: ='[2]Dia 28 (b)'!$X24 -> 19.009953 | AD18: ='[2]Dia 29 (b)'!$X24 -> 15.021533
A19: 16
A20: 17
A21: 18
A22: 19
A23: 20
A24: 21
A25: 22
A26: 23
A27: 24
B28: NÃO ESTÃO SENDO MAIS INTERPOLADOS AS OBSERVAÇÕES ENTRE AS 16H E 6H.
A30: MÉDIA
A31: DIÁRIA
A34: MÁXIMA
A35: DIÁRIA
A38: MÍNIMA
A39: DIÁRIA
A42: AMPLITUDE
A43: DIÁRIA
H46: MÉDIA | K46: MÁXIMA | N46: MÍNIMA | Q46: AMPLITUDE | T46: MÉDIA | V46: MÉDIA | X46: DIF. DAS
H47: MENSAL | K47: MENSAL | N47: MENSAL | Q47: MENSAL | T47: DAS MÁX. | V47: DAS MÍN. | X47: MÉDIAS

Sheet Mar
B1: ='[3]Dia 1 (b)'!C1 -> MARÇO DE 2024 | K1: Umid. Específica (g.kg-1)
A3: H/D | B3: 1 | C3: 2 | D3: 3 | E3: 4 | F3: 5 | G3: 6 | H3: 7 | I3: 8 | J3: 9 | K3: 10 | L3: 11 | M3: 12 | N3: 13 | O3: 14 | P3: 15 | Q3: 16 | R3: 17 | S3: 18 | T3: 19 | U3: 20 | V3: 21 | W3: 22 | X3: 23 | Y3: 24 | Z3: 25 | AA3: 26 | AB3: 27 | AC3: 28 | AD3: 29 | AE3: 30 | AF3: 31
A4: 1
A5: 2
A6: 3
A7: 4
A8: 5
A9: 6
A10: 7 | B10: ='[3]Dia 1 (b)'!$X16 -> 17.195196 | C10: ='[3]Dia 2 (b)'!$X16 -> 14.200017 | D10: ='[3]Dia 3 (b)'!$X16 -> 13.642522 | E10: ='[3]Dia 4 (b)'!$X16 -> 15.18796 | F10: ='[3]Dia 5 (b)'!$X16 -> 16.976902 | G10: ='[3]Dia 6 (b)'!$X16 -> 17.176831 | H10: ='[3]Dia 7 (b)'!$X16 -> 15.475465 | I10: ='[3]Dia 8 (b)'!$X16 -> 16.042395 | J10: ='[3]Dia 9 (b)'!$X16 -> 17.782833 | K10: ='[3]Dia 10 (b)'!$X16 -> 17.230685 | L10: ='[3]Dia 11 (b)'!$X16 -> 14.8417 | M10: ='[3]Dia 12 (b)'!$X16 -> 12.367715 | N10: ='[3]Dia 13 (b)'!$X16 -> 14.774628 | O10: ='[3]Dia 14 (b)'!$X16 -> 16.850957 | P10: ='[3]Dia 15 (b)'!$X16 -> 16.988318 | Q10: ='[3]Dia 16 (b)'!$X16 -> 17.053221 | R10: ='[3]Dia 17 (b)'!$X16 -> 17.502157 | S10: ='[3]Dia 18 (b)'!$X16 -> 16.757333 | T10: ='[3]Dia 19 (b)'!$X16 -> 17.532337 | U10: ='[3]Dia 20 (b)'!$X16 -> 17.59859 | V10: ='[3]Dia 21 (b)'!$X16 -> 17.045159 | W10: ='[3]Dia 22 (b)'!$X16 -> 15.680075 | X10: ='[3]Dia 23 (b)'!$X16 -> 11.862078 | Y10: ='[3]Dia 24 (b)'!$X16 -> 13.335322 | Z10: ='[3]Dia 25 (b)'!$X16 -> 13.462438 | AA10: ='[3]Dia 26 (b)'!$X16 -> 13.243678 | AB10: ='[3]Dia 27 (b)'!$X16 -> 13.29875 | AC10: ='[3]Dia 28 (b)'!$X16 -> 14.160239 | AD10: ='[3]Dia 29 (b)'!$X16 -> 15.333009 | AE10: ='[3]Dia 30 (b)'!$X16 -> 14.851055 | AF10: ='[3]Dia 31 (b)'!$X16 -> 12.131475
A11: 8 | B11: ='[3]Dia 1 (b)'!$X17 -> 17.391254 | C11: ='[3]Dia 2 (b)'!$X17 -> 14.485961 | D11: ='[3]Dia 3 (b)'!$X17 -> 13.516495 | E11: ='[3]Dia 4 (b)'!$X17 -> 14.854463 | F11: ='[3]Dia 5 (b)'!$X17 -> 16.943893 | G11: ='[3]Dia 6 (b)'!$X17 -> 16.593662 | H11: ='[3]Dia 7 (b)'!$X17 -> 15.844837 | I11: ='[3]Dia 8 (b)'!$X17 -> 16.02639 | J11: ='[3]Dia 9 (b)'!$X17 -> 18.261153 | K11: ='[3]Dia 10 (b)'!$X17 -> 17.333244 | L11: ='[3]Dia 11 (b)'!$X17 -> 14.201264 | M11: ='[3]Dia 12 (b)'!$X17 -> 12.324211 | N11: ='[3]Dia 13 (b)'!$X17 -> 15.119728 | O11: ='[3]Dia 14 (b)'!$X17 -> 16.810119 | P11: ='[3]Dia 15 (b)'!$X17 -> 17.008299 | Q11: ='[3]Dia 16 (b)'!$X17 -> 16.946416 | R11: ='[3]Dia 17 (b)'!$X17 -> 17.561802 | S11: ='[3]Dia 18 (b)'!$X17 -> 16.514925 | T11: ='[3]Dia 19 (b)'!$X17 -> 18.06067 | U11: ='[3]Dia 20 (b)'!$X17 -> 17.638465 | V11: ='[3]Dia 21 (b)'!$X17 -> 16.608029 | W11: ='[3]Dia 22 (b)'!$X17 -> 16.004506 | X11: ='[3]Dia 23 (b)'!$X17 -> 12.095129 | Y11: ='[3]Dia 24 (b)'!$X17 -> 13.32796 | Z11: ='[3]Dia 25 (b)'!$X17 -> 13.590141 | AA11: ='[3]Dia 26 (b)'!$X17 -> 14.050659 | AB11: ='[3]Dia 27 (b)'!$X17 -> 12.7805 | AC11: ='[3]Dia 28 (b)'!$X17 -> 14.29394 | AD11: ='[3]Dia 29 (b)'!$X17 -> 15.635738 | AE11: ='[3]Dia 30 (b)'!$X17 -> 14.760092 | AF11: ='[3]Dia 31 (b)'!$X17 -> 14.492606
A12: 9 | B12: ='[3]Dia 1 (b)'!$X18 -> 16.428959 | C12: ='[3]Dia 2 (b)'!$X18 -> 13.194781 | D12: ='[3]Dia 3 (b)'!$X18 -> 13.714142 | E12: ='[3]Dia 4 (b)'!$X18 -> 14.696215 | F12: ='[3]Dia 5 (b)'!$X18 -> 16.846949 | G12: ='[3]Dia 6 (b)'!$X18 -> 16.400529 | H12: ='[3]Dia 7 (b)'!$X18 -> 15.960403 | I12: ='[3]Dia 8 (b)'!$X18 -> 15.89479 | J12: ='[3]Dia 9 (b)'!$X18 -> 18.376836 | K12: ='[3]Dia 10 (b)'!$X18 -> 17.593328 | L12: ='[3]Dia 11 (b)'!$X18 -> 13.065895 | M12: ='[3]Dia 12 (b)'!$X18 -> 11.89375 | N12: ='[3]Dia 13 (b)'!$X18 -> 15.251743 | O12: ='[3]Dia 14 (b)'!$X18 -> 16.553441 | P12: ='[3]Dia 15 (b)'!$X18 -> 16.623007 | Q12: ='[3]Dia 16 (b)'!$X18 -> 16.766882 | R12: ='[3]Dia 17 (b)'!$X18 -> 16.857605 | S12: ='[3]Dia 18 (b)'!$X18 -> 17.006836 | T12: ='[3]Dia 19 (b)'!$X18 -> 17.570139 | U12: ='[3]Dia 20 (b)'!$X18 -> 17.725067 | V12: ='[3]Dia 21 (b)'!$X18 -> 17.040639 | W12: ='[3]Dia 22 (b)'!$X18 -> 15.948792 | X12: ='[3]Dia 23 (b)'!$X18 -> 11.881493 | Y12: ='[3]Dia 24 (b)'!$X18 -> 13.813111 | Z12: ='[3]Dia 25 (b)'!$X18 -> 13.479139 | AA12: ='[3]Dia 26 (b)'!$X18 -> 13.346396 | AB12: ='[3]Dia 27 (b)'!$X18 -> 12.944985 | AC12: ='[3]Dia 28 (b)'!$X18 -> 14.562396 | AD12: ='[3]Dia 29 (b)'!$X18 -> 15.405118 | AE12: ='[3]Dia 30 (b)'!$X18 -> 14.619885 | AF12: ='[3]Dia 31 (b)'!$X18 -> 13.393047
A13: 10 | B13: ='[3]Dia 1 (b)'!$X19 -> 16.280459 | C13: ='[3]Dia 2 (b)'!$X19 -> 12.6126 | D13: ='[3]Dia 3 (b)'!$X19 -> 14.097098 | E13: ='[3]Dia 4 (b)'!$X19 -> 14.654023 | F13: ='[3]Dia 5 (b)'!$X19 -> 15.903616 | G13: ='[3]Dia 6 (b)'!$X19 -> 15.418121 | H13: ='[3]Dia 7 (b)'!$X19 -> 16.018726 | I13: ='[3]Dia 8 (b)'!$X19 -> 16.16348 | J13: ='[3]Dia 9 (b)'!$X19 -> 18.266139 | K13: ='[3]Dia 10 (b)'!$X19 -> 17.486042 | L13: ='[3]Dia 11 (b)'!$X19 -> 12.58772 | M13: ='[3]Dia 12 (b)'!$X19 -> 11.076472 | N13: ='[3]Dia 13 (b)'!$X19 -> 15.911901 | O13: ='[3]Dia 14 (b)'!$X19 -> 16.646171 | P13: ='[3]Dia 15 (b)'!$X19 -> 15.615514 | Q13: ='[3]Dia 16 (b)'!$X19 -> 15.817567 | R13: ='[3]Dia 17 (b)'!$X19 -> 16.79598 | S13: ='[3]Dia 18 (b)'!$X19 -> 16.571969 | T13: ='[3]Dia 19 (b)'!$X19 -> 17.433136 | U13: ='[3]Dia 20 (b)'!$X19 -> 17.241101 | V13: ='[3]Dia 21 (b)'!$X19 -> 16.997884 | W13: ='[3]Dia 22 (b)'!$X19 -> 15.999469 | X13: ='[3]Dia 23 (b)'!$X19 -> 12.326641 | Y13: ='[3]Dia 24 (b)'!$X19 -> 13.453177 | Z13: ='[3]Dia 25 (b)'!$X19 -> 13.705984 | AA13: ='[3]Dia 26 (b)'!$X19 -> 12.691785 | AB13: ='[3]Dia 27 (b)'!$X19 -> 12.906378 | AC13: ='[3]Dia 28 (b)'!$X19 -> 15.087744 | AD13: ='[3]Dia 29 (b)'!$X19 -> 15.306216 | AE13: ='[3]Dia 30 (b)'!$X19 -> 14.462112 | AF13: ='[3]Dia 31 (b)'!$X19 -> 12.853553
A14: 11 | B14: ='[3]Dia 1 (b)'!$X20 -> 17.024675 | C14: ='[3]Dia 2 (b)'!$X20 -> 12.136278 | D14: ='[3]Dia 3 (b)'!$X20 -> 14.709388 | E14: ='[3]Dia 4 (b)'!$X20 -> 14.321531 | F14: ='[3]Dia 5 (b)'!$X20 -> 16.535686 | G14: ='[3]Dia 6 (b)'!$X20 -> 15.386962 | H14: ='[3]Dia 7 (b)'!$X20 -> 16.448955 | I14: ='[3]Dia 8 (b)'!$X20 -> 16.033574 | J14: ='[3]Dia 9 (b)'!$X20 -> 17.976996 | K14: ='[3]Dia 10 (b)'!$X20 -> 17.158447 | L14: ='[3]Dia 11 (b)'!$X20 -> 12.869405 | M14: ='[3]Dia 12 (b)'!$X20 -> 12.237467 | N14: ='[3]Dia 13 (b)'!$X20 -> 15.640706 | O14: ='[3]Dia 14 (b)'!$X20 -> 16.290926 | P14: ='[3]Dia 15 (b)'!$X20 -> 14.665973 | Q14: ='[3]Dia 16 (b)'!$X20 -> 15.303156 | R14: ='[3]Dia 17 (b)'!$X20 -> 16.582767 | S14: ='[3]Dia 18 (b)'!$X20 -> 15.292863 | T14: ='[3]Dia 19 (b)'!$X20 -> 17.503584 | U14: ='[3]Dia 20 (b)'!$X20 -> 16.782703 | V14: ='[3]Dia 21 (b)'!$X20 -> 16.980063 | W14: ='[3]Dia 22 (b)'!$X20 -> 15.017223 | X14: ='[3]Dia 23 (b)'!$X20 -> 12.78955 | Y14: ='[3]Dia 24 (b)'!$X20 -> 13.844383 | Z14: ='[3]Dia 25 (b)'!$X20 -> 14.410144 | AA14: ='[3]Dia 26 (b)'!$X20 -> 12.686253 | AB14: ='[3]Dia 27 (b)'!$X20 -> 13.547441 | AC14: ='[3]Dia 28 (b)'!$X20 -> 15.281822 | AD14: ='[3]Dia 29 (b)'!$X20 -> 14.996543 | AE14: ='[3]Dia 30 (b)'!$X20 -> 14.566801 | AF14: ='[3]Dia 31 (b)'!$X20 -> 10.14021
A15: 12 | B15: ='[3]Dia 1 (b)'!$X21 -> 16.520704 | C15: ='[3]Dia 2 (b)'!$X21 -> 13.496984 | D15: ='[3]Dia 3 (b)'!$X21 -> 15.073296 | E15: ='[3]Dia 4 (b)'!$X21 -> 15.330543 | F15: ='[3]Dia 5 (b)'!$X21 -> 16.425788 | G15: ='[3]Dia 6 (b)'!$X21 -> 16.138458 | H15: ='[3]Dia 7 (b)'!$X21 -> 16.683303 | I15: ='[3]Dia 8 (b)'!$X21 -> 15.744827 | J15: ='[3]Dia 9 (b)'!$X21 -> 16.907891 | K15: ='[3]Dia 10 (b)'!$X21 -> 19.573888 | L15: ='[3]Dia 11 (b)'!$X21 -> 11.797719 | M15: ='[3]Dia 12 (b)'!$X21 -> 13.762455 | N15: ='[3]Dia 13 (b)'!$X21 -> 14.361365 | O15: ='[3]Dia 14 (b)'!$X21 -> 15.720799 | P15: ='[3]Dia 15 (b)'!$X21 -> 13.781521 | Q15: ='[3]Dia 16 (b)'!$X21 -> 15.76967 | R15: ='[3]Dia 17 (b)'!$X21 -> 16.172666 | S15: ='[3]Dia 18 (b)'!$X21 -> 15.994065 | T15: ='[3]Dia 19 (b)'!$X21 -> 16.623804 | U15: ='[3]Dia 20 (b)'!$X21 -> 16.409206 | V15: ='[3]Dia 21 (b)'!$X21 -> 16.817299 | W15: ='[3]Dia 22 (b)'!$X21 -> 14.878696 | X15: ='[3]Dia 23 (b)'!$X21 -> 12.833541 | Y15: ='[3]Dia 24 (b)'!$X21 -> 13.884088 | Z15: ='[3]Dia 25 (b)'!$X21 -> 14.467752 | AA15: ='[3]Dia 26 (b)'!$X21 -> 13.471629 | AB15: ='[3]Dia 27 (b)'!$X21 -> 13.779554 | AC15: ='[3]Dia 28 (b)'!$X21 -> 15.286804 | AD15: ='[3]Dia 29 (b)'!$X21 -> 15.14734 | AE15: ='[3]Dia 30 (b)'!$X21 -> 15.293209 | AF15: ='[3]Dia 31 (b)'!$X21 -> 9.557419
A16: 13 | B16: ='[3]Dia 1 (b)'!$X22 -> 16.116454 | C16: ='[3]Dia 2 (b)'!$X22 -> 14.10216 | D16: ='[3]Dia 3 (b)'!$X22 -> 13.294409 | E16: ='[3]Dia 4 (b)'!$X22 -> 13.328087 | F16: ='[3]Dia 5 (b)'!$X22 -> 16.539414 | G16: ='[3]Dia 6 (b)'!$X22 -> 16.724448 | H16: ='[3]Dia 7 (b)'!$X22 -> 16.78727 | I16: ='[3]Dia 8 (b)'!$X22 -> 16.451374 | J16: ='[3]Dia 9 (b)'!$X22 -> 17.468177 | K16: ='[3]Dia 10 (b)'!$X22 -> 16.605261 | L16: ='[3]Dia 11 (b)'!$X22 -> 13.147696 | M16: ='[3]Dia 12 (b)'!$X22 -> 15.325193 | N16: ='[3]Dia 13 (b)'!$X22 -> 17.218822 | O16: ='[3]Dia 14 (b)'!$X22 -> 15.638989 | P16: ='[3]Dia 15 (b)'!$X22 -> 14.01702 | Q16: ='[3]Dia 16 (b)'!$X22 -> 13.796302 | R16: ='[3]Dia 17 (b)'!$X22 -> 17.006224 | S16: ='[3]Dia 18 (b)'!$X22 -> 19.396704 | T16: ='[3]Dia 19 (b)'!$X22 -> 16.496835 | U16: ='[3]Dia 20 (b)'!$X22 -> 15.491551 | V16: ='[3]Dia 21 (b)'!$X22 -> 15.664893 | W16: ='[3]Dia 22 (b)'!$X22 -> 14.417396 | X16: ='[3]Dia 23 (b)'!$X22 -> 12.797304 | Y16: ='[3]Dia 24 (b)'!$X22 -> 13.896089 | Z16: ='[3]Dia 25 (b)'!$X22 -> 13.98295 | AA16: ='[3]Dia 26 (b)'!$X22 -> 13.185275 | AB16: ='[3]Dia 27 (b)'!$X22 -> 13.346119 | AC16: ='[3]Dia 28 (b)'!$X22 -> 15.793886 | AD16: ='[3]Dia 29 (b)'!$X22 -> 15.095042 | AE16: ='[3]Dia 30 (b)'!$X22 -> 14.691738 | AF16: ='[3]Dia 31 (b)'!$X22 -> 9.284445
A17: 14 | B17: ='[3]Dia 1 (b)'!$X23 -> 14.453521 | C17: ='[3]Dia 2 (b)'!$X23 -> 14.028599 | D17: ='[3]Dia 3 (b)'!$X23 -> 15.964479 | E17: ='[3]Dia 4 (b)'!$X23 -> 12.645956 | F17: ='[3]Dia 5 (b)'!$X23 -> 15.657716 | G17: ='[3]Dia 6 (b)'!$X23 -> 15.350235 | H17: ='[3]Dia 7 (b)'!$X23 -> 16.647852 | I17: ='[3]Dia 8 (b)'!$X23 -> 15.57522 | J17: ='[3]Dia 9 (b)'!$X23 -> 17.286345 | K17: ='[3]Dia 10 (b)'!$X23 -> 17.538788 | L17: ='[3]Dia 11 (b)'!$X23 -> 14.576173 | M17: ='[3]Dia 12 (b)'!$X23 -> 15.680507 | N17: ='[3]Dia 13 (b)'!$X23 -> 17.222517 | O17: ='[3]Dia 14 (b)'!$X23 -> 14.212657 | P17: ='[3]Dia 15 (b)'!$X23 -> 13.327549 | Q17: ='[3]Dia 16 (b)'!$X23 -> 15.225934 | R17: ='[3]Dia 17 (b)'!$X23 -> 14.508277 | S17: ='[3]Dia 18 (b)'!$X23 -> 18.877333 | T17: ='[3]Dia 19 (b)'!$X23 -> 16.348399 | U17: ='[3]Dia 20 (b)'!$X23 -> 16.118497 | V17: ='[3]Dia 21 (b)'!$X23 -> 16.647835 | W17: ='[3]Dia 22 (b)'!$X23 -> 14.68761 | X17: ='[3]Dia 23 (b)'!$X23 -> 12.844888 | Y17: ='[3]Dia 24 (b)'!$X23 -> 13.877371 | Z17: ='[3]Dia 25 (b)'!$X23 -> 14.469259 | AA17: ='[3]Dia 26 (b)'!$X23 -> 13.887534 | AB17: ='[3]Dia 27 (b)'!$X23 -> 13.649023 | AC17: ='[3]Dia 28 (b)'!$X23 -> 15.477802 | AD17: ='[3]Dia 29 (b)'!$X23 -> 15.292949 | AE17: ='[3]Dia 30 (b)'!$X23 -> 15.412342 | AF17: ='[3]Dia 31 (b)'!$X23 -> 9.259302
A18: 15 | B18: ='[3]Dia 1 (b)'!$X24 -> 16.990874 | C18: ='[3]Dia 2 (b)'!$X24 -> 14.413434 | D18: ='[3]Dia 3 (b)'!$X24 -> 17.371667 | E18: ='[3]Dia 4 (b)'!$X24 -> 17.301618 | F18: ='[3]Dia 5 (b)'!$X24 -> 18.588494 | G18: ='[3]Dia 6 (b)'!$X24 -> 15.978799 | H18: ='[3]Dia 7 (b)'!$X24 -> 16.824327 | I18: ='[3]Dia 8 (b)'!$X24 -> 18.49149 | J18: ='[3]Dia 9 (b)'!$X24 -> 18.124676 | K18: ='[3]Dia 10 (b)'!$X24 -> 16.933493 | L18: ='[3]Dia 11 (b)'!$X24 -> 15.273986 | M18: ='[3]Dia 12 (b)'!$X24 -> 15.379758 | N18: ='[3]Dia 13 (b)'!$X24 -> 16.911926 | O18: ='[3]Dia 14 (b)'!$X24 -> 18.918291 | P18: ='[3]Dia 15 (b)'!$X24 -> 13.29212 | Q18: ='[3]Dia 16 (b)'!$X24 -> 15.080993 | R18: ='[3]Dia 17 (b)'!$X24 -> 14.7603 | S18: ='[3]Dia 18 (b)'!$X24 -> 19.234601 | T18: ='[3]Dia 19 (b)'!$X24 -> 19.544906 | U18: ='[3]Dia 20 (b)'!$X24 -> 16.538572 | V18: ='[3]Dia 21 (b)'!$X24 -> 16.171342 | W18: ='[3]Dia 22 (b)'!$X24 -> 14.007954 | X18: ='[3]Dia 23 (b)'!$X24 -> 12.768453 | Y18: ='[3]Dia 24 (b)'!$X24 -> 14.598772 | Z18: ='[3]Dia 25 (b)'!$X24 -> 14.583678 | AA18: ='[3]Dia 26 (b)'!$X24 -> 14.152308 | AB18: ='[3]Dia 27 (b)'!$X24 -> 13.847826 | AC18: ='[3]Dia 28 (b)'!$X24 -> 15.245563 | AD18: ='[3]Dia 29 (b)'!$X24 -> 16.000664 | AE18: ='[3]Dia 30 (b)'!$X24 -> 15.748204 | AF18: ='[3]Dia 31 (b)'!$X24 -> 9.6930474
A19: 16
A20: 17
A21: 18
A22: 19
A23: 20
A24: 21
A25: 22
A26: 23
A27: 24
B28: NÃO ESTÃO SENDO MAIS INTERPOLADOS AS OBSERVAÇÕES ENTRE AS 16H E 6H.
A30: MÉDIA
A31: DIÁRIA
A34: MÁXIMA
A35: DIÁRIA
A38: MÍNIMA
A39: DIÁRIA
A42: AMPLITUDE
A43: DIÁRIA
H46: MÉDIA | K46: MÁXIMA | N46: MÍNIMA | Q46: AMPLITUDE | T46: MÉDIA | V46: MÉDIA | X46: DIF. DAS
H47: MENSAL | K47: MENSAL | N47: MENSAL | Q47: MENSAL | T47: DAS MÁX. | V47: DAS MÍN. | X47: MÉDIAS

Sheet Abr
B1: ='[4]Dia 1 (b)'!C1 -> ABRIL DE 2024 | K1: Umid. Específica (g.kg-1)
A3: H/D | B3: 1 | C3: 2 | D3: 3 | E3: 4 | F3: 5 | G3: 6 | H3: 7 | I3: 8 | J3: 9 | K3: 10 | L3: 11 | M3: 12 | N3: 13 | O3: 14 | P3: 15 | Q3: 16 | R3: 17 | S3: 18 | T3: 19 | U3: 20 | V3: 21 | W3: 22 | X3: 23 | Y3: 24 | Z3: 25 | AA3: 26 | AB3: 27 | AC3: 28 | AD3: 29 | AE3: 30
A4: 1
A5: 2
A6: 3
A7: 4
A8: 5
A9: 6
A10: 7 | B10: ='[4]Dia 1 (b)'!$X16 -> 13.832728 | C10: ='[4]Dia 2 (b)'!$X16 -> 14.112961 | D10: ='[4]Dia 3 (b)'!$X16 -> 14.675661 | E10: ='[4]Dia 4 (b)'!$X16 -> 13.560301 | F10: ='[4]Dia 5 (b)'!$X16 -> 14.667869 | G10: ='[4]Dia 6 (b)'!$X16 -> 14.781088 | H10: ='[4]Dia 7 (b)'!$X16 -> 13.786661 | I10: ='[4]Dia 8 (b)'!$X16 -> 14.356911 | J10: ='[4]Dia 9 (b)'!$X16 -> 14.208506 | K10: ='[4]Dia 10 (b)'!$X16 -> 14.133192 | L10: ='[4]Dia 11 (b)'!$X16 -> 14.812373 | M10: ='[4]Dia 12 (b)'!$X16 -> 14.22317 | N10: ='[4]Dia 13 (b)'!$X16 -> 13.781725 | O10: ='[4]Dia 14 (b)'!$X16 -> 14.715379 | P10: ='[4]Dia 15 (b)'!$X16 -> 14.995267 | Q10: ='[4]Dia 16 (b)'!$X16 -> 15.482771 | R10: ='[4]Dia 17 (b)'!$X16 -> 16.850957 | S10: ='[4]Dia 18 (b)'!$X16 -> 12.421625 | T10: ='[4]Dia 19 (b)'!$X16 -> 10.317221 | U10: ='[4]Dia 20 (b)'!$X16 -> 10.912962 | V10: ='[4]Dia 21 (b)'!$X16 -> 11.803015 | W10: ='[4]Dia 22 (b)'!$X16 -> 12.242346 | X10: ='[4]Dia 23 (b)'!$X16 -> 11.724184 | Y10: ='[4]Dia 24 (b)'!$X16 -> 12.284463 | Z10: ='[4]Dia 25 (b)'!$X16 -> 14.212875 | AA10: ='[4]Dia 26 (b)'!$X16 -> 14.307864 | AB10: ='[4]Dia 27 (b)'!$X16 -> 14.818492 | AC10: ='[4]Dia 28 (b)'!$X16 -> 13.90565 | AD10: ='[4]Dia 29 (b)'!$X16 -> 15.113421 | AE10: ='[4]Dia 30 (b)'!$X16 -> 14.34669
A11: 8 | B11: ='[4]Dia 1 (b)'!$X17 -> 12.621492 | C11: ='[4]Dia 2 (b)'!$X17 -> 14.136764 | D11: ='[4]Dia 3 (b)'!$X17 -> 14.78013 | E11: ='[4]Dia 4 (b)'!$X17 -> 14.465106 | F11: ='[4]Dia 5 (b)'!$X17 -> 14.644888 | G11: ='[4]Dia 6 (b)'!$X17 -> 13.997202 | H11: ='[4]Dia 7 (b)'!$X17 -> 13.798754 | I11: ='[4]Dia 8 (b)'!$X17 -> 14.612168 | J11: ='[4]Dia 9 (b)'!$X17 -> 15.705127 | K11: ='[4]Dia 10 (b)'!$X17 -> 15.130224 | L11: ='[4]Dia 11 (b)'!$X17 -> 15.041602 | M11: ='[4]Dia 12 (b)'!$X17 -> 14.458901 | N11: ='[4]Dia 13 (b)'!$X17 -> 13.880767 | O11: ='[4]Dia 14 (b)'!$X17 -> 14.797103 | P11: ='[4]Dia 15 (b)'!$X17 -> 15.448978 | Q11: ='[4]Dia 16 (b)'!$X17 -> 15.842464 | R11: ='[4]Dia 17 (b)'!$X17 -> 17.620611 | S11: ='[4]Dia 18 (b)'!$X17 -> 12.126157 | T11: ='[4]Dia 19 (b)'!$X17 -> 10.346387 | U11: ='[4]Dia 20 (b)'!$X17 -> 11.246839 | V11: ='[4]Dia 21 (b)'!$X17 -> 11.826151 | W11: ='[4]Dia 22 (b)'!$X17 -> 12.764581 | X11: ='[4]Dia 23 (b)'!$X17 -> 12.395416 | Y11: ='[4]Dia 24 (b)'!$X17 -> 13.545273 | Z11: ='[4]Dia 25 (b)'!$X17 -> 14.332233 | AA11: ='[4]Dia 26 (b)'!$X17 -> 14.703615 | AB11: ='[4]Dia 27 (b)'!$X17 -> 15.099978 | AC11: ='[4]Dia 28 (b)'!$X17 -> 14.196354 | AD11: ='[4]Dia 29 (b)'!$X17 -> 14.854488 | AE11: ='[4]Dia 30 (b)'!$X17 -> 14.439717
A12: 9 | B12: ='[4]Dia 1 (b)'!$X18 -> 13.190412 | C12: ='[4]Dia 2 (b)'!$X18 -> 14.554917 | D12: ='[4]Dia 3 (b)'!$X18 -> 13.556447 | E12: ='[4]Dia 4 (b)'!$X18 -> 14.949234 | F12: ='[4]Dia 5 (b)'!$X18 -> 14.455133 | G12: ='[4]Dia 6 (b)'!$X18 -> 13.808385 | H12: ='[4]Dia 7 (b)'!$X18 -> 13.948523 | I12: ='[4]Dia 8 (b)'!$X18 -> 14.462931 | J12: ='[4]Dia 9 (b)'!$X18 -> 16.016614 | K12: ='[4]Dia 10 (b)'!$X18 -> 15.290175 | L12: ='[4]Dia 11 (b)'!$X18 -> 15.363103 | M12: ='[4]Dia 12 (b)'!$X18 -> 13.789905 | N12: ='[4]Dia 13 (b)'!$X18 -> 14.175762 | O12: ='[4]Dia 14 (b)'!$X18 -> 14.792544 | P12: ='[4]Dia 15 (b)'!$X18 -> 16.191058 | Q12: ='[4]Dia 16 (b)'!$X18 -> 15.646324 | R12: ='[4]Dia 17 (b)'!$X18 -> 17.469208 | S12: ='[4]Dia 18 (b)'!$X18 -> 11.996598 | T12: ='[4]Dia 19 (b)'!$X18 -> 7.523157 | U12: ='[4]Dia 20 (b)'!$X18 -> 11.243354 | V12: ='[4]Dia 21 (b)'!$X18 -> 12.302938 | W12: ='[4]Dia 22 (b)'!$X18 -> 12.269896 | X12: ='[4]Dia 23 (b)'!$X18 -> 11.346751 | Y12: ='[4]Dia 24 (b)'!$X18 -> 10.80453 | Z12: ='[4]Dia 25 (b)'!$X18 -> 13.872523 | AA12: ='[4]Dia 26 (b)'!$X18 -> 14.453107 | AB12: ='[4]Dia 27 (b)'!$X18 -> 14.592456 | AC12: ='[4]Dia 28 (b)'!$X18 -> 13.456315 | AD12: ='[4]Dia 29 (b)'!$X18 -> 14.959906 | AE12: ='[4]Dia 30 (b)'!$X18 -> 13.196368
A13: 10 | B13: ='[4]Dia 1 (b)'!$X19 -> 12.32197 | C13: ='[4]Dia 2 (b)'!$X19 -> 14.12952 | D13: ='[4]Dia 3 (b)'!$X19 -> 14.171475 | E13: ='[4]Dia 4 (b)'!$X19 -> 14.729749 | F13: ='[4]Dia 5 (b)'!$X19 -> 14.068168 | G13: ='[4]Dia 6 (b)'!$X19 -> 13.256999 | H13: ='[4]Dia 7 (b)'!$X19 -> 13.680441 | I13: ='[4]Dia 8 (b)'!$X19 -> 14.405453 | J13: ='[4]Dia 9 (b)'!$X19 -> 15.068287 | K13: ='[4]Dia 10 (b)'!$X19 -> 14.679509 | L13: ='[4]Dia 11 (b)'!$X19 -> 14.984623 | M13: ='[4]Dia 12 (b)'!$X19 -> 14.152773 | N13: ='[4]Dia 13 (b)'!$X19 -> 14.707755 | O13: ='[4]Dia 14 (b)'!$X19 -> 14.546715 | P13: ='[4]Dia 15 (b)'!$X19 -> 16.062361 | Q13: ='[4]Dia 16 (b)'!$X19 -> 14.974444 | R13: ='[4]Dia 17 (b)'!$X19 -> 15.381687 | S13: ='[4]Dia 18 (b)'!$X19 -> 11.225327 | T13: ='[4]Dia 19 (b)'!$X19 -> 7.1146639 | U13: ='[4]Dia 20 (b)'!$X19 -> 10.908215 | V13: ='[4]Dia 21 (b)'!$X19 -> 12.103561 | W13: ='[4]Dia 22 (b)'!$X19 -> 11.845078 | X13: ='[4]Dia 23 (b)'!$X19 -> 9.9103304 | Y13: ='[4]Dia 24 (b)'!$X19 -> 11.775467 | Z13: ='[4]Dia 25 (b)'!$X19 -> 14.702493 | AA13: ='[4]Dia 26 (b)'!$X19 -> 14.168454 | AB13: ='[4]Dia 27 (b)'!$X19 -> 14.365825 | AC13: ='[4]Dia 28 (b)'!$X19 -> 12.554836 | AD13: ='[4]Dia 29 (b)'!$X19 -> 14.935911 | AE13: ='[4]Dia 30 (b)'!$X19 -> 12.311884
A14: 11 | B14: ='[4]Dia 1 (b)'!$X20 -> 11.693026 | C14: ='[4]Dia 2 (b)'!$X20 -> 13.528606 | D14: ='[4]Dia 3 (b)'!$X20 -> 14.444995 | E14: ='[4]Dia 4 (b)'!$X20 -> 14.705882 | F14: ='[4]Dia 5 (b)'!$X20 -> 12.802908 | G14: ='[4]Dia 6 (b)'!$X20 -> 13.561201 | H14: ='[4]Dia 7 (b)'!$X20 -> 14.487936 | I14: ='[4]Dia 8 (b)'!$X20 -> 14.328349 | J14: ='[4]Dia 9 (b)'!$X20 -> 13.844236 | K14: ='[4]Dia 10 (b)'!$X20 -> 14.884197 | L14: ='[4]Dia 11 (b)'!$X20 -> 14.838489 | M14: ='[4]Dia 12 (b)'!$X20 -> 13.635708 | N14: ='[4]Dia 13 (b)'!$X20 -> 13.516678 | O14: ='[4]Dia 14 (b)'!$X20 -> 14.580833 | P14: ='[4]Dia 15 (b)'!$X20 -> 15.000868 | Q14: ='[4]Dia 16 (b)'!$X20 -> 14.012245 | R14: ='[4]Dia 17 (b)'!$X20 -> 15.290596 | S14: ='[4]Dia 18 (b)'!$X20 -> 11.454083 | T14: ='[4]Dia 19 (b)'!$X20 -> 6.4224499 | U14: ='[4]Dia 20 (b)'!$X20 -> 11.206191 | V14: ='[4]Dia 21 (b)'!$X20 -> 12.129661 | W14: ='[4]Dia 22 (b)'!$X20 -> 10.739222 | X14: ='[4]Dia 23 (b)'!$X20 -> 10.458194 | Y14: ='[4]Dia 24 (b)'!$X20 -> 11.416895 | Z14: ='[4]Dia 25 (b)'!$X20 -> 15.150887 | AA14: ='[4]Dia 26 (b)'!$X20 -> 14.462509 | AB14: ='[4]Dia 27 (b)'!$X20 -> 13.785606 | AC14: ='[4]Dia 28 (b)'!$X20 -> 12.766393 | AD14: ='[4]Dia 29 (b)'!$X20 -> 15.364805 | AE14: ='[4]Dia 30 (b)'!$X20 -> 11.1283
A15: 12 | B15: ='[4]Dia 1 (b)'!$X21 -> 10.415036 | C15: ='[4]Dia 2 (b)'!$X21 -> 12.146531 | D15: ='[4]Dia 3 (b)'!$X21 -> 13.666667 | E15: ='[4]Dia 4 (b)'!$X21 -> 14.423089 | F15: ='[4]Dia 5 (b)'!$X21 -> 11.095842 | G15: ='[4]Dia 6 (b)'!$X21 -> 14.200527 | H15: ='[4]Dia 7 (b)'!$X21 -> 13.503861 | I15: ='[4]Dia 8 (b)'!$X21 -> 14.410083 | J15: ='[4]Dia 9 (b)'!$X21 -> 14.010183 | K15: ='[4]Dia 10 (b)'!$X21 -> 13.358218 | L15: ='[4]Dia 11 (b)'!$X21 -> 15.002746 | M15: ='[4]Dia 12 (b)'!$X21 -> 14.010525 | N15: ='[4]Dia 13 (b)'!$X21 -> 13.196173 | O15: ='[4]Dia 14 (b)'!$X21 -> 14.011603 | P15: ='[4]Dia 15 (b)'!$X21 -> 14.752119 | Q15: ='[4]Dia 16 (b)'!$X21 -> 14.201694 | R15: ='[4]Dia 17 (b)'!$X21 -> 15.136819 | S15: ='[4]Dia 18 (b)'!$X21 -> 11.229824 | T15: ='[4]Dia 19 (b)'!$X21 -> 7.4175313 | U15: ='[4]Dia 20 (b)'!$X21 -> 11.224738 | V15: ='[4]Dia 21 (b)'!$X21 -> 11.095321 | W15: ='[4]Dia 22 (b)'!$X21 -> 9.0580585 | X15: ='[4]Dia 23 (b)'!$X21 -> 9.3169497 | Y15: ='[4]Dia 24 (b)'!$X21 -> 11.052587 | Z15: ='[4]Dia 25 (b)'!$X21 -> 15.096293 | AA15: ='[4]Dia 26 (b)'!$X21 -> 14.157318 | AB15: ='[4]Dia 27 (b)'!$X21 -> 14.092087 | AC15: ='[4]Dia 28 (b)'!$X21 -> 13.244107 | AD15: ='[4]Dia 29 (b)'!$X21 -> 15.488314 | AE15: ='[4]Dia 30 (b)'!$X21 -> 11.174472
A16: 13 | B16: ='[4]Dia 1 (b)'!$X22 -> 8.4931767 | C16: ='[4]Dia 2 (b)'!$X22 -> 12.205355 | D16: ='[4]Dia 3 (b)'!$X22 -> 13.936531 | E16: ='[4]Dia 4 (b)'!$X22 -> 13.721831 | F16: ='[4]Dia 5 (b)'!$X22 -> 9.7177735 | G16: ='[4]Dia 6 (b)'!$X22 -> 14.76534 | H16: ='[4]Dia 7 (b)'!$X22 -> 13.336446 | I16: ='[4]Dia 8 (b)'!$X22 -> 14.67127 | J16: ='[4]Dia 9 (b)'!$X22 -> 14.272775 | K16: ='[4]Dia 10 (b)'!$X22 -> 13.551267 | L16: ='[4]Dia 11 (b)'!$X22 -> 16.431747 | M16: ='[4]Dia 12 (b)'!$X22 -> 15.052914 | N16: ='[4]Dia 13 (b)'!$X22 -> 13.535364 | O16: ='[4]Dia 14 (b)'!$X22 -> 14.788859 | P16: ='[4]Dia 15 (b)'!$X22 -> 14.072833 | Q16: ='[4]Dia 16 (b)'!$X22 -> 12.888892 | R16: ='[4]Dia 17 (b)'!$X22 -> 15.387715 | S16: ='[4]Dia 18 (b)'!$X22 -> 11.799491 | T16: ='[4]Dia 19 (b)'!$X22 -> 9.0490232 | U16: ='[4]Dia 20 (b)'!$X22 -> 11.368761 | V16: ='[4]Dia 21 (b)'!$X22 -> 9.369145 | W16: ='[4]Dia 22 (b)'!$X22 -> 8.9840566 | X16: ='[4]Dia 23 (b)'!$X22 -> 9.9555119 | Y16: ='[4]Dia 24 (b)'!$X22 -> 11.586195 | Z16: ='[4]Dia 25 (b)'!$X22 -> 15.568091 | AA16: ='[4]Dia 26 (b)'!$X22 -> 14.553073 | AB16: ='[4]Dia 27 (b)'!$X22 -> 13.058423 | AC16: ='[4]Dia 28 (b)'!$X22 -> 12.112695 | AD16: ='[4]Dia 29 (b)'!$X22 -> 13.899878 | AE16: ='[4]Dia 30 (b)'!$X22 -> 10.220167
A17: 14 | B17: ='[4]Dia 1 (b)'!$X23 -> 8.6646279 | C17: ='[4]Dia 2 (b)'!$X23 -> 13.200747 | D17: ='[4]Dia 3 (b)'!$X23 -> 13.419919 | E17: ='[4]Dia 4 (b)'!$X23 -> 12.658953 | F17: ='[4]Dia 5 (b)'!$X23 -> 10.524497 | G17: ='[4]Dia 6 (b)'!$X23 -> 14.920172 | H17: ='[4]Dia 7 (b)'!$X23 -> 15.170404 | I17: ='[4]Dia 8 (b)'!$X23 -> 15.075589 | J17: ='[4]Dia 9 (b)'!$X23 -> 13.863063 | K17: ='[4]Dia 10 (b)'!$X23 -> 15.702196 | L17: ='[4]Dia 11 (b)'!$X23 -> 15.904567 | M17: ='[4]Dia 12 (b)'!$X23 -> 14.958442 | N17: ='[4]Dia 13 (b)'!$X23 -> 12.882588 | O17: ='[4]Dia 14 (b)'!$X23 -> 15.258646 | P17: ='[4]Dia 15 (b)'!$X23 -> 13.917082 | Q17: ='[4]Dia 16 (b)'!$X23 -> 14.964954 | R17: ='[4]Dia 17 (b)'!$X23 -> 15.674576 | S17: ='[4]Dia 18 (b)'!$X23 -> 12.162064 | T17: ='[4]Dia 19 (b)'!$X23 -> 9.1663765 | U17: ='[4]Dia 20 (b)'!$X23 -> 13.25387 | V17: ='[4]Dia 21 (b)'!$X23 -> 9.1335867 | W17: ='[4]Dia 22 (b)'!$X23 -> 8.5346035 | X17: ='[4]Dia 23 (b)'!$X23 -> 8.9626742 | Y17: ='[4]Dia 24 (b)'!$X23 -> 12.213833 | Z17: ='[4]Dia 25 (b)'!$X23 -> 15.726789 | AA17: ='[4]Dia 26 (b)'!$X23 -> 13.80342 | AB17: ='[4]Dia 27 (b)'!$X23 -> 13.115368 | AC17: ='[4]Dia 28 (b)'!$X23 -> 12.635773 | AD17: ='[4]Dia 29 (b)'!$X23 -> 13.979482 | AE17: ='[4]Dia 30 (b)'!$X23 -> 10.234526
A18: 15 | B18: ='[4]Dia 1 (b)'!$X24 -> 9.575691 | C18: ='[4]Dia 2 (b)'!$X24 -> 16.818937 | D18: ='[4]Dia 3 (b)'!$X24 -> 16.051343 | E18: ='[4]Dia 4 (b)'!$X24 -> 15.228763 | F18: ='[4]Dia 5 (b)'!$X24 -> 11.172014 | G18: ='[4]Dia 6 (b)'!$X24 -> 14.912301 | H18: ='[4]Dia 7 (b)'!$X24 -> 14.616517 | I18: ='[4]Dia 8 (b)'!$X24 -> 16.199938 | J18: ='[4]Dia 9 (b)'!$X24 -> 15.142354 | K18: ='[4]Dia 10 (b)'!$X24 -> 16.59027 | L18: ='[4]Dia 11 (b)'!$X24 -> 15.480438 | M18: ='[4]Dia 12 (b)'!$X24 -> 15.00767 | N18: ='[4]Dia 13 (b)'!$X24 -> 16.219248 | O18: ='[4]Dia 14 (b)'!$X24 -> 15.029645 | P18: ='[4]Dia 15 (b)'!$X24 -> 16.430964 | Q18: ='[4]Dia 16 (b)'!$X24 -> 13.823186 | R18: ='[4]Dia 17 (b)'!$X24 -> 15.445951 | S18: ='[4]Dia 18 (b)'!$X24 -> 11.561516 | T18: ='[4]Dia 19 (b)'!$X24 -> 9.5451644 | U18: ='[4]Dia 20 (b)'!$X24 -> 13.247476 | V18: ='[4]Dia 21 (b)'!$X24 -> 9.6986019 | W18: ='[4]Dia 22 (b)'!$X24 -> 9.0026711 | X18: ='[4]Dia 23 (b)'!$X24 -> 9.5659365 | Y18: ='[4]Dia 24 (b)'!$X24 -> 12.857065 | Z18: ='[4]Dia 25 (b)'!$X24 -> 15.414882 | AA18: ='[4]Dia 26 (b)'!$X24 -> 16.286179 | AB18: ='[4]Dia 27 (b)'!$X24 -> 12.658992 | AC18: ='[4]Dia 28 (b)'!$X24 -> 12.262361 | AD18: ='[4]Dia 29 (b)'!$X24 -> 12.392918 | AE18: ='[4]Dia 30 (b)'!$X24 -> 10.279327
A19: 16
A20: 17
A21: 18
A22: 19
A23: 20
A24: 21
A25: 22
A26: 23
A27: 24
B28: NÃO ESTÃO SENDO MAIS INTERPOLADOS AS OBSERVAÇÕES ENTRE AS 16H E 6H.
A30: MÉDIA
A31: DIÁRIA
A34: MÁXIMA
A35: DIÁRIA
A38: MÍNIMA
A39: DIÁRIA
A42: AMPLITUDE
A43: DIÁRIA
H46: MÉDIA | K46: MÁXIMA | N46: MÍNIMA | Q46: AMPLITUDE | T46: MÉDIA | V46: MÉDIA | X46: DIF. DAS
H47: MENSAL | K47: MENSAL | N47: MENSAL | Q47: MENSAL | T47: DAS MÁX. | V47: DAS MÍN. | X47: MÉDIAS

Sheet Mai
B1: ='[5]Dia 1 (b)'!C1 -> MAIO DE 2024 | K1: Umid. Específica (g.kg-1)
A3: H/D | B3: 1 | C3: 2 | D3: 3 | E3: 4 | F3: 5 | G3: 6 | H3: 7 | I3: 8 | J3: 9 | K3: 10 | L3: 11 | M3: 12 | N3: 13 | O3: 14 | P3: 15 | Q3: 16 | R3: 17 | S3: 18 | T3: 19 | U3: 20 | V3: 21 | W3: 22 | X3: 23 | Y3: 24 | Z3: 25 | AA3: 26 | AB3: 27 | AC3: 28 | AD3: 29 | AE3: 30 | AF3: 31
A4: 1
A5: 2
A6: 3
A7: 4
A8: 5
A9: 6
A10: 7 | B10: ='[5]Dia 1 (b)'!$X16 -> 13.076039 | C10: ='[5]Dia 2 (b)'!$X16 -> 13.28152 | D10: ='[5]Dia 3 (b)'!$X16 -> 13.646748 | E10: ='[5]Dia 4 (b)'!$X16 -> 14.02562 | F10: ='[5]Dia 5 (b)'!$X16 -> 12.59998 | G10: ='[5]Dia 6 (b)'!$X16 -> 12.488761 | H10: ='[5]Dia 7 (b)'!$X16 -> 11.99583 | I10: ='[5]Dia 8 (b)'!$X16 -> 13.345256 | J10: ='[5]Dia 9 (b)'!$X16 -> 12.174733 | K10: ='[5]Dia 10 (b)'!$X16 -> 14.151126 | L10: ='[5]Dia 11 (b)'!$X16 -> 13.987387 | M10: ='[5]Dia 12 (b)'!$X16 -> 11.724709 | N10: ='[5]Dia 13 (b)'!$X16 -> 9.9141377 | O10: ='[5]Dia 14 (b)'!$X16 -> 14.253081 | P10: ='[5]Dia 15 (b)'!$X16 -> 11.615484 | Q10: ='[5]Dia 16 (b)'!$X16 -> 12.344332 | R10: ='[5]Dia 17 (b)'!$X16 -> 13.298505 | S10: ='[5]Dia 18 (b)'!$X16 -> 13.290728 | T10: ='[5]Dia 19 (b)'!$X16 -> 13.203741 | U10: ='[5]Dia 20 (b)'!$X16 -> 14.586577 | V10: ='[5]Dia 21 (b)'!$X16 -> 11.391452 | W10: ='[5]Dia 22 (b)'!$X16 -> 12.875017 | X10: ='[5]Dia 23 (b)'!$X16 -> 11.481474 | Y10: ='[5]Dia 24 (b)'!$X16 -> 10.426677 | Z10: ='[5]Dia 25 (b)'!$X16 -> 11.660049 | AA10: ='[5]Dia 26 (b)'!$X16 -> 10.697056 | AB10: ='[5]Dia 27 (b)'!$X16 -> 11.529647 | AC10: ='[5]Dia 28 (b)'!$X16 -> 12.885681 | AD10: ='[5]Dia 29 (b)'!$X16 -> 7.6544579 | AE10: ='[5]Dia 30 (b)'!$X16 -> 7.7630254 | AF10: ='[5]Dia 31 (b)'!$X16 -> 9.0568713
A11: 8 | B11: ='[5]Dia 1 (b)'!$X17 -> 13.565537 | C11: ='[5]Dia 2 (b)'!$X17 -> 14.927239 | D11: ='[5]Dia 3 (b)'!$X17 -> 15.569724 | E11: ='[5]Dia 4 (b)'!$X17 -> 14.125349 | F11: ='[5]Dia 5 (b)'!$X17 -> 13.653581 | G11: ='[5]Dia 6 (b)'!$X17 -> 12.64106 | H11: ='[5]Dia 7 (b)'!$X17 -> 13.200612 | I11: ='[5]Dia 8 (b)'!$X17 -> 13.164325 | J11: ='[5]Dia 9 (b)'!$X17 -> 14.236695 | K11: ='[5]Dia 10 (b)'!$X17 -> 14.662095 | L11: ='[5]Dia 11 (b)'!$X17 -> 14.839012 | M11: ='[5]Dia 12 (b)'!$X17 -> 12.349505 | N11: ='[5]Dia 13 (b)'!$X17 -> 10.292855 | O11: ='[5]Dia 14 (b)'!$X17 -> 14.010165 | P11: ='[5]Dia 15 (b)'!$X17 -> 11.764804 | Q11: ='[5]Dia 16 (b)'!$X17 -> 12.66582 | R11: ='[5]Dia 17 (b)'!$X17 -> 13.864437 | S11: ='[5]Dia 18 (b)'!$X17 -> 13.953437 | T11: ='[5]Dia 19 (b)'!$X17 -> 13.249366 | U11: ='[5]Dia 20 (b)'!$X17 -> 15.430169 | V11: ='[5]Dia 21 (b)'!$X17 -> 11.686368 | W11: ='[5]Dia 22 (b)'!$X17 -> 12.953556 | X11: ='[5]Dia 23 (b)'!$X17 -> 12.407344 | Y11: ='[5]Dia 24 (b)'!$X17 -> 11.731831 | Z11: ='[5]Dia 25 (b)'!$X17 -> 11.801817 | AA11: ='[5]Dia 26 (b)'!$X17 -> 10.677432 | AB11: ='[5]Dia 27 (b)'!$X17 -> 11.61005 | AC11: ='[5]Dia 28 (b)'!$X17 -> 12.544317 | AD11: ='[5]Dia 29 (b)'!$X17 -> 7.6587687 | AE11: ='[5]Dia 30 (b)'!$X17 -> 8.7867065 | AF11: ='[5]Dia 31 (b)'!$X17 -> 9.4274988
A12: 9 | B12: ='[5]Dia 1 (b)'!$X18 -> 13.664489 | C12: ='[5]Dia 2 (b)'!$X18 -> 12.494766 | D12: ='[5]Dia 3 (b)'!$X18 -> 15.276672 | E12: ='[5]Dia 4 (b)'!$X18 -> 13.709085 | F12: ='[5]Dia 5 (b)'!$X18 -> 12.904417 | G12: ='[5]Dia 6 (b)'!$X18 -> 12.29537 | H12: ='[5]Dia 7 (b)'!$X18 -> 13.208491 | I12: ='[5]Dia 8 (b)'!$X18 -> 12.597873 | J12: ='[5]Dia 9 (b)'!$X18 -> 12.059115 | K12: ='[5]Dia 10 (b)'!$X18 -> 14.020434 | L12: ='[5]Dia 11 (b)'!$X18 -> 13.390937 | M12: ='[5]Dia 12 (b)'!$X18 -> 11.438192 | N12: ='[5]Dia 13 (b)'!$X18 -> 10.503168 | O12: ='[5]Dia 14 (b)'!$X18 -> 13.357082 | P12: ='[5]Dia 15 (b)'!$X18 -> 11.837846 | Q12: ='[5]Dia 16 (b)'!$X18 -> 12.616654 | R12: ='[5]Dia 17 (b)'!$X18 -> 13.006501 | S12: ='[5]Dia 18 (b)'!$X18 -> 13.708815 | T12: ='[5]Dia 19 (b)'!$X18 -> 12.851914 | U12: ='[5]Dia 20 (b)'!$X18 -> 15.141812 | V12: ='[5]Dia 21 (b)'!$X18 -> 11.867706 | W12: ='[5]Dia 22 (b)'!$X18 -> 13.48515 | X12: ='[5]Dia 23 (b)'!$X18 -> 11.098795 | Y12: ='[5]Dia 24 (b)'!$X18 -> 10.721465 | Z12: ='[5]Dia 25 (b)'!$X18 -> 11.31063 | AA12: ='[5]Dia 26 (b)'!$X18 -> 10.669312 | AB12: ='[5]Dia 27 (b)'!$X18 -> 11.762312 | AC12: ='[5]Dia 28 (b)'!$X18 -> 12.449561 | AD12: ='[5]Dia 29 (b)'!$X18 -> 6.8548409 | AE12: ='[5]Dia 30 (b)'!$X18 -> 8.7072394 | AF12: ='[5]Dia 31 (b)'!$X18 -> 9.186825
A13: 10 | B13: ='[5]Dia 1 (b)'!$X19 -> 12.357599 | C13: ='[5]Dia 2 (b)'!$X19 -> 12.32204 | D13: ='[5]Dia 3 (b)'!$X19 -> 14.153181 | E13: ='[5]Dia 4 (b)'!$X19 -> 13.469445 | F13: ='[5]Dia 5 (b)'!$X19 -> 12.104228 | G13: ='[5]Dia 6 (b)'!$X19 -> 10.7018 | H13: ='[5]Dia 7 (b)'!$X19 -> 12.721499 | I13: ='[5]Dia 8 (b)'!$X19 -> 11.787368 | J13: ='[5]Dia 9 (b)'!$X19 -> 11.700916 | K13: ='[5]Dia 10 (b)'!$X19 -> 13.195635 | L13: ='[5]Dia 11 (b)'!$X19 -> 11.844729 | M13: ='[5]Dia 12 (b)'!$X19 -> 10.938913 | N13: ='[5]Dia 13 (b)'!$X19 -> 10.525949 | O13: ='[5]Dia 14 (b)'!$X19 -> 12.96656 | P13: ='[5]Dia 15 (b)'!$X19 -> 11.912835 | Q13: ='[5]Dia 16 (b)'!$X19 -> 12.988074 | R13: ='[5]Dia 17 (b)'!$X19 -> 11.544352 | S13: ='[5]Dia 18 (b)'!$X19 -> 12.998944 | T13: ='[5]Dia 19 (b)'!$X19 -> 12.778249 | U13: ='[5]Dia 20 (b)'!$X19 -> 15.737367 | V13: ='[5]Dia 21 (b)'!$X19 -> 12.138244 | W13: ='[5]Dia 22 (b)'!$X19 -> 13.079813 | X13: ='[5]Dia 23 (b)'!$X19 -> 10.597231 | Y13: ='[5]Dia 24 (b)'!$X19 -> 11.807983 | Z13: ='[5]Dia 25 (b)'!$X19 -> 11.730556 | AA13: ='[5]Dia 26 (b)'!$X19 -> 10.878191 | AB13: ='[5]Dia 27 (b)'!$X19 -> 12.026491 | AC13: ='[5]Dia 28 (b)'!$X19 -> 11.655376 | AD13: ='[5]Dia 29 (b)'!$X19 -> 6.8168077 | AE13: ='[5]Dia 30 (b)'!$X19 -> 8.5182696 | AF13: ='[5]Dia 31 (b)'!$X19 -> 9.0502285
A14: 11 | B14: ='[5]Dia 1 (b)'!$X20 -> 11.133595 | C14: ='[5]Dia 2 (b)'!$X20 -> 11.980876 | D14: ='[5]Dia 3 (b)'!$X20 -> 13.322539 | E14: ='[5]Dia 4 (b)'!$X20 -> 12.54433 | F14: ='[5]Dia 5 (b)'!$X20 -> 11.273915 | G14: ='[5]Dia 6 (b)'!$X20 -> 9.3554099 | H14: ='[5]Dia 7 (b)'!$X20 -> 12.675837 | I14: ='[5]Dia 8 (b)'!$X20 -> 11.319521 | J14: ='[5]Dia 9 (b)'!$X20 -> 12.152677 | K14: ='[5]Dia 10 (b)'!$X20 -> 13.255249 | L14: ='[5]Dia 11 (b)'!$X20 -> 11.775417 | M14: ='[5]Dia 12 (b)'!$X20 -> 11.118817 | N14: ='[5]Dia 13 (b)'!$X20 -> 9.5039167 | O14: ='[5]Dia 14 (b)'!$X20 -> 13.531907 | P14: ='[5]Dia 15 (b)'!$X20 -> 11.62706 | Q14: ='[5]Dia 16 (b)'!$X20 -> 13.31439 | R14: ='[5]Dia 17 (b)'!$X20 -> 11.474967 | S14: ='[5]Dia 18 (b)'!$X20 -> 12.890523 | T14: ='[5]Dia 19 (b)'!$X20 -> 12.741758 | U14: ='[5]Dia 20 (b)'!$X20 -> 15.054659 | V14: ='[5]Dia 21 (b)'!$X20 -> 12.180961 | W14: ='[5]Dia 22 (b)'!$X20 -> 12.545569 | X14: ='[5]Dia 23 (b)'!$X20 -> 9.7673595 | Y14: ='[5]Dia 24 (b)'!$X20 -> 12.890382 | Z14: ='[5]Dia 25 (b)'!$X20 -> 11.079022 | AA14: ='[5]Dia 26 (b)'!$X20 -> 11.50671 | AB14: ='[5]Dia 27 (b)'!$X20 -> 12.018192 | AC14: ='[5]Dia 28 (b)'!$X20 -> 11.951914 | AD14: ='[5]Dia 29 (b)'!$X20 -> 6.3630286 | AE14: ='[5]Dia 30 (b)'!$X20 -> 7.8776191 | AF14: ='[5]Dia 31 (b)'!$X20 -> 8.7852583
A15: 12 | B15: ='[5]Dia 1 (b)'!$X21 -> 11.180736 | C15: ='[5]Dia 2 (b)'!$X21 -> 11.962436 | D15: ='[5]Dia 3 (b)'!$X21 -> 16.495724 | E15: ='[5]Dia 4 (b)'!$X21 -> 10.967892 | F15: ='[5]Dia 5 (b)'!$X21 -> 8.3917447 | G15: ='[5]Dia 6 (b)'!$X21 -> 9.3433678 | H15: ='[5]Dia 7 (b)'!$X21 -> 10.876571 | I15: ='[5]Dia 8 (b)'!$X21 -> 11.22297 | J15: ='[5]Dia 9 (b)'!$X21 -> 11.620133 | K15: ='[5]Dia 10 (b)'!$X21 -> 13.075974 | L15: ='[5]Dia 11 (b)'!$X21 -> 11.231404 | M15: ='[5]Dia 12 (b)'!$X21 -> 9.2118727 | N15: ='[5]Dia 13 (b)'!$X21 -> 9.0929996 | O15: ='[5]Dia 14 (b)'!$X21 -> 13.827173 | P15: ='[5]Dia 15 (b)'!$X21 -> 11.752836 | Q15: ='[5]Dia 16 (b)'!$X21 -> 13.34062 | R15: ='[5]Dia 17 (b)'!$X21 -> 11.490741 | S15: ='[5]Dia 18 (b)'!$X21 -> 11.131223 | T15: ='[5]Dia 19 (b)'!$X21 -> 13.361476 | U15: ='[5]Dia 20 (b)'!$X21 -> 13.957935 | V15: ='[5]Dia 21 (b)'!$X21 -> 12.270633 | W15: ='[5]Dia 22 (b)'!$X21 -> 12.74784 | X15: ='[5]Dia 23 (b)'!$X21 -> 10.257588 | Y15: ='[5]Dia 24 (b)'!$X21 -> 12.108053 | Z15: ='[5]Dia 25 (b)'!$X21 -> 11.179094 | AA15: ='[5]Dia 26 (b)'!$X21 -> 11.264621 | AB15: ='[5]Dia 27 (b)'!$X21 -> 12.269004 | AC15: ='[5]Dia 28 (b)'!$X21 -> 11.957434 | AD15: ='[5]Dia 29 (b)'!$X21 -> 6.8449133 | AE15: ='[5]Dia 30 (b)'!$X21 -> 7.6368089 | AF15: ='[5]Dia 31 (b)'!$X21 -> 8.8932199
A16: 13 | B16: ='[5]Dia 1 (b)'!$X22 -> 10.429091 | C16: ='[5]Dia 2 (b)'!$X22 -> 10.256632 | D16: ='[5]Dia 3 (b)'!$X22 -> 13.297546 | E16: ='[5]Dia 4 (b)'!$X22 -> 10.118685 | F16: ='[5]Dia 5 (b)'!$X22 -> 7.5664279 | G16: ='[5]Dia 6 (b)'!$X22 -> 7.5921744 | H16: ='[5]Dia 7 (b)'!$X22 -> 10.460766 | I16: ='[5]Dia 8 (b)'!$X22 -> 11.253108 | J16: ='[5]Dia 9 (b)'!$X22 -> 10.494946 | K16: ='[5]Dia 10 (b)'!$X22 -> 12.103296 | L16: ='[5]Dia 11 (b)'!$X22 -> 10.369554 | M16: ='[5]Dia 12 (b)'!$X22 -> 9.6668101 | N16: ='[5]Dia 13 (b)'!$X22 -> 9.6280018 | O16: ='[5]Dia 14 (b)'!$X22 -> 14.301748 | P16: ='[5]Dia 15 (b)'!$X22 -> 11.677649 | Q16: ='[5]Dia 16 (b)'!$X22 -> 13.09067 | R16: ='[5]Dia 17 (b)'!$X22 -> 10.130529 | S16: ='[5]Dia 18 (b)'!$X22 -> 10.131255 | T16: ='[5]Dia 19 (b)'!$X22 -> 12.873453 | U16: ='[5]Dia 20 (b)'!$X22 -> 15.436874 | V16: ='[5]Dia 21 (b)'!$X22 -> 12.725131 | W16: ='[5]Dia 22 (b)'!$X22 -> 12.933712 | X16: ='[5]Dia 23 (b)'!$X22 -> 9.769204 | Y16: ='[5]Dia 24 (b)'!$X22 -> 13.368513 | Z16: ='[5]Dia 25 (b)'!$X22 -> 11.017174 | AA16: ='[5]Dia 26 (b)'!$X22 -> 10.808727 | AB16: ='[5]Dia 27 (b)'!$X22 -> 12.436872 | AC16: ='[5]Dia 28 (b)'!$X22 -> 11.546663 | AD16: ='[5]Dia 29 (b)'!$X22 -> 6.8967859 | AE16: ='[5]Dia 30 (b)'!$X22 -> 7.202059 | AF16: ='[5]Dia 31 (b)'!$X22 -> 9.4296373
A17: 14 | B17: ='[5]Dia 1 (b)'!$X23 -> 10.84572 | C17: ='[5]Dia 2 (b)'!$X23 -> 10.235644 | D17: ='[5]Dia 3 (b)'!$X23 -> 12.054506 | E17: ='[5]Dia 4 (b)'!$X23 -> 10.550421 | F17: ='[5]Dia 5 (b)'!$X23 -> 6.9932909 | G17: ='[5]Dia 6 (b)'!$X23 -> 8.3198695 | H17: ='[5]Dia 7 (b)'!$X23 -> 9.2833298 | I17: ='[5]Dia 8 (b)'!$X23 -> 10.721524 | J17: ='[5]Dia 9 (b)'!$X23 -> 10.413213 | K17: ='[5]Dia 10 (b)'!$X23 -> 11.84986 | L17: ='[5]Dia 11 (b)'!$X23 -> 9.0966274 | M17: ='[5]Dia 12 (b)'!$X23 -> 9.5966963 | N17: ='[5]Dia 13 (b)'!$X23 -> 8.8602958 | O17: ='[5]Dia 14 (b)'!$X23 -> 13.426026 | P17: ='[5]Dia 15 (b)'!$X23 -> 11.559515 | Q17: ='[5]Dia 16 (b)'!$X23 -> 13.315225 | R17: ='[5]Dia 17 (b)'!$X23 -> 9.8363085 | S17: ='[5]Dia 18 (b)'!$X23 -> 10.029986 | T17: ='[5]Dia 19 (b)'!$X23 -> 13.154963 | U17: ='[5]Dia 20 (b)'!$X23 -> 14.967143 | V17: ='[5]Dia 21 (b)'!$X23 -> 13.322103 | W17: ='[5]Dia 22 (b)'!$X23 -> 11.318421 | X17: ='[5]Dia 23 (b)'!$X23 -> 9.1454767 | Y17: ='[5]Dia 24 (b)'!$X23 -> 12.055292 | Z17: ='[5]Dia 25 (b)'!$X23 -> 10.653358 | AA17: ='[5]Dia 26 (b)'!$X23 -> 11.156249 | AB17: ='[5]Dia 27 (b)'!$X23 -> 12.534954 | AC17: ='[5]Dia 28 (b)'!$X23 -> 10.895508 | AD17: ='[5]Dia 29 (b)'!$X23 -> 6.8976754 | AE17: ='[5]Dia 30 (b)'!$X23 -> 8.0312726 | AF17: ='[5]Dia 31 (b)'!$X23 -> 9.663508
