Workbook

Sheet janeiro
B1: JANEIRO DE 2024 | J1: INSTITUTO ASTRONÔMICO E GEOFÍSICO DA UNIVERSIDADE DE SÃO PAULO | BE1: ultima 24horas | BG1: ultima 24horas
B2: DIGITADO POR PETY | AU2: Planilha atualizada por Edvaldo Gomes | BE2: até7h do dia | BG2: até 7H DO DIA ANTERIOR
B3: VERIFICADO POR PETY | M3: RESULTADOS EXTRAÍDOS DE PLUVIOGRAMA DIÁRIO (mm DE CHUVA)
AY4: VALORES DIÁRIOS | BE4: 7as7h do dia de hoje
AY5: (de 00h a 24h) | BE5: DAEE | BF5: DESVIO | BG5: EMAE
AY6: Altura | AZ6: Duração | BA6: Máxima | BE6: Altura | BG6: Máxima
A7: H. | B7: 0 - 1 | D7: 1 - 2 | F7: 2 - 3 | H7: 3 - 4 | J7: 4 - 5 | L7: 5 - 6 | N7: 6 - 7 | P7: 7 - 8 | R7: 8 - 9 | T7: 9 - 10 | V7: 10 - 11 | X7: 11 - 12 | Z7: 12 - 13 | AB7: 13 - 14 | AD7: 14 - 15 | AF7: 15 - 16 | AH7: 16 - 17 | AJ7: 17 - 18 | AL7: 18 - 19 | AN7: 19 - 20 | AP7: 20 - 21 | AR7: 21 - 22 | AT7: 22 - 23 | AV7: 23 - 24 | AX7: H. | AY7: total | AZ7: total | BA7: altura | BB7: Freq. | BE7: total | BG7: altura
A8: D. | B8: ALT. | C8: DUR. | D8: ALT. | E8: DUR. | F8: ALT. | G8: DUR. | H8: ALT. | I8: DUR. | J8: ALT. | K8: DUR. | L8: ALT. | M8: DUR. | N8: ALT. | O8: DUR. | P8: ALT. | Q8: DUR. | R8: ALT. | S8: DUR. | T8: ALT. | U8: DUR. | V8: ALT. | W8: DUR. | X8: ALT. | Y8: DUR. | Z8: ALT. | AA8: DUR. | AB8: ALT. | AC8: DUR. | AD8: ALT. | AE8: DUR. | AF8: ALT. | AG8: DUR. | AH8: ALT. | AI8: DUR. | AJ8: ALT. | AK8: DUR. | AL8: ALT. | AM8: DUR. | AN8: ALT. | AO8: DUR. | AP8: ALT. | AQ8: DUR. | AR8: ALT. | AS8: DUR. | AT8: ALT. | AU8: DUR. | AV8: ALT. | AW8: DUR. | AX8: D. | AY8: (mm) | AZ8: (min) | BA8: horária | BB8: (horas) | BE8: (mm) | BG8: horária | BH8: (horas)
A9: 31 | AX9: 31 | AY9: =B9+D9+F9+H9+J9+L9+N9+P9+R9+T9+V9+X9+Z9+AB9+AD9+AF9+AH9+AJ9+AL9+AN9+AP9+AR9+AT9+AV9 -> 0 | AZ9: =C9+E9+G9+I9+K9+M9+O9+Q9+S9+U9+W9+Y9+AA9+AC9+AE9+AG9+AI9+AK9+AM9+AO9+AQ9+AS9+AU9+AW9 -> 0 | BA9: =MAX(B9,D9,F9,H9,J9,L9,N9,P9,R9,T9,V9,X9,Z9,AB9,AD9,AF9,AH9,AJ9,AL9,AN9,AP9,AR9,AT9,AV9) -> 0 | BB9: =COUNT(B9,D9,F9,H9,J9,L9,N9,P9,R9,T9,V9,X9,Z9,AB9,AD9,AF9,AH9,AJ9,AL9,AN9,AP9,AR9,AT9,AV9) -> 0 | BE9: =SUM(P9+R9+T9+V9+X9+Z9+AB9+AD9+AF9+AH9+AJ9+AL9+AN9+AP9+AR9+AT9+AV9+B10+D10+F10+H10+J10+L10+N10) -> 0 | BG9: =BE10 -> 0
A10: 1 | AX10: 1 | AY10: =B10+D10+F10+H10+J10+L10+N10+P10+R10+T10+V10+X10+Z10+AB10+AD10+AF10+AH10+AJ10+AL10+AN10+AP10+AR10+AT10+AV10 -> 0 | AZ10: =C10+E10+G10+I10+K10+M10+O10+Q10+S10+U10+W10+Y10+AA10+AC10+AE10+AG10+AI10+AK10+AM10+AO10+AQ10+AS10+AU10+AW10 -> 0 | BA10: =MAX(B10,D10,F10,H10,J10,L10,N10,P10,R10,T10,V10,X10,Z10,AB10,AD10,AF10,AH10,AJ10,AL10,AN10,AP10,AR10,AT10,AV10) -> 0 | BB10: =COUNT(B10,D10,F10,H10,J10,L10,N10,P10,R10,T10,V10,X10,Z10,AB10,AD10,AF10,AH10,AJ10,AL10,AN10,AP10,AR10,AT10,AV10) -> 0 | BD10: =IF(BB10>0,1,0) -> 0 | BE10: =P9+R9+T9+V9+X9+Z9+AB9+AD9+AF9+AH9+AJ9+AL9+AN9+AP9+AR9+AT9+AV9+B10+D10+F10+H10+J10+L10+N10 -> 0 | BF10: 40908 | BG10: =janeiro!$BE11 -> 0 | BI10: =IF(BH10>0,1,0) -> 0
A11: 2 | AX11: 2 | AY11: =B11+D11+F11+H11+J11+L11+N11+P11+R11+T11+V11+X11+Z11+AB11+AD11+AF11+AH11+AJ11+AL11+AN11+AP11+AR11+AT11+AV11 -> 0 | AZ11: =C11+E11+G11+I11+K11+M11+O11+Q11+S11+U11+W11+Y11+AA11+AC11+AE11+AG11+AI11+AK11+AM11+AO11+AQ11+AS11+AU11+AW11 -> 0 | BA11: =MAX(B11,D11,F11,H11,J11,L11,N11,P11,R11,T11,V11,X11,Z11,AB11,AD11,AF11,AH11,AJ11,AL11,AN11,AP11,AR11,AT11,AV11) -> 0 | BB11: =COUNT(B11,D11,F11,H11,J11,L11,N11,P11,R11,T11,V11,X11,Z11,AB11,AD11,AF11,AH11,AJ11,AL11,AN11,AP11,AR11,AT11,AV11) -> 0 | BD11: =IF(BB11>0,1,0) -> 0 | BE11: =P10+R10+T10+V10+X10+Z10+AB10+AD10+AF10+AH10+AJ10+AL10+AN10+AP10+AR10+AT10+AV10+B11+D11+F11+H11+J11+L11+N11 -> 0 | BG11: =janeiro!$BE12 -> 0 | BI11: =IF(BH11>0,1,0) -> 0
A12: 3 | AX12: 3 | AY12: =B12+D12+F12+H12+J12+L12+N12+P12+R12+T12+V12+X12+Z12+AB12+AD12+AF12+AH12+AJ12+AL12+AN12+AP12+AR12+AT12+AV12 -> 0 | AZ12: =C12+E12+G12+I12+K12+M12+O12+Q12+S12+U12+W12+Y12+AA12+AC12+AE12+AG12+AI12+AK12+AM12+AO12+AQ12+AS12+AU12+AW12 -> 0 | BA12: =MAX(B12,D12,F12,H12,J12,L12,N12,P12,R12,T12,V12,X12,Z12,AB12,AD12,AF12,AH12,AJ12,AL12,AN12,AP12,AR12,AT12,AV12) -> 0 | BB12: =COUNT(B12,D12,F12,H12,J12,L12,N12,P12,R12,T12,V12,X12,Z12,AB12,AD12,AF12,AH12,AJ12,AL12,AN12,AP12,AR12,AT12,AV12) -> 0 | BD12: =IF(BB12>0,1,0) -> 0 | BE12: =P11+R11+T11+V11+X11+Z11+AB11+AD11+AF11+AH11+AJ11+AL11+AN11+AP11+AR11+AT11+AV11+B12+D12+F12+H12+J12+L12+N12 -> 0 | BG12: =janeiro!$BE13 -> 1.2 | BI12: =IF(BH12>0,1,0) -> 0
A13: 4 | B13: 0.1 | C13: 5 | D13: 1.1 | E13: 50 | R13: 0.1 | S13: 10 | T13: 0.2 | U13: 5 | X13: 0.7 | Y13: 10 | Z13: 0.1 | AA13: 5 | AB13: 0.9 | AC13: 10 | AH13: 0.8 | AI13: 30 | AJ13: 0.3 | AK13: 50 | AL13: 3.1 | AM13: 55 | AN13: 5.9 | AO13: 60 | AP13: 10 | AQ13: 60 | AR13: 2.6 | AS13: 30 | AT13: 0.5 | AU13: 20 | AX13: 4 | AY13: =B13+D13+F13+H13+J13+L13+N13+P13+R13+T13+V13+X13+Z13+AB13+AD13+AF13+AH13+AJ13+AL13+AN13+AP13+AR13+AT13+AV13 -> 26.4 | AZ13: =C13+E13+G13+I13+K13+M13+O13+Q13+S13+U13+W13+Y13+AA13+AC13+AE13+AG13+AI13+AK13+AM13+AO13+AQ13+AS13+AU13+AW13 -> 400 | BA13: =MAX(B13,D13,F13,H13,J13,L13,N13,P13,R13,T13,V13,X13,Z13,AB13,AD13,AF13,AH13,AJ13,AL13,AN13,AP13,AR13,AT13,AV13) -> 10 | BB13: =COUNT(B13,D13,F13,H13,J13,L13,N13,P13,R13,T13,V13,X13,Z13,AB13,AD13,AF13,AH13,AJ13,AL13,AN13,AP13,AR13,AT13,AV13) -> 14 | BD13: =IF(BB13>0,1,0) -> 1 | BE13: =P12+R12+T12+V12+X12+Z12+AB12+AD12+AF12+AH12+AJ12+AL12+AN12+AP12+AR12+AT12+AV12+B13+D13+F13+H13+J13+L13+N13 -> 1.2 | BG13: =janeiro!$BE14 -> 25.2 | BI13: =IF(BH13>0,1,0) -> 0
A14: 5 | AX14: 5 | AY14: =B14+D14+F14+H14+J14+L14+N14+P14+R14+T14+V14+X14+Z14+AB14+AD14+AF14+AH14+AJ14+AL14+AN14+AP14+AR14+AT14+AV14 -> 0 | AZ14: =C14+E14+G14+I14+K14+M14+O14+Q14+S14+U14+W14+Y14+AA14+AC14+AE14+AG14+AI14+AK14+AM14+AO14+AQ14+AS14+AU14+AW14 -> 0 | BA14: =MAX(B14,D14,F14,H14,J14,L14,N14,P14,R14,T14,V14,X14,Z14,AB14,AD14,AF14,AH14,AJ14,AL14,AN14,AP14,AR14,AT14,AV14) -> 0 | BB14: =COUNT(B14,D14,F14,H14,J14,L14,N14,P14,R14,T14,V14,X14,Z14,AB14,AD14,AF14,AH14,AJ14,AL14,AN14,AP14,AR14,AT14,AV14) -> 0 | BD14: =IF(BB14>0,1,0) -> 0 | BE14: =P13+R13+T13+V13+X13+Z13+AB13+AD13+AF13+AH13+AJ13+AL13+AN13+AP13+AR13+AT13+AV13+B14+D14+F14+H14+J14+L14+N14 -> 25.2 | BG14: =janeiro!$BE15 -> 0 | BI14: =IF(BH14>0,1,0) -> 0
A15: 6 | AX15: 6 | AY15: =B15+D15+F15+H15+J15+L15+N15+P15+R15+T15+V15+X15+Z15+AB15+AD15+AF15+AH15+AJ15+AL15+AN15+AP15+AR15+AT15+AV15 -> 0 | AZ15: =C15+E15+G15+I15+K15+M15+O15+Q15+S15+U15+W15+Y15+AA15+AC15+AE15+AG15+AI15+AK15+AM15+AO15+AQ15+AS15+AU15+AW15 -> 0 | BA15: =MAX(B15,D15,F15,H15,J15,L15,N15,P15,R15,T15,V15,X15,Z15,AB15,AD15,AF15,AH15,AJ15,AL15,AN15,AP15,AR15,AT15,AV15) -> 0 | BB15: =COUNT(B15,D15,F15,H15,J15,L15,N15,P15,R15,T15,V15,X15,Z15,AB15,AD15,AF15,AH15,AJ15,AL15,AN15,AP15,AR15,AT15,AV15) -> 0 | BD15: =IF(BB15>0,1,0) -> 0 | BE15: =P14+R14+T14+V14+X14+Z14+AB14+AD14+AF14+AH14+AJ14+AL14+AN14+AP14+AR14+AT14+AV14+B15+D15+F15+H15+J15+L15+N15 -> 0 | BG15: =janeiro!$BE16 -> 0 | BI15: =IF(BH15>0,1,0) -> 0
A16: 7 | AX16: 7 | AY16: =B16+D16+F16+H16+J16+L16+N16+P16+R16+T16+V16+X16+Z16+AB16+AD16+AF16+AH16+AJ16+AL16+AN16+AP16+AR16+AT16+AV16 -> 0 | AZ16: =C16+E16+G16+I16+K16+M16+O16+Q16+S16+U16+W16+Y16+AA16+AC16+AE16+AG16+AI16+AK16+AM16+AO16+AQ16+AS16+AU16+AW16 -> 0 | BA16: =MAX(B16,D16,F16,H16,J16,L16,N16,P16,R16,T16,V16,X16,Z16,AB16,AD16,AF16,AH16,AJ16,AL16,AN16,AP16,AR16,AT16,AV16) -> 0 | BB16: =COUNT(B16,D16,F16,H16,J16,L16,N16,P16,R16,T16,V16,X16,Z16,AB16,AD16,AF16,AH16,AJ16,AL16,AN16,AP16,AR16,AT16,AV16) -> 0 | BD16: =IF(BB16>0,1,0) -> 0 | BE16: =P15+R15+T15+V15+X15+Z15+AB15+AD15+AF15+AH15+AJ15+AL15+AN15+AP15+AR15+AT15+AV15+B16+D16+F16+H16+J16+L16+N16 -> 0 | BG16: =janeiro!$BE17 -> 0 | BI16: =IF(BH16>0,1,0) -> 0
A17: 8 | AD17: 19.8 | AE17: 40 | AF17: 11.4 | AG17: 60 | AH17: 0.1 | AI17: 5 | AX17: 8 | AY17: =B17+D17+F17+H17+J17+L17+N17+P17+R17+T17+V17+X17+Z17+AB17+AD17+AF17+AH17+AJ17+AL17+AN17+AP17+AR17+AT17+AV17 -> 31.3 | AZ17: =C17+E17+G17+I17+K17+M17+O17+Q17+S17+U17+W17+Y17+AA17+AC17+AE17+AG17+AI17+AK17+AM17+AO17+AQ17+AS17+AU17+AW17 -> 105 | BA17: =MAX(B17,D17,F17,H17,J17,L17,N17,P17,R17,T17,V17,X17,Z17,AB17,AD17,AF17,AH17,AJ17,AL17,AN17,AP17,AR17,AT17,AV17) -> 19.8 | BB17: =COUNT(B17,D17,F17,H17,J17,L17,N17,P17,R17,T17,V17,X17,Z17,AB17,AD17,AF17,AH17,AJ17,AL17,AN17,AP17,AR17,AT17,AV17) -> 3 | BD17: =IF(BB17>0,1,0) -> 1 | BE17: =P16+R16+T16+V16+X16+Z16+AB16+AD16+AF16+AH16+AJ16+AL16+AN16+AP16+AR16+AT16+AV16+B17+D17+F17+H17+J17+L17+N17 -> 0 | BG17: =janeiro!$BE18 -> 31.3 | BI17: =IF(BH17>0,1,0) -> 0
A18: 9 | AJ18: 0.6 | AK18: 10 | AL18: 0.2 | AM18: 10 | AP18: 3.7 | AQ18: 30 | AR18: 0.2 | AS18: 10 | AX18: 9 | AY18: =B18+D18+F18+H18+J18+L18+N18+P18+R18+T18+V18+X18+Z18+AB18+AD18+AF18+AH18+AJ18+AL18+AN18+AP18+AR18+AT18+AV18 -> 4.7 | AZ18: =C18+E18+G18+I18+K18+M18+O18+Q18+S18+U18+W18+Y18+AA18+AC18+AE18+AG18+AI18+AK18+AM18+AO18+AQ18+AS18+AU18+AW18 -> 60 | BA18: =MAX(B18,D18,F18,H18,J18,L18,N18,P18,R18,T18,V18,X18,Z18,AB18,AD18,AF18,AH18,AJ18,AL18,AN18,AP18,AR18,AT18,AV18) -> 3.7 | BB18: =COUNT(B18,D18,F18,H18,J18,L18,N18,P18,R18,T18,V18,X18,Z18,AB18,AD18,AF18,AH18,AJ18,AL18,AN18,AP18,AR18,AT18,AV18) -> 4 | BD18: =IF(BB18>0,1,0) -> 1 | BE18: =P17+R17+T17+V17+X17+Z17+AB17+AD17+AF17+AH17+AJ17+AL17+AN17+AP17+AR17+AT17+AV17+B18+D18+F18+H18+J18+L18+N18 -> 31.3 | BG18: =janeiro!$BE19 -> 4.7 | BI18: =IF(BH18>0,1,0) -> 0
A19: 10 | AH19: 0.1 | AI19: 5 | AJ19: 12.1 | AK19: 60 | AL19: 0.3 | AM19: 10 | AR19: 1.4 | AS19: 40 | AT19: 2 | AU19: 60 | AV19: 1.3 | AW19: 60 | AX19: 10 | AY19: =B19+D19+F19+H19+J19+L19+N19+P19+R19+T19+V19+X19+Z19+AB19+AD19+AF19+AH19+AJ19+AL19+AN19+AP19+AR19+AT19+AV19 -> 17.2 | AZ19: =C19+E19+G19+I19+K19+M19+O19+Q19+S19+U19+W19+Y19+AA19+AC19+AE19+AG19+AI19+AK19+AM19+AO19+AQ19+AS19+AU19+AW19 -> 235 | BA19: =MAX(B19,D19,F19,H19,J19,L19,N19,P19,R19,T19,V19,X19,Z19,AB19,AD19,AF19,AH19,AJ19,AL19,AN19,AP19,AR19,AT19,AV19) -> 12.1 | BB19: =COUNT(B19,D19,F19,H19,J19,L19,N19,P19,R19,T19,V19,X19,Z19,AB19,AD19,AF19,AH19,AJ19,AL19,AN19,AP19,AR19,AT19,AV19) -> 6 | BD19: =IF(BB19>0,1,0) -> 1 | BE19: =P18+R18+T18+V18+X18+Z18+AB18+AD18+AF18+AH18+AJ18+AL18+AN18+AP18+AR18+AT18+AV18+B19+D19+F19+H19+J19+L19+N19 -> 4.7 | BG19: =janeiro!$BE20 -> 18.4 | BI19: =IF(BH19>0,1,0) -> 0
A20: 11 | B20: 1.2 | C20: 60 | AL20: 0.2 | AM20: 5 | AX20: 11 | AY20: =B20+D20+F20+H20+J20+L20+N20+P20+R20+T20+V20+X20+Z20+AB20+AD20+AF20+AH20+AJ20+AL20+AN20+AP20+AR20+AT20+AV20 -> 1.4 | AZ20: =C20+E20+G20+I20+K20+M20+O20+Q20+S20+U20+W20+Y20+AA20+AC20+AE20+AG20+AI20+AK20+AM20+AO20+AQ20+AS20+AU20+AW20 -> 65 | BA20: =MAX(B20,D20,F20,H20,J20,L20,N20,P20,R20,T20,V20,X20,Z20,AB20,AD20,AF20,AH20,AJ20,AL20,AN20,AP20,AR20,AT20,AV20) -> 1.2 | BB20: =COUNT(B20,D20,F20,H20,J20,L20,N20,P20,R20,T20,V20,X20,Z20,AB20,AD20,AF20,AH20,AJ20,AL20,AN20,AP20,AR20,AT20,AV20) -> 2 | BD20: =IF(BB20>0,1,0) -> 1 | BE20: =P19+R19+T19+V19+X19+Z19+AB19+AD19+AF19+AH19+AJ19+AL19+AN19+AP19+AR19+AT19+AV19+B20+D20+F20+H20+J20+L20+N20 -> 18.4 | BG20: =janeiro!$BE21 -> 4.7 | BI20: =IF(BH20>0,1,0) -> 0
A21: 12 | H21: 3.6 | I21: 15 | J21: 0.8 | K21: 35 | L21: 0.1 | M21: 5 | AB21: 0.4 | AC21: 5 | AD21: 0.1 | AE21: 5 | AJ21: 5.3 | AK21: 10 | AL21: 14.7 | AM21: 60 | AN21: 9.4 | AO21: 60 | AP21: 9.4 | AQ21: 60 | AR21: 8.9 | AS21: 60 | AT21: 10.2 | AU21: 60 | AV21: 6 | AW21: 60 | AX21: 12 | AY21: =B21+D21+F21+H21+J21+L21+N21+P21+R21+T21+V21+X21+Z21+AB21+AD21+AF21+AH21+AJ21+AL21+AN21+AP21+AR21+AT21+AV21 -> 68.9 | AZ21: =C21+E21+G21+I21+K21+M21+O21+Q21+S21+U21+W21+Y21+AA21+AC21+AE21+AG21+AI21+AK21+AM21+AO21+AQ21+AS21+AU21+AW21 -> 435 | BA21: =MAX(B21,D21,F21,H21,J21,L21,N21,P21,R21,T21,V21,X21,Z21,AB21,AD21,AF21,AH21,AJ21,AL21,AN21,AP21,AR21,AT21,AV21) -> 14.7 | BB21: =COUNT(B21,D21,F21,H21,J21,L21,N21,P21,R21,T21,V21,X21,Z21,AB21,AD21,AF21,AH21,AJ21,AL21,AN21,AP21,AR21,AT21,AV21) -> 12 | BD21: =IF(BB21>0,1,0) -> 1 | BE21: =P20+R20+T20+V20+X20+Z20+AB20+AD20+AF20+AH20+AJ20+AL20+AN20+AP20+AR20+AT20+AV20+B21+D21+F21+H21+J21+L21+N21 -> 4.7 | BG21: =janeiro!$BE22 -> 80.4 | BI21: =IF(BH21>0,1,0) -> 0
A22: 13 | B22: 5.7 | C22: 60 | D22: 5.2 | E22: 60 | F22: 3.4 | G22: 60 | H22: 1.2 | I22: 60 | J22: 0.5 | K22: 25 | R22: 0.3 | S22: 15 | AP22: 0.1 | AQ22: 5 | AR22: 0.1 | AS22: 5 | AX22: 13 | AY22: =B22+D22+F22+H22+J22+L22+N22+P22+R22+T22+V22+X22+Z22+AB22+AD22+AF22+AH22+AJ22+AL22+AN22+AP22+AR22+AT22+AV22 -> 16.5 | AZ22: =C22+E22+G22+I22+K22+M22+O22+Q22+S22+U22+W22+Y22+AA22+AC22+AE22+AG22+AI22+AK22+AM22+AO22+AQ22+AS22+AU22+AW22 -> 290 | BA22: =MAX(B22,D22,F22,H22,J22,L22,N22,P22,R22,T22,V22,X22,Z22,AB22,AD22,AF22,AH22,AJ22,AL22,AN22,AP22,AR22,AT22,AV22) -> 5.7 | BB22: =COUNT(B22,D22,F22,H22,J22,L22,N22,P22,R22,T22,V22,X22,Z22,AB22,AD22,AF22,AH22,AJ22,AL22,AN22,AP22,AR22,AT22,AV22) -> 8 | BD22: =IF(BB22>0,1,0) -> 1 | BE22: =P21+R21+T21+V21+X21+Z21+AB21+AD21+AF21+AH21+AJ21+AL21+AN21+AP21+AR21+AT21+AV21+B22+D22+F22+H22+J22+L22+N22 -> 80.4 | BG22: =janeiro!$BE23 -> 0.5 | BI22: =IF(BH22>0,1,0) -> 0
A23: 14 | AX23: 14 | AY23: =B23+D23+F23+H23+J23+L23+N23+P23+R23+T23+V23+X23+Z23+AB23+AD23+AF23+AH23+AJ23+AL23+AN23+AP23+AR23+AT23+AV23 -> 0 | AZ23: =C23+E23+G23+I23+K23+M23+O23+Q23+S23+U23+W23+Y23+AA23+AC23+AE23+AG23+AI23+AK23+AM23+AO23+AQ23+AS23+AU23+AW23 -> 0 | BA23: =MAX(B23,D23,F23,H23,J23,L23,N23,P23,R23,T23,V23,X23,Z23,AB23,AD23,AF23,AH23,AJ23,AL23,AN23,AP23,AR23,AT23,AV23) -> 0 | BB23: =COUNT(B23,D23,F23,H23,J23,L23,N23,P23,R23,T23,V23,X23,Z23,AB23,AD23,AF23,AH23,AJ23,AL23,AN23,AP23,AR23,AT23,AV23) -> 0 | BD23: =IF(BB23>0,1,0) -> 0 | BE23: =P22+R22+T22+V22+X22+Z22+AB22+AD22+AF22+AH22+AJ22+AL22+AN22+AP22+AR22+AT22+AV22+B23+D23+F23+H23+J23+L23+N23 -> 0.5 | BG23: =janeiro!$BE24 -> 0 | BI23: =IF(BH23>0,1,0) -> 0
A24: 15 | AX24: 15 | AY24: =B24+D24+F24+H24+J24+L24+N24+P24+R24+T24+V24+X24+Z24+AB24+AD24+AF24+AH24+AJ24+AL24+AN24+AP24+AR24+AT24+AV24 -> 0 | AZ24: =C24+E24+G24+I24+K24+M24+O24+Q24+S24+U24+W24+Y24+AA24+AC24+AE24+AG24+AI24+AK24+AM24+AO24+AQ24+AS24+AU24+AW24 -> 0 | BA24: =MAX(B24,D24,F24,H24,J24,L24,N24,P24,R24,T24,V24,X24,Z24,AB24,AD24,AF24,AH24,AJ24,AL24,AN24,AP24,AR24,AT24,AV24) -> 0 | BB24: =COUNT(B24,D24,F24,H24,J24,L24,N24,P24,R24,T24,V24,X24,Z24,AB24,AD24,AF24,AH24,AJ24,AL24,AN24,AP24,AR24,AT24,AV24) -> 0 | BD24: =IF(BB24>0,1,0) -> 0 | BE24: =P23+R23+T23+V23+X23+Z23+AB23+AD23+AF23+AH23+AJ23+AL23+AN23+AP23+AR23+AT23+AV23+B24+D24+F24+H24+J24+L24+N24 -> 0 | BG24: =janeiro!$BE25 -> 0 | BI24: =IF(BH24>0,1,0) -> 0
A25: 16 | AX25: 16 | AY25: =B25+D25+F25+H25+J25+L25+N25+P25+R25+T25+V25+X25+Z25+AB25+AD25+AF25+AH25+AJ25+AL25+AN25+AP25+AR25+AT25+AV25 -> 0 | AZ25: =C25+E25+G25+I25+K25+M25+O25+Q25+S25+U25+W25+Y25+AA25+AC25+AE25+AG25+AI25+AK25+AM25+AO25+AQ25+AS25+AU25+AW25 -> 0 | BA25: =MAX(B25,D25,F25,H25,J25,L25,N25,P25,R25,T25,V25,X25,Z25,AB25,AD25,AF25,AH25,AJ25,AL25,AN25,AP25,AR25,AT25,AV25) -> 0 | BB25: =COUNT(B25,D25,F25,H25,J25,L25,N25,P25,R25,T25,V25,X25,Z25,AB25,AD25,AF25,AH25,AJ25,AL25,AN25,AP25,AR25,AT25,AV25) -> 0 | BD25: =IF(BB25>0,1,0) -> 0 | BE25: =P24+R24+T24+V24+X24+Z24+AB24+AD24+AF24+AH24+AJ24+AL24+AN24+AP24+AR24+AT24+AV24+B25+D25+F25+H25+J25+L25+N25 -> 0 | BG25: =janeiro!$BE26 -> 0 | BI25: =IF(BH25>0,1,0) -> 0
A26: 17 | AH26: 0.8 | AI26: 10 | AJ26: 7.2 | AK26: 40 | AX26: 17 | AY26: =B26+D26+F26+H26+J26+L26+N26+P26+R26+T26+V26+X26+Z26+AB26+AD26+AF26+AH26+AJ26+AL26+AN26+AP26+AR26+AT26+AV26 -> 8 | AZ26: =C26+E26+G26+I26+K26+M26+O26+Q26+S26+U26+W26+Y26+AA26+AC26+AE26+AG26+AI26+AK26+AM26+AO26+AQ26+AS26+AU26+AW26 -> 50 | BA26: =MAX(B26,D26,F26,H26,J26,L26,N26,P26,R26,T26,V26,X26,Z26,AB26,AD26,AF26,AH26,AJ26,AL26,AN26,AP26,AR26,AT26,AV26) -> 7.2 | BB26: =COUNT(B26,D26,F26,H26,J26,L26,N26,P26,R26,T26,V26,X26,Z26,AB26,AD26,AF26,AH26,AJ26,AL26,AN26,AP26,AR26,AT26,AV26) -> 2 | BD26: =IF(BB26>0,1,0) -> 1 | BE26: =P25+R25+T25+V25+X25+Z25+AB25+AD25+AF25+AH25+AJ25+AL25+AN25+AP25+AR25+AT25+AV25+B26+D26+F26+H26+J26+L26+N26 -> 0 | BG26: =janeiro!$BE27 -> 8 | BI26: =IF(BH26>0,1,0) -> 0
A27: 18 | AX27: 18 | AY27: =B27+D27+F27+H27+J27+L27+N27+P27+R27+T27+V27+X27+Z27+AB27+AD27+AF27+AH27+AJ27+AL27+AN27+AP27+AR27+AT27+AV27 -> 0 | AZ27: =C27+E27+G27+I27+K27+M27+O27+Q27+S27+U27+W27+Y27+AA27+AC27+AE27+AG27+AI27+AK27+AM27+AO27+AQ27+AS27+AU27+AW27 -> 0 | BA27: =MAX(B27,D27,F27,H27,J27,L27,N27,P27,R27,T27,V27,X27,Z27,AB27,AD27,AF27,AH27,AJ27,AL27,AN27,AP27,AR27,AT27,AV27) -> 0 | BB27: =COUNT(B27,D27,F27,H27,J27,L27,N27,P27,R27,T27,V27,X27,Z27,AB27,AD27,AF27,AH27,AJ27,AL27,AN27,AP27,AR27,AT27,AV27) -> 0 | BD27: =IF(BB27>0,1,0) -> 0 | BE27: =P26+R26+T26+V26+X26+Z26+AB26+AD26+AF26+AH26+AJ26+AL26+AN26+AP26+AR26+AT26+AV26+B27+D27+F27+H27+J27+L27+N27 -> 8 | BG27: =janeiro!$BE28 -> 2.8 | BI27: =IF(BH27>0,1,0) -> 0
A28: 19 | B28: 0.7 | C28: 25 | D28: 1.2 | E28: 60 | F28: 0.5 | G28: 60 | H28: 0.4 | I28: 40 | AJ28: 16.8 | AK28: 20 | AL28: 17 | AM28: 60 | AN28: 3.5 | AO28: 30 | AP28: 29.5 | AQ28: 50 | AR28: 0.1 | AS28: 5 | AX28: 19 | AY28: =B28+D28+F28+H28+J28+L28+N28+P28+R28+T28+V28+X28+Z28+AB28+AD28+AF28+AH28+AJ28+AL28+AN28+AP28+AR28+AT28+AV28 -> 69.7 | AZ28: =C28+E28+G28+I28+K28+M28+O28+Q28+S28+U28+W28+Y28+AA28+AC28+AE28+AG28+AI28+AK28+AM28+AO28+AQ28+AS28+AU28+AW28 -> 350 | BA28: =MAX(B28,D28,F28,H28,J28,L28,N28,P28,R28,T28,V28,X28,Z28,AB28,AD28,AF28,AH28,AJ28,AL28,AN28,AP28,AR28,AT28,AV28) -> 29.5 | BB28: =COUNT(B28,D28,F28,H28,J28,L28,N28,P28,R28,T28,V28,X28,Z28,AB28,AD28,AF28,AH28,AJ28,AL28,AN28,AP28,AR28,AT28,AV28) -> 9 | BD28: =IF(BB28>0,1,0) -> 1 | BE28: =P27+R27+T27+V27+X27+Z27+AB27+AD27+AF27+AH27+AJ27+AL27+AN27+AP27+AR27+AT27+AV27+B28+D28+F28+H28+J28+L28+N28 -> 2.8 | BG28: =janeiro!$BE29 -> 66.9 | BI28: =IF(BH28>0,1,0) -> 0
A29: 20 | AL29: 17.1 | AM29: 50 | AN29: 3.8 | AO29: 60 | AP29: 2.1 | AQ29: 60 | AR29: 0.2 | AS29: 20 | AT29: 0.3 | AU29: 20 | AX29: 20 | AY29: =B29+D29+F29+H29+J29+L29+N29+P29+R29+T29+V29+X29+Z29+AB29+AD29+AF29+AH29+AJ29+AL29+AN29+AP29+AR29+AT29+AV29 -> 23.5 | AZ29: =C29+E29+G29+I29+K29+M29+O29+Q29+S29+U29+W29+Y29+AA29+AC29+AE29+AG29+AI29+AK29+AM29+AO29+AQ29+AS29+AU29+AW29 -> 210 | BA29: =MAX(B29,D29,F29,H29,J29,L29,N29,P29,R29,T29,V29,X29,Z29,AB29,AD29,AF29,AH29,AJ29,AL29,AN29,AP29,AR29,AT29,AV29) -> 17.1 | BB29: =COUNT(B29,D29,F29,H29,J29,L29,N29,P29,R29,T29,V29,X29,Z29,AB29,AD29,AF29,AH29,AJ29,AL29,AN29,AP29,AR29,AT29,AV29) -> 5 | BD29: =IF(BB29>0,1,0) -> 1 | BE29: =P28+R28+T28+V28+X28+Z28+AB28+AD28+AF28+AH28+AJ28+AL28+AN28+AP28+AR28+AT28+AV28+B29+D29+F29+H29+J29+L29+N29 -> 66.9 | BG29: =janeiro!$BE30 -> 23.5 | BI29: =IF(BH29>0,1,0) -> 0
A30: 21 | V30: 1.7 | W30: 5 | AB30: 0.7 | AC30: 15 | AD30: 0.9 | AE30: 25 | AF30: 4.3 | AG30: 30 | AJ30: 0.9 | AK30: 25 | AL30: 0.7 | AM30: 25 | AN30: 0.4 | AO30: 15 | AP30: 1 | AQ30: 25 | AR30: 0.1 | AS30: 5 | AT30: 1.9 | AU30: 40 | AV30: 0.2 | AW30: 5 | AX30: 21 | AY30: =B30+D30+F30+H30+J30+L30+N30+P30+R30+T30+V30+X30+Z30+AB30+AD30+AF30+AH30+AJ30+AL30+AN30+AP30+AR30+AT30+AV30 -> 12.8 | AZ30: =C30+E30+G30+I30+K30+M30+O30+Q30+S30+U30+W30+Y30+AA30+AC30+AE30+AG30+AI30+AK30+AM30+AO30+AQ30+AS30+AU30+AW30 -> 215 | BA30: =MAX(B30,D30,F30,H30,J30,L30,N30,P30,R30,T30,V30,X30,Z30,AB30,AD30,AF30,AH30,AJ30,AL30,AN30,AP30,AR30,AT30,AV30) -> 4.3 | BB30: =COUNT(B30,D30,F30,H30,J30,L30,N30,P30,R30,T30,V30,X30,Z30,AB30,AD30,AF30,AH30,AJ30,AL30,AN30,AP30,AR30,AT30,AV30) -> 11 | BD30: =IF(BB30>0,1,0) -> 1 | BE30: =P29+R29+T29+V29+X29+Z29+AB29+AD29+AF29+AH29+AJ29+AL29+AN29+AP29+AR29+AT29+AV29+B30+D30+F30+H30+J30+L30+N30 -> 23.5 | BG30: =janeiro!$BE31 -> 14.5 | BI30: =IF(BH30>0,1,0) -> 0
A31: 22 | F31: 0.1 | G31: 5 | H31: 0.2 | I31: 15 | J31: 0.4 | K31: 30 | L31: 0.2 | M31: 25 | N31: 0.8 | O31: 35 | P31: 0.1 | Q31: 10 | AJ31: 0.3 | AK31: 5 | AX31: 22 | AY31: =B31+D31+F31+H31+J31+L31+N31+P31+R31+T31+V31+X31+Z31+AB31+AD31+AF31+AH31+AJ31+AL31+AN31+AP31+AR31+AT31+AV31 -> 2.1 | AZ31: =C31+E31+G31+I31+K31+M31+O31+Q31+S31+U31+W31+Y31+AA31+AC31+AE31+AG31+AI31+AK31+AM31+AO31+AQ31+AS31+AU31+AW31 -> 125 | BA31: =MAX(B31,D31,F31,H31,J31,L31,N31,P31,R31,T31,V31,X31,Z31,AB31,AD31,AF31,AH31,AJ31,AL31,AN31,AP31,AR31,AT31,AV31) -> 0.8 | BB31: =COUNT(B31,D31,F31,H31,J31,L31,N31,P31,R31,T31,V31,X31,Z31,AB31,AD31,AF31,AH31,AJ31,AL31,AN31,AP31,AR31,AT31,AV31) -> 7 | BD31: =IF(BB31>0,1,0) -> 1 | BE31: =P30+R30+T30+V30+X30+Z30+AB30+AD30+AF30+AH30+AJ30+AL30+AN30+AP30+AR30+AT30+AV30+B31+D31+F31+H31+J31+L31+N31 -> 14.5 | BG31: =janeiro!$BE32 -> 1.2 | BI31: =IF(BH31>0,1,0) -> 0
A32: 23 | B32: 0.1 | C32: 5 | D32: 0.1 | E32: 5 | N32: 0.6 | O32: 30 | P32: 1.3 | Q32: 60 | R32: 3.4 | S32: 30 | T32: 5 | U32: 60 | V32: 6.2 | W32: 60 | X32: 4.7 | Y32: 60 | Z32: 0.1 | AA32: 10 | AB32: 0.8 | AC32: 30 | AD32: 0.9 | AE32: 30 | AF32: 0.1 | AG32: 10 | AH32: 0.1 | AI32: 5 | AJ32: 0.2 | AK32: 15 | AL32: 0.2 | AM32: 15 | AR32: 0.1 | AS32: 20 | AT32: 0.1 | AU32: 5 | AX32: 23 | AY32: =B32+D32+F32+H32+J32+L32+N32+P32+R32+T32+V32+X32+Z32+AB32+AD32+AF32+AH32+AJ32+AL32+AN32+AP32+AR32+AT32+AV32 -> 24 | AZ32: =C32+E32+G32+I32+K32+M32+O32+Q32+S32+U32+W32+Y32+AA32+AC32+AE32+AG32+AI32+AK32+AM32+AO32+AQ32+AS32+AU32+AW32 -> 450 | BA32: =MAX(B32,D32,F32,H32,J32,L32,N32,P32,R32,T32,V32,X32,Z32,AB32,AD32,AF32,AH32,AJ32,AL32,AN32,AP32,AR32,AT32,AV32) -> 6.2 | BB32: =COUNT(B32,D32,F32,H32,J32,L32,N32,P32,R32,T32,V32,X32,Z32,AB32,AD32,AF32,AH32,AJ32,AL32,AN32,AP32,AR32,AT32,AV32) -> 17 | BD32: =IF(BB32>0,1,0) -> 1 | BE32: =P31+R31+T31+V31+X31+Z31+AB31+AD31+AF31+AH31+AJ31+AL31+AN31+AP31+AR31+AT31+AV31+B32+D32+F32+H32+J32+L32+N32 -> 1.2 | BG32: =janeiro!$BE33 -> 23.2 | BI32: =IF(BH32>0,1,0) -> 0
A33: 24 | AJ33: 0.1 | AK33: 5 | AP33: 0.1 | AQ33: 10 | AR33: 0.1 | AS33: 10 | AT33: 0.1 | AU33: 5 | AV33: 0.1 | AW33: 5 | AX33: 24 | AY33: =B33+D33+F33+H33+J33+L33+N33+P33+R33+T33+V33+X33+Z33+AB33+AD33+AF33+AH33+AJ33+AL33+AN33+AP33+AR33+AT33+AV33 -> 0.5 | AZ33: =C33+E33+G33+I33+K33+M33+O33+Q33+S33+U33+W33+Y33+AA33+AC33+AE33+AG33+AI33+AK33+AM33+AO33+AQ33+AS33+AU33+AW33 -> 35 | BA33: =MAX(B33,D33,F33,H33,J33,L33,N33,P33,R33,T33,V33,X33,Z33,AB33,AD33,AF33,AH33,AJ33,AL33,AN33,AP33,AR33,AT33,AV33) -> 0.1 | BB33: =COUNT(B33,D33,F33,H33,J33,L33,N33,P33,R33,T33,V33,X33,Z33,AB33,AD33,AF33,AH33,AJ33,AL33,AN33,AP33,AR33,AT33,AV33) -> 5 | BD33: =IF(BB33>0,1,0) -> 1 | BE33: =P32+R32+T32+V32+X32+Z32+AB32+AD32+AF32+AH32+AJ32+AL32+AN32+AP32+AR32+AT32+AV32+B33+D33+F33+H33+J33+L33+N33 -> 23.2 | BG33: =janeiro!$BE34 -> 1 | BI33: =IF(BH33>0,1,0) -> 0
A34: 25 | B34: 0.2 | C34: 25 | F34: 0.1 | G34: 5 | H34: 0.1 | I34: 1 | L34: 0.1 | M34: 15 | AD34: 0.3 | AE34: 5 | AH34: 0.3 | AI34: 5 | AL34: 0.1 | AM34: 5 | AX34: 25 | AY34: =B34+D34+F34+H34+J34+L34+N34+P34+R34+T34+V34+X34+Z34+AB34+AD34+AF34+AH34+AJ34+AL34+AN34+AP34+AR34+AT34+AV34 -> 1.2 | AZ34: =C34+E34+G34+I34+K34+M34+O34+Q34+S34+U34+W34+Y34+AA34+AC34+AE34+AG34+AI34+AK34+AM34+AO34+AQ34+AS34+AU34+AW34 -> 61 | BA34: =MAX(B34,D34,F34,H34,J34,L34,N34,P34,R34,T34,V34,X34,Z34,AB34,AD34,AF34,AH34,AJ34,AL34,AN34,AP34,AR34,AT34,AV34) -> 0.3 | BB34: =COUNT(B34,D34,F34,H34,J34,L34,N34,P34,R34,T34,V34,X34,Z34,AB34,AD34,AF34,AH34,AJ34,AL34,AN34,AP34,AR34,AT34,AV34) -> 7 | BD34: =IF(BB34>0,1,0) -> 1 | BE34: =P33+R33+T33+V33+X33+Z33+AB33+AD33+AF33+AH33+AJ33+AL33+AN33+AP33+AR33+AT33+AV33+B34+D34+F34+H34+J34+L34+N34 -> 1 | BG34: =janeiro!$BE35 -> 2.2 | BI34: =IF(BH34>0,1,0) -> 0
A35: 26 | B35: 0.1 | C35: 5 | F35: 0.3 | G35: 25 | H35: 1 | I35: 60 | J35: 0.1 | K35: 5 | AR35: 0.1 | AS35: 5 | AT35: 0.2 | AU35: 20 | AV35: 0.3 | AW35: 40 | AX35: 26 | AY35: =B35+D35+F35+H35+J35+L35+N35+P35+R35+T35+V35+X35+Z35+AB35+AD35+AF35+AH35+AJ35+AL35+AN35+AP35+AR35+AT35+AV35 -> 2.1 | AZ35: =C35+E35+G35+I35+K35+M35+O35+Q35+S35+U35+W35+Y35+AA35+AC35+AE35+AG35+AI35+AK35+AM35+AO35+AQ35+AS35+AU35+AW35 -> 160 | BA35: =MAX(B35,D35,F35,H35,J35,L35,N35,P35,R35,T35,V35,X35,Z35,AB35,AD35,AF35,AH35,AJ35,AL35,AN35,AP35,AR35,AT35,AV35) -> 1 | BB35: =COUNT(B35,D35,F35,H35,J35,L35,N35,P35,R35,T35,V35,X35,Z35,AB35,AD35,AF35,AH35,AJ35,AL35,AN35,AP35,AR35,AT35,AV35) -> 7 | BD35: =IF(BB35>0,1,0) -> 1 | BE35: =P34+R34+T34+V34+X34+Z34+AB34+AD34+AF34+AH34+AJ34+AL34+AN34+AP34+AR34+AT34+AV34+B35+D35+F35+H35+J35+L35+N35 -> 2.2 | BG35: =janeiro!$BE36 -> 1 | BI35: =IF(BH35>0,1,0) -> 0
A36: 27 | D36: 0.1 | E36: 5 | F36: 0.1 | G36: 15 | H36: 0.1 | I36: 5 | L36: 0.1 | M36: 5 | AF36: 1.3 | AG36: 20 | AH36: 16.3 | AI36: 25 | AX36: 27 | AY36: =B36+D36+F36+H36+J36+L36+N36+P36+R36+T36+V36+X36+Z36+AB36+AD36+AF36+AH36+AJ36+AL36+AN36+AP36+AR36+AT36+AV36 -> 18 | AZ36: =C36+E36+G36+I36+K36+M36+O36+Q36+S36+U36+W36+Y36+AA36+AC36+AE36+AG36+AI36+AK36+AM36+AO36+AQ36+AS36+AU36+AW36 -> 75 | BA36: =MAX(B36,D36,F36,H36,J36,L36,N36,P36,R36,T36,V36,X36,Z36,AB36,AD36,AF36,AH36,AJ36,AL36,AN36,AP36,AR36,AT36,AV36) -> 16.3 | BB36: =COUNT(B36,D36,F36,H36,J36,L36,N36,P36,R36,T36,V36,X36,Z36,AB36,AD36,AF36,AH36,AJ36,AL36,AN36,AP36,AR36,AT36,AV36) -> 6 | BD36: =IF(BB36>0,1,0) -> 1 | BE36: =P35+R35+T35+V35+X35+Z35+AB35+AD35+AF35+AH35+AJ35+AL35+AN35+AP35+AR35+AT35+AV35+B36+D36+F36+H36+J36+L36+N36 -> 1 | BG36: =janeiro!$BE37 -> 17.6 | BI36: =IF(BH36>0,1,0) -> 0
A37: 28 | V37: 24.6 | W37: 25 | X37: 5.8 | Y37: 55 | AX37: 28 | AY37: =B37+D37+F37+H37+J37+L37+N37+P37+R37+T37+V37+X37+Z37+AB37+AD37+AF37+AH37+AJ37+AL37+AN37+AP37+AR37+AT37+AV37 -> 30.4 | AZ37: =C37+E37+G37+I37+K37+M37+O37+Q37+S37+U37+W37+Y37+AA37+AC37+AE37+AG37+AI37+AK37+AM37+AO37+AQ37+AS37+AU37+AW37 -> 80 | BA37: =MAX(B37,D37,F37,H37,J37,L37,N37,P37,R37,T37,V37,X37,Z37,AB37,AD37,AF37,AH37,AJ37,AL37,AN37,AP37,AR37,AT37,AV37) -> 24.6 | BB37: =COUNT(B37,D37,F37,H37,J37,L37,N37,P37,R37,T37,V37,X37,Z37,AB37,AD37,AF37,AH37,AJ37,AL37,AN37,AP37,AR37,AT37,AV37) -> 2 | BD37: =IF(BB37>0,1,0) -> 1 | BE37: =P36+R36+T36+V36+X36+Z36+AB36+AD36+AF36+AH36+AJ36+AL36+AN36+AP36+AR36+AT36+AV36+B37+D37+F37+H37+J37+L37+N37 -> 17.6 | BG37: =janeiro!$BE38 -> 30.4 | BI37: =IF(BH37>0,1,0) -> 0
A38: 29 | AX38: 29 | AY38: =B38+D38+F38+H38+J38+L38+N38+P38+R38+T38+V38+X38+Z38+AB38+AD38+AF38+AH38+AJ38+AL38+AN38+AP38+AR38+AT38+AV38 -> 0 | AZ38: =C38+E38+G38+I38+K38+M38+O38+Q38+S38+U38+W38+Y38+AA38+AC38+AE38+AG38+AI38+AK38+AM38+AO38+AQ38+AS38+AU38+AW38 -> 0 | BA38: =MAX(B38,D38,F38,H38,J38,L38,N38,P38,R38,T38,V38,X38,Z38,AB38,AD38,AF38,AH38,AJ38,AL38,AN38,AP38,AR38,AT38,AV38) -> 0 | BB38: =COUNT(B38,D38,F38,H38,J38,L38,N38,P38,R38,T38,V38,X38,Z38,AB38,AD38,AF38,AH38,AJ38,AL38,AN38,AP38,AR38,AT38,AV38) -> 0 | BD38: =IF(BB38>0,1,0) -> 0 | BE38: =P37+R37+T37+V37+X37+Z37+AB37+AD37+AF37+AH37+AJ37+AL37+AN37+AP37+AR37+AT37+AV37+B38+D38+F38+H38+J38+L38+N38 -> 30.4 | BG38: =janeiro!$BE39 -> 0 | BI38: =IF(BH38>0,1,0) -> 0
A39: 30 | AX39: 30 | AY39: =B39+D39+F39+H39+J39+L39+N39+P39+R39+T39+V39+X39+Z39+AB39+AD39+AF39+AH39+AJ39+AL39+AN39+AP39+AR39+AT39+AV39 -> 0 | AZ39: =C39+E39+G39+I39+K39+M39+O39+Q39+S39+U39+W39+Y39+AA39+AC39+AE39+AG39+AI39+AK39+AM39+AO39+AQ39+AS39+AU39+AW39 -> 0 | BA39: =MAX(B39,D39,F39,H39,J39,L39,N39,P39,R39,T39,V39,X39,Z39,AB39,AD39,AF39,AH39,AJ39,AL39,AN39,AP39,AR39,AT39,AV39) -> 0 | BB39: =COUNT(B39,D39,F39,H39,J39,L39,N39,P39,R39,T39,V39,X39,Z39,AB39,AD39,AF39,AH39,AJ39,AL39,AN39,AP39,AR39,AT39,AV39) -> 0 | BD39: =IF(BB39>0,1,0) -> 0 | BE39: =P38+R38+T38+V38+X38+Z38+AB38+AD38+AF38+AH38+AJ38+AL38+AN38+AP38+AR38+AT38+AV38+B39+D39+F39+H39+J39+L39+N39 -> 0 | BG39: =janeiro!$BE40 -> 0 | BI39: =IF(BH39>0,1,0) -> 0
A40: 31 | AD40: 16.5 | AE40: 15 | AF40: 20.3 | AG40: 40 | AH40: 0.2 | AI40: 15 | AJ40: 1 | AK40: 60 | AL40: 0.2 | AM40: 15 | AN40: 1.8 | AO40: 60 | AP40: 0.7 | AQ40: 30 | AX40: 31 | AY40: =B40+D40+F40+H40+J40+L40+N40+P40+R40+T40+V40+X40+Z40+AB40+AD40+AF40+AH40+AJ40+AL40+AN40+AP40+AR40+AT40+AV40 -> 40.7 | AZ40: =C40+E40+G40+I40+K40+M40+O40+Q40+S40+U40+W40+Y40+AA40+AC40+AE40+AG40+AI40+AK40+AM40+AO40+AQ40+AS40+AU40+AW40 -> 235 | BA40: =MAX(B40,D40,F40,H40,J40,L40,N40,P40,R40,T40,V40,X40,Z40,AB40,AD40,AF40,AH40,AJ40,AL40,AN40,AP40,AR40,AT40,AV40) -> 20.3 | BB40: =COUNT(B40,D40,F40,H40,J40,L40,N40,P40,R40,T40,V40,X40,Z40,AB40,AD40,AF40,AH40,AJ40,AL40,AN40,AP40,AR40,AT40,AV40) -> 7 | BD40: =IF(BB40>0,1,0) -> 1 | BE40: =P39+R39+T39+V39+X39+Z39+AB39+AD39+AF39+AH39+AJ39+AL39+AN39+AP39+AR39+AT39+AV39+B40+D40+F40+H40+J40+L40+N40 -> 0 | BG40: =janeiro!$BH41 -> 40.7 | BH40: 39114 | BI40: =IF(BH40>0,1,0) -> 1
...

Sheet fevereiro
B1: FEVEREIRO DE 2024 | J1: INSTITUTO ASTRONÔMICO E GEOFÍSICO DA UNIVERSIDADE DE SÃO PAULO
B2: DIGITADO POR PETY | AU2: Planilha atualizada por Edvaldo Gomes
B3: VERIFICADO POR PETY | M3: RESULTADOS EXTRAÍDOS DE PLUVIOGRAMA DIÁRIO (mm DE CHUVA)
AY4: VALORES DIÁRIOS | BE4: VALORES DIÁRIOS
AY5: (de 00h a 24h) | BE5: DAEE | BF5: DESVIO | BG5: EMAE
AY6: Altura | AZ6: Duração | BA6: Máxima | BE6: Altura | BG6: Máxima
A7: H. | B7: 0 - 1 | D7: 1 - 2 | F7: 2 - 3 | H7: 3 - 4 | J7: 4 - 5 | L7: 5 - 6 | N7: 6 - 7 | P7: 7 - 8 | R7: 8 - 9 | T7: 9 - 10 | V7: 10 - 11 | X7: 11 - 12 | Z7: 12 - 13 | AB7: 13 - 14 | AD7: 14 - 15 | AF7: 15 - 16 | AH7: 16 - 17 | AJ7: 17 - 18 | AL7: 18 - 19 | AN7: 19 - 20 | AP7: 20 - 21 | AR7: 21 - 22 | AT7: 22 - 23 | AV7: 23 - 24 | AX7: H. | AY7: total | AZ7: total | BA7: altura | BB7: Freq. | BE7: total | BG7: altura
A8: D. | B8: ALT. | C8: DUR. | D8: ALT. | E8: DUR. | F8: ALT. | G8: DUR. | H8: ALT. | I8: DUR. | J8: ALT. | K8: DUR. | L8: ALT. | M8: DUR. | N8: ALT. | O8: DUR. | P8: ALT. | Q8: DUR. | R8: ALT. | S8: DUR. | T8: ALT. | U8: DUR. | V8: ALT. | W8: DUR. | X8: ALT. | Y8: DUR. | Z8: ALT. | AA8: DUR. | AB8: ALT. | AC8: DUR. | AD8: ALT. | AE8: DUR. | AF8: ALT. | AG8: DUR. | AH8: ALT. | AI8: DUR. | AJ8: ALT. | AK8: DUR. | AL8: ALT. | AM8: DUR. | AN8: ALT. | AO8: DUR. | AP8: ALT. | AQ8: DUR. | AR8: ALT. | AS8: DUR. | AT8: ALT. | AU8: DUR. | AV8: ALT. | AW8: DUR. | AX8: D. | AY8: (mm) | AZ8: (min) | BA8: horária | BB8: (horas) | BE8: (mm) | BG8: horária | BH8: (horas)
A9: 1 | AD9: 0.7 | AE9: 5 | AF9: 0.3 | AG9: 35 | AH9: 0.1 | AI9: 5 | AX9: 1 | AY9: =B9+D9+F9+H9+J9+L9+N9+P9+R9+T9+V9+X9+Z9+AB9+AD9+AF9+AH9+AJ9+AL9+AN9+AP9+AR9+AT9+AV9 -> 1.1 | AZ9: =C9+E9+G9+I9+K9+M9+O9+Q9+S9+U9+W9+Y9+AA9+AC9+AE9+AG9+AI9+AK9+AM9+AO9+AQ9+AS9+AU9+AW9 -> 45 | BA9: =MAX(B9,D9,F9,H9,J9,L9,N9,P9,R9,T9,V9,X9,Z9,AB9,AD9,AF9,AH9,AJ9,AL9,AN9,AP9,AR9,AT9,AV9) -> 0.7 | BB9: =COUNT(B9,D9,F9,H9,J9,L9,N9,P9,R9,T9,V9,X9,Z9,AB9,AD9,AF9,AH9,AJ9,AL9,AN9,AP9,AR9,AT9,AV9) -> 3 | BD9: =IF(BB9>0,1,0) -> 1 | BE9: =janeiro!$BH41 -> 40.7 | BF9: 39113 | BG9: =fevereiro!$BE10 -> 1.1 | BI9: =IF(BH9>0,1,0) -> 0
A10: 2 | Z10: 2 | AA10: 20 | AB10: 21.2 | AC10: 60 | AD10: 0.8 | AE10: 20 | AF10: 0.1 | AG10: 5 | AX10: 2 | AY10: =B10+D10+F10+H10+J10+L10+N10+P10+R10+T10+V10+X10+Z10+AB10+AD10+AF10+AH10+AJ10+AL10+AN10+AP10+AR10+AT10+AV10 -> 24.1 | AZ10: =C10+E10+G10+I10+K10+M10+O10+Q10+S10+U10+W10+Y10+AA10+AC10+AE10+AG10+AI10+AK10+AM10+AO10+AQ10+AS10+AU10+AW10 -> 105 | BA10: =MAX(B10,D10,F10,H10,J10,L10,N10,P10,R10,T10,V10,X10,Z10,AB10,AD10,AF10,AH10,AJ10,AL10,AN10,AP10,AR10,AT10,AV10) -> 21.2 | BB10: =COUNT(B10,D10,F10,H10,J10,L10,N10,P10,R10,T10,V10,X10,Z10,AB10,AD10,AF10,AH10,AJ10,AL10,AN10,AP10,AR10,AT10,AV10) -> 4 | BD10: =IF(BB10>0,1,0) -> 1 | BE10: =P9+R9+T9+V9+X9+Z9+AB9+AD9+AF9+AH9+AJ9+AL9+AN9+AP9+AR9+AT9+AV9+B10+D10+F10+H10+J10+L10+N10 -> 1.1 | BG10: =fevereiro!$BE11 -> 24.1 | BI10: =IF(BH10>0,1,0) -> 0
A11: 3 | AX11: 3 | AY11: =B11+D11+F11+H11+J11+L11+N11+P11+R11+T11+V11+X11+Z11+AB11+AD11+AF11+AH11+AJ11+AL11+AN11+AP11+AR11+AT11+AV11 -> 0 | AZ11: =C11+E11+G11+I11+K11+M11+O11+Q11+S11+U11+W11+Y11+AA11+AC11+AE11+AG11+AI11+AK11+AM11+AO11+AQ11+AS11+AU11+AW11 -> 0 | BA11: =MAX(B11,D11,F11,H11,J11,L11,N11,P11,R11,T11,V11,X11,Z11,AB11,AD11,AF11,AH11,AJ11,AL11,AN11,AP11,AR11,AT11,AV11) -> 0 | BB11: =COUNT(B11,D11,F11,H11,J11,L11,N11,P11,R11,T11,V11,X11,Z11,AB11,AD11,AF11,AH11,AJ11,AL11,AN11,AP11,AR11,AT11,AV11) -> 0 | BD11: =IF(BB11>0,1,0) -> 0 | BE11: =P10+R10+T10+V10+X10+Z10+AB10+AD10+AF10+AH10+AJ10+AL10+AN10+AP10+AR10+AT10+AV10+B11+D11+F11+H11+J11+L11+N11 -> 24.1 | BG11: =fevereiro!$BE12 -> 0 | BI11: =IF(BH11>0,1,0) -> 0
A12: 4 | AD12: 6.9 | AE12: 55 | AF12: 0.9 | AG12: 40 | AJ12: 5 | AK12: 30 | AL12: 1 | AM12: 60 | AN12: 0.1 | AO12: 10 | AX12: 4 | AY12: =B12+D12+F12+H12+J12+L12+N12+P12+R12+T12+V12+X12+Z12+AB12+AD12+AF12+AH12+AJ12+AL12+AN12+AP12+AR12+AT12+AV12 -> 13.9 | AZ12: =C12+E12+G12+I12+K12+M12+O12+Q12+S12+U12+W12+Y12+AA12+AC12+AE12+AG12+AI12+AK12+AM12+AO12+AQ12+AS12+AU12+AW12 -> 195 | BA12: =MAX(B12,D12,F12,H12,J12,L12,N12,P12,R12,T12,V12,X12,Z12,AB12,AD12,AF12,AH12,AJ12,AL12,AN12,AP12,AR12,AT12,AV12) -> 6.9 | BB12: =COUNT(B12,D12,F12,H12,J12,L12,N12,P12,R12,T12,V12,X12,Z12,AB12,AD12,AF12,AH12,AJ12,AL12,AN12,AP12,AR12,AT12,AV12) -> 5 | BD12: =IF(BB12>0,1,0) -> 1 | BE12: =P11+R11+T11+V11+X11+Z11+AB11+AD11+AF11+AH11+AJ11+AL11+AN11+AP11+AR11+AT11+AV11+B12+D12+F12+H12+J12+L12+N12 -> 0 | BG12: =fevereiro!$BE13 -> 13.9 | BI12: =IF(BH12>0,1,0) -> 0
A13: 5 | AX13: 5 | AY13: =B13+D13+F13+H13+J13+L13+N13+P13+R13+T13+V13+X13+Z13+AB13+AD13+AF13+AH13+AJ13+AL13+AN13+AP13+AR13+AT13+AV13 -> 0 | AZ13: =C13+E13+G13+I13+K13+M13+O13+Q13+S13+U13+W13+Y13+AA13+AC13+AE13+AG13+AI13+AK13+AM13+AO13+AQ13+AS13+AU13+AW13 -> 0 | BA13: =MAX(B13,D13,F13,H13,J13,L13,N13,P13,R13,T13,V13,X13,Z13,AB13,AD13,AF13,AH13,AJ13,AL13,AN13,AP13,AR13,AT13,AV13) -> 0 | BB13: =COUNT(B13,D13,F13,H13,J13,L13,N13,P13,R13,T13,V13,X13,Z13,AB13,AD13,AF13,AH13,AJ13,AL13,AN13,AP13,AR13,AT13,AV13) -> 0 | BD13: =IF(BB13>0,1,0) -> 0 | BE13: =P12+R12+T12+V12+X12+Z12+AB12+AD12+AF12+AH12+AJ12+AL12+AN12+AP12+AR12+AT12+AV12+B13+D13+F13+H13+J13+L13+N13 -> 13.9 | BG13: =fevereiro!$BE14 -> 0 | BI13: =IF(BH13>0,1,0) -> 0
A14: 6 | AX14: 6 | AY14: =B14+D14+F14+H14+J14+L14+N14+P14+R14+T14+V14+X14+Z14+AB14+AD14+AF14+AH14+AJ14+AL14+AN14+AP14+AR14+AT14+AV14 -> 0 | AZ14: =C14+E14+G14+I14+K14+M14+O14+Q14+S14+U14+W14+Y14+AA14+AC14+AE14+AG14+AI14+AK14+AM14+AO14+AQ14+AS14+AU14+AW14 -> 0 | BA14: =MAX(B14,D14,F14,H14,J14,L14,N14,P14,R14,T14,V14,X14,Z14,AB14,AD14,AF14,AH14,AJ14,AL14,AN14,AP14,AR14,AT14,AV14) -> 0 | BB14: =COUNT(B14,D14,F14,H14,J14,L14,N14,P14,R14,T14,V14,X14,Z14,AB14,AD14,AF14,AH14,AJ14,AL14,AN14,AP14,AR14,AT14,AV14) -> 0 | BD14: =IF(BB14>0,1,0) -> 0 | BE14: =P13+R13+T13+V13+X13+Z13+AB13+AD13+AF13+AH13+AJ13+AL13+AN13+AP13+AR13+AT13+AV13+B14+D14+F14+H14+J14+L14+N14 -> 0 | BG14: =fevereiro!$BE15 -> 0 | BI14: =IF(BH14>0,1,0) -> 0
A15: 7 | AX15: 7 | AY15: =B15+D15+F15+H15+J15+L15+N15+P15+R15+T15+V15+X15+Z15+AB15+AD15+AF15+AH15+AJ15+AL15+AN15+AP15+AR15+AT15+AV15 -> 0 | AZ15: =C15+E15+G15+I15+K15+M15+O15+Q15+S15+U15+W15+Y15+AA15+AC15+AE15+AG15+AI15+AK15+AM15+AO15+AQ15+AS15+AU15+AW15 -> 0 | BA15: =MAX(B15,D15,F15,H15,J15,L15,N15,P15,R15,T15,V15,X15,Z15,AB15,AD15,AF15,AH15,AJ15,AL15,AN15,AP15,AR15,AT15,AV15) -> 0 | BB15: =COUNT(B15,D15,F15,H15,J15,L15,N15,P15,R15,T15,V15,X15,Z15,AB15,AD15,AF15,AH15,AJ15,AL15,AN15,AP15,AR15,AT15,AV15) -> 0 | BD15: =IF(BB15>0,1,0) -> 0 | BE15: =P14+R14+T14+V14+X14+Z14+AB14+AD14+AF14+AH14+AJ14+AL14+AN14+AP14+AR14+AT14+AV14+B15+D15+F15+H15+J15+L15+N15 -> 0 | BG15: =fevereiro!$BE16 -> 0 | BI15: =IF(BH15>0,1,0) -> 0
A16: 8 | AX16: 8 | AY16: =B16+D16+F16+H16+J16+L16+N16+P16+R16+T16+V16+X16+Z16+AB16+AD16+AF16+AH16+AJ16+AL16+AN16+AP16+AR16+AT16+AV16 -> 0 | AZ16: =C16+E16+G16+I16+K16+M16+O16+Q16+S16+U16+W16+Y16+AA16+AC16+AE16+AG16+AI16+AK16+AM16+AO16+AQ16+AS16+AU16+AW16 -> 0 | BA16: =MAX(B16,D16,F16,H16,J16,L16,N16,P16,R16,T16,V16,X16,Z16,AB16,AD16,AF16,AH16,AJ16,AL16,AN16,AP16,AR16,AT16,AV16) -> 0 | BB16: =COUNT(B16,D16,F16,H16,J16,L16,N16,P16,R16,T16,V16,X16,Z16,AB16,AD16,AF16,AH16,AJ16,AL16,AN16,AP16,AR16,AT16,AV16) -> 0 | BD16: =IF(BB16>0,1,0) -> 0 | BE16: =P15+R15+T15+V15+X15+Z15+AB15+AD15+AF15+AH15+AJ15+AL15+AN15+AP15+AR15+AT15+AV15+B16+D16+F16+H16+J16+L16+N16 -> 0 | BG16: =fevereiro!$BE17 -> 0 | BI16: =IF(BH16>0,1,0) -> 0
A17: 9 | AX17: 9 | AY17: =B17+D17+F17+H17+J17+L17+N17+P17+R17+T17+V17+X17+Z17+AB17+AD17+AF17+AH17+AJ17+AL17+AN17+AP17+AR17+AT17+AV17 -> 0 | AZ17: =C17+E17+G17+I17+K17+M17+O17+Q17+S17+U17+W17+Y17+AA17+AC17+AE17+AG17+AI17+AK17+AM17+AO17+AQ17+AS17+AU17+AW17 -> 0 | BA17: =MAX(B17,D17,F17,H17,J17,L17,N17,P17,R17,T17,V17,X17,Z17,AB17,AD17,AF17,AH17,AJ17,AL17,AN17,AP17,AR17,AT17,AV17) -> 0 | BB17: =COUNT(B17,D17,F17,H17,J17,L17,N17,P17,R17,T17,V17,X17,Z17,AB17,AD17,AF17,AH17,AJ17,AL17,AN17,AP17,AR17,AT17,AV17) -> 0 | BD17: =IF(BB17>0,1,0) -> 0 | BE17: =P16+R16+T16+V16+X16+Z16+AB16+AD16+AF16+AH16+AJ16+AL16+AN16+AP16+AR16+AT16+AV16+B17+D17+F17+H17+J17+L17+N17 -> 0 | BG17: =fevereiro!$BE18 -> 0 | BI17: =IF(BH17>0,1,0) -> 0
A18: 10 | AX18: 10 | AY18: =B18+D18+F18+H18+J18+L18+N18+P18+R18+T18+V18+X18+Z18+AB18+AD18+AF18+AH18+AJ18+AL18+AN18+AP18+AR18+AT18+AV18 -> 0 | AZ18: =C18+E18+G18+I18+K18+M18+O18+Q18+S18+U18+W18+Y18+AA18+AC18+AE18+AG18+AI18+AK18+AM18+AO18+AQ18+AS18+AU18+AW18 -> 0 | BA18: =MAX(B18,D18,F18,H18,J18,L18,N18,P18,R18,T18,V18,X18,Z18,AB18,AD18,AF18,AH18,AJ18,AL18,AN18,AP18,AR18,AT18,AV18) -> 0 | BB18: =COUNT(B18,D18,F18,H18,J18,L18,N18,P18,R18,T18,V18,X18,Z18,AB18,AD18,AF18,AH18,AJ18,AL18,AN18,AP18,AR18,AT18,AV18) -> 0 | BD18: =IF(BB18>0,1,0) -> 0 | BE18: =P17+R17+T17+V17+X17+Z17+AB17+AD17+AF17+AH17+AJ17+AL17+AN17+AP17+AR17+AT17+AV17+B18+D18+F18+H18+J18+L18+N18 -> 0 | BG18: =fevereiro!$BE19 -> 0 | BI18: =IF(BH18>0,1,0) -> 0
A19: 11 | AL19: 0.1 | AM19: 15 | AX19: 11 | AY19: =B19+D19+F19+H19+J19+L19+N19+P19+R19+T19+V19+X19+Z19+AB19+AD19+AF19+AH19+AJ19+AL19+AN19+AP19+AR19+AT19+AV19 -> 0.1 | AZ19: =C19+E19+G19+I19+K19+M19+O19+Q19+S19+U19+W19+Y19+AA19+AC19+AE19+AG19+AI19+AK19+AM19+AO19+AQ19+AS19+AU19+AW19 -> 15 | BA19: =MAX(B19,D19,F19,H19,J19,L19,N19,P19,R19,T19,V19,X19,Z19,AB19,AD19,AF19,AH19,AJ19,AL19,AN19,AP19,AR19,AT19,AV19) -> 0.1 | BB19: =COUNT(B19,D19,F19,H19,J19,L19,N19,P19,R19,T19,V19,X19,Z19,AB19,AD19,AF19,AH19,AJ19,AL19,AN19,AP19,AR19,AT19,AV19) -> 1 | BD19: =IF(BB19>0,1,0) -> 1 | BE19: =P18+R18+T18+V18+X18+Z18+AB18+AD18+AF18+AH18+AJ18+AL18+AN18+AP18+AR18+AT18+AV18+B19+D19+F19+H19+J19+L19+N19 -> 0 | BG19: =fevereiro!$BE20 -> 0.1 | BI19: =IF(BH19>0,1,0) -> 0
A20: 12 | AX20: 12 | AY20: =B20+D20+F20+H20+J20+L20+N20+P20+R20+T20+V20+X20+Z20+AB20+AD20+AF20+AH20+AJ20+AL20+AN20+AP20+AR20+AT20+AV20 -> 0 | AZ20: =C20+E20+G20+I20+K20+M20+O20+Q20+S20+U20+W20+Y20+AA20+AC20+AE20+AG20+AI20+AK20+AM20+AO20+AQ20+AS20+AU20+AW20 -> 0 | BA20: =MAX(B20,D20,F20,H20,J20,L20,N20,P20,R20,T20,V20,X20,Z20,AB20,AD20,AF20,AH20,AJ20,AL20,AN20,AP20,AR20,AT20,AV20) -> 0 | BB20: =COUNT(B20,D20,F20,H20,J20,L20,N20,P20,R20,T20,V20,X20,Z20,AB20,AD20,AF20,AH20,AJ20,AL20,AN20,AP20,AR20,AT20,AV20) -> 0 | BD20: =IF(BB20>0,1,0) -> 0 | BE20: =P19+R19+T19+V19+X19+Z19+AB19+AD19+AF19+AH19+AJ19+AL19+AN19+AP19+AR19+AT19+AV19+B20+D20+F20+H20+J20+L20+N20 -> 0.1 | BG20: =fevereiro!$BE21 -> 0 | BI20: =IF(BH20>0,1,0) -> 0
A21: 13 | AR21: 9.3 | AS21: 30 | AT21: 25.8 | AU21: 60 | AV21: 20.1 | AW21: 60 | AX21: 13 | AY21: =B21+D21+F21+H21+J21+L21+N21+P21+R21+T21+V21+X21+Z21+AB21+AD21+AF21+AH21+AJ21+AL21+AN21+AP21+AR21+AT21+AV21 -> 55.2 | AZ21: =C21+E21+G21+I21+K21+M21+O21+Q21+S21+U21+W21+Y21+AA21+AC21+AE21+AG21+AI21+AK21+AM21+AO21+AQ21+AS21+AU21+AW21 -> 150 | BA21: =MAX(B21,D21,F21,H21,J21,L21,N21,P21,R21,T21,V21,X21,Z21,AB21,AD21,AF21,AH21,AJ21,AL21,AN21,AP21,AR21,AT21,AV21) -> 25.8 | BB21: =COUNT(B21,D21,F21,H21,J21,L21,N21,P21,R21,T21,V21,X21,Z21,AB21,AD21,AF21,AH21,AJ21,AL21,AN21,AP21,AR21,AT21,AV21) -> 3 | BD21: =IF(BB21>0,1,0) -> 1 | BE21: =P20+R20+T20+V20+X20+Z20+AB20+AD20+AF20+AH20+AJ20+AL20+AN20+AP20+AR20+AT20+AV20+B21+D21+F21+H21+J21+L21+N21 -> 0 | BG21: =fevereiro!$BE22 -> 64.2 | BI21: =IF(BH21>0,1,0) -> 0
A22: 14 | B22: 4.9 | C22: 60 | D22: 2.4 | E22: 60 | F22: 1.4 | G22: 60 | H22: 0.3 | I22: 60 | V22: 1.2 | W22: 15 | Z22: 0.3 | AA22: 5 | AB22: 1.5 | AC22: 55 | AJ22: 1.1 | AK22: 40 | AP22: 0.2 | AQ22: 10 | AR22: 2.3 | AS22: 60 | AT22: 6.3 | AU22: 60 | AV22: 0.4 | AW22: 15 | AX22: 14 | AY22: =B22+D22+F22+H22+J22+L22+N22+P22+R22+T22+V22+X22+Z22+AB22+AD22+AF22+AH22+AJ22+AL22+AN22+AP22+AR22+AT22+AV22 -> 22.3 | AZ22: =C22+E22+G22+I22+K22+M22+O22+Q22+S22+U22+W22+Y22+AA22+AC22+AE22+AG22+AI22+AK22+AM22+AO22+AQ22+AS22+AU22+AW22 -> 500 | BA22: =MAX(B22,D22,F22,H22,J22,L22,N22,P22,R22,T22,V22,X22,Z22,AB22,AD22,AF22,AH22,AJ22,AL22,AN22,AP22,AR22,AT22,AV22) -> 6.3 | BB22: =COUNT(B22,D22,F22,H22,J22,L22,N22,P22,R22,T22,V22,X22,Z22,AB22,AD22,AF22,AH22,AJ22,AL22,AN22,AP22,AR22,AT22,AV22) -> 12 | BD22: =IF(BB22>0,1,0) -> 1 | BE22: =P21+R21+T21+V21+X21+Z21+AB21+AD21+AF21+AH21+AJ21+AL21+AN21+AP21+AR21+AT21+AV21+B22+D22+F22+H22+J22+L22+N22 -> 64.2 | BG22: =fevereiro!$BE23 -> 16.5 | BI22: =IF(BH22>0,1,0) -> 0
A23: 15 | B23: 0.2 | C23: 10 | D23: 0.6 | E23: 30 | F23: 1.2 | G23: 55 | H23: 0.3 | I23: 25 | J23: 0.5 | K23: 30 | L23: 0.3 | M23: 10 | N23: 0.1 | O23: 5 | T23: 0.3 | U23: 10 | V23: 0.2 | W23: 20 | X23: 0.4 | Y23: 15 | AB23: 0.3 | AC23: 20 | AD23: 0.6 | AE23: 30 | AF23: 0.2 | AG23: 20 | AN23: 0.2 | AO23: 10 | AR23: 0.2 | AS23: 15 | AX23: 15 | AY23: =B23+D23+F23+H23+J23+L23+N23+P23+R23+T23+V23+X23+Z23+AB23+AD23+AF23+AH23+AJ23+AL23+AN23+AP23+AR23+AT23+AV23 -> 5.6 | AZ23: =C23+E23+G23+I23+K23+M23+O23+Q23+S23+U23+W23+Y23+AA23+AC23+AE23+AG23+AI23+AK23+AM23+AO23+AQ23+AS23+AU23+AW23 -> 305 | BA23: =MAX(B23,D23,F23,H23,J23,L23,N23,P23,R23,T23,V23,X23,Z23,AB23,AD23,AF23,AH23,AJ23,AL23,AN23,AP23,AR23,AT23,AV23) -> 1.2 | BB23: =COUNT(B23,D23,F23,H23,J23,L23,N23,P23,R23,T23,V23,X23,Z23,AB23,AD23,AF23,AH23,AJ23,AL23,AN23,AP23,AR23,AT23,AV23) -> 15 | BD23: =IF(BB23>0,1,0) -> 1 | BE23: =P22+R22+T22+V22+X22+Z22+AB22+AD22+AF22+AH22+AJ22+AL22+AN22+AP22+AR22+AT22+AV22+B23+D23+F23+H23+J23+L23+N23 -> 16.5 | BG23: =fevereiro!$BE24 -> 2.5 | BI23: =IF(BH23>0,1,0) -> 0
A24: 16 | N24: 0.1 | AX24: 16 | AY24: =B24+D24+F24+H24+J24+L24+N24+P24+R24+T24+V24+X24+Z24+AB24+AD24+AF24+AH24+AJ24+AL24+AN24+AP24+AR24+AT24+AV24 -> 0.1 | AZ24: =C24+E24+G24+I24+K24+M24+O24+Q24+S24+U24+W24+Y24+AA24+AC24+AE24+AG24+AI24+AK24+AM24+AO24+AQ24+AS24+AU24+AW24 -> 0 | BA24: =MAX(B24,D24,F24,H24,J24,L24,N24,P24,R24,T24,V24,X24,Z24,AB24,AD24,AF24,AH24,AJ24,AL24,AN24,AP24,AR24,AT24,AV24) -> 0.1 | BB24: =COUNT(B24,D24,F24,H24,J24,L24,N24,P24,R24,T24,V24,X24,Z24,AB24,AD24,AF24,AH24,AJ24,AL24,AN24,AP24,AR24,AT24,AV24) -> 1 | BD24: =IF(BB24>0,1,0) -> 1 | BE24: =P23+R23+T23+V23+X23+Z23+AB23+AD23+AF23+AH23+AJ23+AL23+AN23+AP23+AR23+AT23+AV23+B24+D24+F24+H24+J24+L24+N24 -> 2.5 | BG24: =fevereiro!$BE25 -> 0 | BI24: =IF(BH24>0,1,0) -> 0
A25: 17 | AX25: 17 | AY25: =B25+D25+F25+H25+J25+L25+N25+P25+R25+T25+V25+X25+Z25+AB25+AD25+AF25+AH25+AJ25+AL25+AN25+AP25+AR25+AT25+AV25 -> 0 | AZ25: =C25+E25+G25+I25+K25+M25+O25+Q25+S25+U25+W25+Y25+AA25+AC25+AE25+AG25+AI25+AK25+AM25+AO25+AQ25+AS25+AU25+AW25 -> 0 | BA25: =MAX(B25,D25,F25,H25,J25,L25,N25,P25,R25,T25,V25,X25,Z25,AB25,AD25,AF25,AH25,AJ25,AL25,AN25,AP25,AR25,AT25,AV25) -> 0 | BB25: =COUNT(B25,D25,F25,H25,J25,L25,N25,P25,R25,T25,V25,X25,Z25,AB25,AD25,AF25,AH25,AJ25,AL25,AN25,AP25,AR25,AT25,AV25) -> 0 | BD25: =IF(BB25>0,1,0) -> 0 | BE25: =P24+R24+T24+V24+X24+Z24+AB24+AD24+AF24+AH24+AJ24+AL24+AN24+AP24+AR24+AT24+AV24+B25+D25+F25+H25+J25+L25+N25 -> 0 | BG25: =fevereiro!$BE26 -> 0 | BI25: =IF(BH25>0,1,0) -> 0
A26: 18 | AF26: 3.5 | AG26: 25 | AH26: 1.4 | AI26: 55 | AJ26: 0.2 | AK26: 10 | AX26: 18 | AY26: =B26+D26+F26+H26+J26+L26+N26+P26+R26+T26+V26+X26+Z26+AB26+AD26+AF26+AH26+AJ26+AL26+AN26+AP26+AR26+AT26+AV26 -> 5.1 | AZ26: =C26+E26+G26+I26+K26+M26+O26+Q26+S26+U26+W26+Y26+AA26+AC26+AE26+AG26+AI26+AK26+AM26+AO26+AQ26+AS26+AU26+AW26 -> 90 | BA26: =MAX(B26,D26,F26,H26,J26,L26,N26,P26,R26,T26,V26,X26,Z26,AB26,AD26,AF26,AH26,AJ26,AL26,AN26,AP26,AR26,AT26,AV26) -> 3.5 | BB26: =COUNT(B26,D26,F26,H26,J26,L26,N26,P26,R26,T26,V26,X26,Z26,AB26,AD26,AF26,AH26,AJ26,AL26,AN26,AP26,AR26,AT26,AV26) -> 3 | BD26: =IF(BB26>0,1,0) -> 1 | BE26: =P25+R25+T25+V25+X25+Z25+AB25+AD25+AF25+AH25+AJ25+AL25+AN25+AP25+AR25+AT25+AV25+B26+D26+F26+H26+J26+L26+N26 -> 0 | BG26: =fevereiro!$BE27 -> 5.1 | BI26: =IF(BH26>0,1,0) -> 0
A27: 19 | AF27: 2.2 | AG27: 30 | AH27: 5.1 | AI27: 30 | AX27: 19 | AY27: =B27+D27+F27+H27+J27+L27+N27+P27+R27+T27+V27+X27+Z27+AB27+AD27+AF27+AH27+AJ27+AL27+AN27+AP27+AR27+AT27+AV27 -> 7.3 | AZ27: =C27+E27+G27+I27+K27+M27+O27+Q27+S27+U27+W27+Y27+AA27+AC27+AE27+AG27+AI27+AK27+AM27+AO27+AQ27+AS27+AU27+AW27 -> 60 | BA27: =MAX(B27,D27,F27,H27,J27,L27,N27,P27,R27,T27,V27,X27,Z27,AB27,AD27,AF27,AH27,AJ27,AL27,AN27,AP27,AR27,AT27,AV27) -> 5.1 | BB27: =COUNT(B27,D27,F27,H27,J27,L27,N27,P27,R27,T27,V27,X27,Z27,AB27,AD27,AF27,AH27,AJ27,AL27,AN27,AP27,AR27,AT27,AV27) -> 2 | BD27: =IF(BB27>0,1,0) -> 1 | BE27: =P26+R26+T26+V26+X26+Z26+AB26+AD26+AF26+AH26+AJ26+AL26+AN26+AP26+AR26+AT26+AV26+B27+D27+F27+H27+J27+L27+N27 -> 5.1 | BG27: =fevereiro!$BE28 -> 7.3 | BI27: =IF(BH27>0,1,0) -> 0
A28: 20 | V28: 5.7 | W28: 20 | X28: 2.4 | Y28: 20 | AB28: 0.1 | AC28: 5 | AD28: 14.7 | AE28: 60 | AL28: 0.1 | AM28: 5 | AV28: 0.1 | AW28: 5 | AX28: 20 | AY28: =B28+D28+F28+H28+J28+L28+N28+P28+R28+T28+V28+X28+Z28+AB28+AD28+AF28+AH28+AJ28+AL28+AN28+AP28+AR28+AT28+AV28 -> 23.1 | AZ28: =C28+E28+G28+I28+K28+M28+O28+Q28+S28+U28+W28+Y28+AA28+AC28+AE28+AG28+AI28+AK28+AM28+AO28+AQ28+AS28+AU28+AW28 -> 115 | BA28: =MAX(B28,D28,F28,H28,J28,L28,N28,P28,R28,T28,V28,X28,Z28,AB28,AD28,AF28,AH28,AJ28,AL28,AN28,AP28,AR28,AT28,AV28) -> 14.7 | BB28: =COUNT(B28,D28,F28,H28,J28,L28,N28,P28,R28,T28,V28,X28,Z28,AB28,AD28,AF28,AH28,AJ28,AL28,AN28,AP28,AR28,AT28,AV28) -> 6 | BD28: =IF(BB28>0,1,0) -> 1 | BE28: =P27+R27+T27+V27+X27+Z27+AB27+AD27+AF27+AH27+AJ27+AL27+AN27+AP27+AR27+AT27+AV27+B28+D28+F28+H28+J28+L28+N28 -> 7.3 | BG28: =fevereiro!$BE29 -> 23.1 | BI28: =IF(BH28>0,1,0) -> 0
A29: 21 | AD29: 15.6 | AE29: 30 | AF29: 3.9 | AG29: 20 | AH29: 0.2 | AI29: 10 | AJ29: 1.5 | AK29: 40 | AL29: 6.8 | AM29: 50 | AN29: 0.4 | AO29: 20 | AP29: 0.4 | AQ29: 25 | AR29: 1.4 | AS29: 60 | AT29: 0.3 | AU29: 20 | AX29: 21 | AY29: =B29+D29+F29+H29+J29+L29+N29+P29+R29+T29+V29+X29+Z29+AB29+AD29+AF29+AH29+AJ29+AL29+AN29+AP29+AR29+AT29+AV29 -> 30.5 | AZ29: =C29+E29+G29+I29+K29+M29+O29+Q29+S29+U29+W29+Y29+AA29+AC29+AE29+AG29+AI29+AK29+AM29+AO29+AQ29+AS29+AU29+AW29 -> 275 | BA29: =MAX(B29,D29,F29,H29,J29,L29,N29,P29,R29,T29,V29,X29,Z29,AB29,AD29,AF29,AH29,AJ29,AL29,AN29,AP29,AR29,AT29,AV29) -> 15.6 | BB29: =COUNT(B29,D29,F29,H29,J29,L29,N29,P29,R29,T29,V29,X29,Z29,AB29,AD29,AF29,AH29,AJ29,AL29,AN29,AP29,AR29,AT29,AV29) -> 9 | BD29: =IF(BB29>0,1,0) -> 1 | BE29: =P28+R28+T28+V28+X28+Z28+AB28+AD28+AF28+AH28+AJ28+AL28+AN28+AP28+AR28+AT28+AV28+B29+D29+F29+H29+J29+L29+N29 -> 23.1 | BG29: =fevereiro!$BE30 -> 30.7 | BI29: =IF(BH29>0,1,0) -> 0
A30: 22 | B30: 0.1 | C30: 5 | F30: 0.1 | G30: 5 | AX30: 22 | AY30: =B30+D30+F30+H30+J30+L30+N30+P30+R30+T30+V30+X30+Z30+AB30+AD30+AF30+AH30+AJ30+AL30+AN30+AP30+AR30+AT30+AV30 -> 0.2 | AZ30: =C30+E30+G30+I30+K30+M30+O30+Q30+S30+U30+W30+Y30+AA30+AC30+AE30+AG30+AI30+AK30+AM30+AO30+AQ30+AS30+AU30+AW30 -> 10 | BA30: =MAX(B30,D30,F30,H30,J30,L30,N30,P30,R30,T30,V30,X30,Z30,AB30,AD30,AF30,AH30,AJ30,AL30,AN30,AP30,AR30,AT30,AV30) -> 0.1 | BB30: =COUNT(B30,D30,F30,H30,J30,L30,N30,P30,R30,T30,V30,X30,Z30,AB30,AD30,AF30,AH30,AJ30,AL30,AN30,AP30,AR30,AT30,AV30) -> 2 | BD30: =IF(BB30>0,1,0) -> 1 | BE30: =P29+R29+T29+V29+X29+Z29+AB29+AD29+AF29+AH29+AJ29+AL29+AN29+AP29+AR29+AT29+AV29+B30+D30+F30+H30+J30+L30+N30 -> 30.7 | BG30: =fevereiro!$BE31 -> 0 | BI30: =IF(BH30>0,1,0) -> 0
A31: 23 | AH31: 9.7 | AI31: 10 | AJ31: 11.3 | AK31: 10 | AN31: 1 | AO31: 20 | AP31: 0.3 | AQ31: 5 | AR31: 0.5 | AS31: 25 | AX31: 23 | AY31: =B31+D31+F31+H31+J31+L31+N31+P31+R31+T31+V31+X31+Z31+AB31+AD31+AF31+AH31+AJ31+AL31+AN31+AP31+AR31+AT31+AV31 -> 22.8 | AZ31: =C31+E31+G31+I31+K31+M31+O31+Q31+S31+U31+W31+Y31+AA31+AC31+AE31+AG31+AI31+AK31+AM31+AO31+AQ31+AS31+AU31+AW31 -> 70 | BA31: =MAX(B31,D31,F31,H31,J31,L31,N31,P31,R31,T31,V31,X31,Z31,AB31,AD31,AF31,AH31,AJ31,AL31,AN31,AP31,AR31,AT31,AV31) -> 11.3 | BB31: =COUNT(B31,D31,F31,H31,J31,L31,N31,P31,R31,T31,V31,X31,Z31,AB31,AD31,AF31,AH31,AJ31,AL31,AN31,AP31,AR31,AT31,AV31) -> 5 | BD31: =IF(BB31>0,1,0) -> 1 | BE31: =P30+R30+T30+V30+X30+Z30+AB30+AD30+AF30+AH30+AJ30+AL30+AN30+AP30+AR30+AT30+AV30+B31+D31+F31+H31+J31+L31+N31 -> 0 | BG31: =fevereiro!$BE32 -> 22.8 | BI31: =IF(BH31>0,1,0) -> 0
A32: 24 | AB32: 7.6 | AC32: 20 | AD32: 9.5 | AE32: 40 | AF32: 6.2 | AG32: 60 | AH32: 0.4 | AI32: 30 | AJ32: 0.1 | AK32: 5 | AX32: 24 | AY32: =B32+D32+F32+H32+J32+L32+N32+P32+R32+T32+V32+X32+Z32+AB32+AD32+AF32+AH32+AJ32+AL32+AN32+AP32+AR32+AT32+AV32 -> 23.8 | AZ32: =C32+E32+G32+I32+K32+M32+O32+Q32+S32+U32+W32+Y32+AA32+AC32+AE32+AG32+AI32+AK32+AM32+AO32+AQ32+AS32+AU32+AW32 -> 155 | BA32: =MAX(B32,D32,F32,H32,J32,L32,N32,P32,R32,T32,V32,X32,Z32,AB32,AD32,AF32,AH32,AJ32,AL32,AN32,AP32,AR32,AT32,AV32) -> 9.5 | BB32: =COUNT(B32,D32,F32,H32,J32,L32,N32,P32,R32,T32,V32,X32,Z32,AB32,AD32,AF32,AH32,AJ32,AL32,AN32,AP32,AR32,AT32,AV32) -> 5 | BD32: =IF(BB32>0,1,0) -> 1 | BE32: =P31+R31+T31+V31+X31+Z31+AB31+AD31+AF31+AH31+AJ31+AL31+AN31+AP31+AR31+AT31+AV31+B32+D32+F32+H32+J32+L32+N32 -> 22.8 | BG32: =fevereiro!$BE33 -> 23.8 | BI32: =IF(BH32>0,1,0) -> 0
A33: 25 | AX33: 25 | AY33: =B33+D33+F33+H33+J33+L33+N33+P33+R33+T33+V33+X33+Z33+AB33+AD33+AF33+AH33+AJ33+AL33+AN33+AP33+AR33+AT33+AV33 -> 0 | AZ33: =C33+E33+G33+I33+K33+M33+O33+Q33+S33+U33+W33+Y33+AA33+AC33+AE33+AG33+AI33+AK33+AM33+AO33+AQ33+AS33+AU33+AW33 -> 0 | BA33: =MAX(B33,D33,F33,H33,J33,L33,N33,P33,R33,T33,V33,X33,Z33,AB33,AD33,AF33,AH33,AJ33,AL33,AN33,AP33,AR33,AT33,AV33) -> 0 | BB33: =COUNT(B33,D33,F33,H33,J33,L33,N33,P33,R33,T33,V33,X33,Z33,AB33,AD33,AF33,AH33,AJ33,AL33,AN33,AP33,AR33,AT33,AV33) -> 0 | BD33: =IF(BB33>0,1,0) -> 0 | BE33: =P32+R32+T32+V32+X32+Z32+AB32+AD32+AF32+AH32+AJ32+AL32+AN32+AP32+AR32+AT32+AV32+B33+D33+F33+H33+J33+L33+N33 -> 23.8 | BG33: =fevereiro!$BE34 -> 0 | BI33: =IF(BH33>0,1,0) -> 0
A34: 26 | AX34: 26 | AY34: =B34+D34+F34+H34+J34+L34+N34+P34+R34+T34+V34+X34+Z34+AB34+AD34+AF34+AH34+AJ34+AL34+AN34+AP34+AR34+AT34+AV34 -> 0 | AZ34: =C34+E34+G34+I34+K34+M34+O34+Q34+S34+U34+W34+Y34+AA34+AC34+AE34+AG34+AI34+AK34+AM34+AO34+AQ34+AS34+AU34+AW34 -> 0 | BA34: =MAX(B34,D34,F34,H34,J34,L34,N34,P34,R34,T34,V34,X34,Z34,AB34,AD34,AF34,AH34,AJ34,AL34,AN34,AP34,AR34,AT34,AV34) -> 0 | BB34: =COUNT(B34,D34,F34,H34,J34,L34,N34,P34,R34,T34,V34,X34,Z34,AB34,AD34,AF34,AH34,AJ34,AL34,AN34,AP34,AR34,AT34,AV34) -> 0 | BD34: =IF(BB34>0,1,0) -> 0 | BE34: =P33+R33+T33+V33+X33+Z33+AB33+AD33+AF33+AH33+AJ33+AL33+AN33+AP33+AR33+AT33+AV33+B34+D34+F34+H34+J34+L34+N34 -> 0 | BG34: =fevereiro!$BE35 -> 0 | BI34: =IF(BH34>0,1,0) -> 0
A35: 27 | AX35: 27 | AY35: =B35+D35+F35+H35+J35+L35+N35+P35+R35+T35+V35+X35+Z35+AB35+AD35+AF35+AH35+AJ35+AL35+AN35+AP35+AR35+AT35+AV35 -> 0 | AZ35: =C35+E35+G35+I35+K35+M35+O35+Q35+S35+U35+W35+Y35+AA35+AC35+AE35+AG35+AI35+AK35+AM35+AO35+AQ35+AS35+AU35+AW35 -> 0 | BA35: =MAX(B35,D35,F35,H35,J35,L35,N35,P35,R35,T35,V35,X35,Z35,AB35,AD35,AF35,AH35,AJ35,AL35,AN35,AP35,AR35,AT35,AV35) -> 0 | BB35: =COUNT(B35,D35,F35,H35,J35,L35,N35,P35,R35,T35,V35,X35,Z35,AB35,AD35,AF35,AH35,AJ35,AL35,AN35,AP35,AR35,AT35,AV35) -> 0 | BD35: =IF(BB35>0,1,0) -> 0 | BE35: =P34+R34+T34+V34+X34+Z34+AB34+AD34+AF34+AH34+AJ34+AL34+AN34+AP34+AR34+AT34+AV34+B35+D35+F35+H35+J35+L35+N35 -> 0 | BG35: =fevereiro!$BE36 -> 0 | BI35: =IF(BH35>0,1,0) -> 0
A36: 28 | AB36: 5.9 | AC36: 10 | AF36: 8.1 | AG36: 30 | AH36: 0.1 | AI36: 5 | AJ36: 3.4 | AK36: 20 | AX36: 28 | AY36: =B36+D36+F36+H36+J36+L36+N36+P36+R36+T36+V36+X36+Z36+AB36+AD36+AF36+AH36+AJ36+AL36+AN36+AP36+AR36+AT36+AV36 -> 17.5 | AZ36: =C36+E36+G36+I36+K36+M36+O36+Q36+S36+U36+W36+Y36+AA36+AC36+AE36+AG36+AI36+AK36+AM36+AO36+AQ36+AS36+AU36+AW36 -> 65 | BA36: =MAX(B36,D36,F36,H36,J36,L36,N36,P36,R36,T36,V36,X36,Z36,AB36,AD36,AF36,AH36,AJ36,AL36,AN36,AP36,AR36,AT36,AV36) -> 8.1 | BB36: =COUNT(B36,D36,F36,H36,J36,L36,N36,P36,R36,T36,V36,X36,Z36,AB36,AD36,AF36,AH36,AJ36,AL36,AN36,AP36,AR36,AT36,AV36) -> 4 | BD36: =IF(BB36>0,1,0) -> 1 | BE36: =P35+R35+T35+V35+X35+Z35+AB35+AD35+AF35+AH35+AJ35+AL35+AN35+AP35+AR35+AT35+AV35+B36+D36+F36+H36+J36+L36+N36 -> 0 | BG36: =fevereiro!$BE37 -> 19.9 | BI36: =IF(BH36>0,1,0) -> 0
A37: 29 | J37: 1.5 | K37: 25 | L37: 0.9 | M37: 25 | AX37: 29 | AY37: =B37+D37+F37+H37+J37+L37+N37+P37+R37+T37+V37+X37+Z37+AB37+AD37+AF37+AH37+AJ37+AL37+AN37+AP37+AR37+AT37+AV37 -> 2.4 | AZ37: =C37+E37+G37+I37+K37+M37+O37+Q37+S37+U37+W37+Y37+AA37+AC37+AE37+AG37+AI37+AK37+AM37+AO37+AQ37+AS37+AU37+AW37 -> 50 | BA37: =MAX(B37,D37,F37,H37,J37,L37,N37,P37,R37,T37,V37,X37,Z37,AB37,AD37,AF37,AH37,AJ37,AL37,AN37,AP37,AR37,AT37,AV37) -> 1.5 | BB37: =COUNT(B37,D37,F37,H37,J37,L37,N37,P37,R37,T37,V37,X37,Z37,AB37,AD37,AF37,AH37,AJ37,AL37,AN37,AP37,AR37,AT37,AV37) -> 2 | BD37: =IF(BB37>0,1,0) -> 1 | BE37: =P36+R36+T36+V36+X36+Z36+AB36+AD36+AF36+AH36+AJ36+AL36+AN36+AP36+AR36+AT36+AV36+B37+D37+F37+H37+J37+L37+N37 -> 19.9 | BG37: =fevereiro!$BE38 -> 0 | BI37: =IF(BH37>0,1,0) -> 0
A38: 1 | BG38: =fevereiro!$BH40 -> 0 | BI38: =IF(BH38>0,1,0) -> 0
BH39: 39142
AY40: VALORES MENSAIS | BD40: TOTAL | BE40: =SUM(BE9:BE39) -> 295.8 | BH40: =P37+R37+T37+V37+X37+Z37+AB37+AD37+AF37+AH37+AJ37+AL37+AN37+AP37+AR37+AT37+AV37+B38+D38+F38+H38+J38+L38+N38 -> 0
...

Sheet marco
B1: MARÇO DE 2024 | J1: INSTITUTO ASTRONÔMICO E GEOFÍSICO DA UNIVERSIDADE DE SÃO PAULO
B2: DIGITADO POR PETY | AU2: Planilha atualizada por Edvaldo Gomes
B3: VERIFICADO POR PETY | M3: RESULTADOS EXTRAÍDOS DE PLUVIOGRAMA DIÁRIO (mm DE CHUVA)
AY4: VALORES DIÁRIOS | BE4: VALORES DIÁRIOS
AY5: (de 00h a 24h) | BE5: DAEE | BF5: DESVIO | BG5: EMAE
AY6: Altura | AZ6: Duração | BA6: Máxima | BE6: Altura | BG6: Máxima
A7: H. | B7: 0 - 1 | D7: 1 - 2 | F7: 2 - 3 | H7: 3 - 4 | J7: 4 - 5 | L7: 5 - 6 | N7: 6 - 7 | P7: 7 - 8 | R7: 8 - 9 | T7: 9 - 10 | V7: 10 - 11 | X7: 11 - 12 | Z7: 12 - 13 | AB7: 13 - 14 | AD7: 14 - 15 | AF7: 15 - 16 | AH7: 16 - 17 | AJ7: 17 - 18 | AL7: 18 - 19 | AN7: 19 - 20 | AP7: 20 - 21 | AR7: 21 - 22 | AT7: 22 - 23 | AV7: 23 - 24 | AX7: H. | AY7: total | AZ7: total | BA7: altura | BB7: Freq. | BE7: total | BG7: altura
A8: D. | B8: ALT. | C8: DUR. | D8: ALT. | E8: DUR. | F8: ALT. | G8: DUR. | H8: ALT. | I8: DUR. | J8: ALT. | K8: DUR. | L8: ALT. | M8: DUR. | N8: ALT. | O8: DUR. | P8: ALT. | Q8: DUR. | R8: ALT. | S8: DUR. | T8: ALT. | U8: DUR. | V8: ALT. | W8: DUR. | X8: ALT. | Y8: DUR. | Z8: ALT. | AA8: DUR. | AB8: ALT. | AC8: DUR. | AD8: ALT. | AE8: DUR. | AF8: ALT. | AG8: DUR. | AH8: ALT. | AI8: DUR. | AJ8: ALT. | AK8: DUR. | AL8: ALT. | AM8: DUR. | AN8: ALT. | AO8: DUR. | AP8: ALT. | AQ8: DUR. | AR8: ALT. | AS8: DUR. | AT8: ALT. | AU8: DUR. | AV8: ALT. | AW8: DUR. | AX8: D. | AY8: (mm) | AZ8: (min) | BA8: horária | BB8: (horas) | BE8: (mm) | BG8: horária | BH8: (horas)
A9: 1 | AF9: 2.8 | AG9: 10 | AX9: 1 | AY9: =B9+D9+F9+H9+J9+L9+N9+P9+R9+T9+V9+X9+Z9+AB9+AD9+AF9+AH9+AJ9+AL9+AN9+AP9+AR9+AT9+AV9 -> 2.8 | AZ9: =C9+E9+G9+I9+K9+M9+O9+Q9+S9+U9+W9+Y9+AA9+AC9+AE9+AG9+AI9+AK9+AM9+AO9+AQ9+AS9+AU9+AW9 -> 10 | BA9: =MAX(B9,D9,F9,H9,J9,L9,N9,P9,R9,T9,V9,X9,Z9,AB9,AD9,AF9,AH9,AJ9,AL9,AN9,AP9,AR9,AT9,AV9) -> 2.8 | BB9: =COUNT(B9,D9,F9,H9,J9,L9,N9,P9,R9,T9,V9,X9,Z9,AB9,AD9,AF9,AH9,AJ9,AL9,AN9,AP9,AR9,AT9,AV9) -> 1 | BD9: =IF(BB9>0,1,0) -> 1 | BE9: =fevereiro!$BH40 -> 0 | BF9: 39507 | BG9: =marco!$BE10 -> 2.8 | BI9: =IF(BH9>0,1,0) -> 0
A10: 2 | AX10: 2 | AY10: =B10+D10+F10+H10+J10+L10+N10+P10+R10+T10+V10+X10+Z10+AB10+AD10+AF10+AH10+AJ10+AL10+AN10+AP10+AR10+AT10+AV10 -> 0 | AZ10: =C10+E10+G10+I10+K10+M10+O10+Q10+S10+U10+W10+Y10+AA10+AC10+AE10+AG10+AI10+AK10+AM10+AO10+AQ10+AS10+AU10+AW10 -> 0 | BA10: =MAX(B10,D10,F10,H10,J10,L10,N10,P10,R10,T10,V10,X10,Z10,AB10,AD10,AF10,AH10,AJ10,AL10,AN10,AP10,AR10,AT10,AV10) -> 0 | BB10: =COUNT(B10,D10,F10,H10,J10,L10,N10,P10,R10,T10,V10,X10,Z10,AB10,AD10,AF10,AH10,AJ10,AL10,AN10,AP10,AR10,AT10,AV10) -> 0 | BD10: =IF(BB10>0,1,0) -> 0 | BE10: =P9+R9+T9+V9+X9+Z9+AB9+AD9+AF9+AH9+AJ9+AL9+AN9+AP9+AR9+AT9+AV9+B10+D10+F10+H10+J10+L10+N10 -> 2.8 | BG10: =marco!$BE11 -> 0 | BI10: =IF(BH10>0,1,0) -> 0
A11: 3 | AX11: 3 | AY11: =B11+D11+F11+H11+J11+L11+N11+P11+R11+T11+V11+X11+Z11+AB11+AD11+AF11+AH11+AJ11+AL11+AN11+AP11+AR11+AT11+AV11 -> 0 | AZ11: =C11+E11+G11+I11+K11+M11+O11+Q11+S11+U11+W11+Y11+AA11+AC11+AE11+AG11+AI11+AK11+AM11+AO11+AQ11+AS11+AU11+AW11 -> 0 | BA11: =MAX(B11,D11,F11,H11,J11,L11,N11,P11,R11,T11,V11,X11,Z11,AB11,AD11,AF11,AH11,AJ11,AL11,AN11,AP11,AR11,AT11,AV11) -> 0 | BB11: =COUNT(B11,D11,F11,H11,J11,L11,N11,P11,R11,T11,V11,X11,Z11,AB11,AD11,AF11,AH11,AJ11,AL11,AN11,AP11,AR11,AT11,AV11) -> 0 | BD11: =IF(BB11>0,1,0) -> 0 | BE11: =P10+R10+T10+V10+X10+Z10+AB10+AD10+AF10+AH10+AJ10+AL10+AN10+AP10+AR10+AT10+AV10+B11+D11+F11+H11+J11+L11+N11 -> 0 | BG11: =marco!$BE12 -> 0 | BI11: =IF(BH11>0,1,0) -> 0
A12: 4 | AX12: 4 | AY12: =B12+D12+F12+H12+J12+L12+N12+P12+R12+T12+V12+X12+Z12+AB12+AD12+AF12+AH12+AJ12+AL12+AN12+AP12+AR12+AT12+AV12 -> 0 | AZ12: =C12+E12+G12+I12+K12+M12+O12+Q12+S12+U12+W12+Y12+AA12+AC12+AE12+AG12+AI12+AK12+AM12+AO12+AQ12+AS12+AU12+AW12 -> 0 | BA12: =MAX(B12,D12,F12,H12,J12,L12,N12,P12,R12,T12,V12,X12,Z12,AB12,AD12,AF12,AH12,AJ12,AL12,AN12,AP12,AR12,AT12,AV12) -> 0 | BB12: =COUNT(B12,D12,F12,H12,J12,L12,N12,P12,R12,T12,V12,X12,Z12,AB12,AD12,AF12,AH12,AJ12,AL12,AN12,AP12,AR12,AT12,AV12) -> 0 | BD12: =IF(BB12>0,1,0) -> 0 | BE12: =P11+R11+T11+V11+X11+Z11+AB11+AD11+AF11+AH11+AJ11+AL11+AN11+AP11+AR11+AT11+AV11+B12+D12+F12+H12+J12+L12+N12 -> 0 | BG12: =marco!$BE13 -> 2.1 | BI12: =IF(BH12>0,1,0) -> 0
A13: 5 | H13: 1.9 | I13: 15 | L13: 0.2 | M13: 15 | AH13: 1 | AI13: 10 | AP13: 7.6 | AQ13: 55 | AR13: 0.9 | AS13: 25 | AX13: 5 | AY13: =B13+D13+F13+H13+J13+L13+N13+P13+R13+T13+V13+X13+Z13+AB13+AD13+AF13+AH13+AJ13+AL13+AN13+AP13+AR13+AT13+AV13 -> 11.6 | AZ13: =C13+E13+G13+I13+K13+M13+O13+Q13+S13+U13+W13+Y13+AA13+AC13+AE13+AG13+AI13+AK13+AM13+AO13+AQ13+AS13+AU13+AW13 -> 120 | BA13: =MAX(B13,D13,F13,H13,J13,L13,N13,P13,R13,T13,V13,X13,Z13,AB13,AD13,AF13,AH13,AJ13,AL13,AN13,AP13,AR13,AT13,AV13) -> 7.6 | BB13: =COUNT(B13,D13,F13,H13,J13,L13,N13,P13,R13,T13,V13,X13,Z13,AB13,AD13,AF13,AH13,AJ13,AL13,AN13,AP13,AR13,AT13,AV13) -> 5 | BD13: =IF(BB13>0,1,0) -> 1 | BE13: =P12+R12+T12+V12+X12+Z12+AB12+AD12+AF12+AH12+AJ12+AL12+AN12+AP12+AR12+AT12+AV12+B13+D13+F13+H13+J13+L13+N13 -> 2.1 | BG13: =marco!$BE14 -> 11.3 | BI13: =IF(BH13>0,1,0) -> 0
A14: 6 | F14: 1.1 | G14: 25 | H14: 0.6 | I14: 20 | N14: 0.1 | O14: 5 | AX14: 6 | AY14: =B14+D14+F14+H14+J14+L14+N14+P14+R14+T14+V14+X14+Z14+AB14+AD14+AF14+AH14+AJ14+AL14+AN14+AP14+AR14+AT14+AV14 -> 1.8 | AZ14: =C14+E14+G14+I14+K14+M14+O14+Q14+S14+U14+W14+Y14+AA14+AC14+AE14+AG14+AI14+AK14+AM14+AO14+AQ14+AS14+AU14+AW14 -> 50 | BA14: =MAX(B14,D14,F14,H14,J14,L14,N14,P14,R14,T14,V14,X14,Z14,AB14,AD14,AF14,AH14,AJ14,AL14,AN14,AP14,AR14,AT14,AV14) -> 1.1 | BB14: =COUNT(B14,D14,F14,H14,J14,L14,N14,P14,R14,T14,V14,X14,Z14,AB14,AD14,AF14,AH14,AJ14,AL14,AN14,AP14,AR14,AT14,AV14) -> 3 | BD14: =IF(BB14>0,1,0) -> 1 | BE14: =P13+R13+T13+V13+X13+Z13+AB13+AD13+AF13+AH13+AJ13+AL13+AN13+AP13+AR13+AT13+AV13+B14+D14+F14+H14+J14+L14+N14 -> 11.3 | BG14: =marco!$BE15 -> 0 | BI14: =IF(BH14>0,1,0) -> 0
A15: 7 | AX15: 7 | AY15: =B15+D15+F15+H15+J15+L15+N15+P15+R15+T15+V15+X15+Z15+AB15+AD15+AF15+AH15+AJ15+AL15+AN15+AP15+AR15+AT15+AV15 -> 0 | AZ15: =C15+E15+G15+I15+K15+M15+O15+Q15+S15+U15+W15+Y15+AA15+AC15+AE15+AG15+AI15+AK15+AM15+AO15+AQ15+AS15+AU15+AW15 -> 0 | BA15: =MAX(B15,D15,F15,H15,J15,L15,N15,P15,R15,T15,V15,X15,Z15,AB15,AD15,AF15,AH15,AJ15,AL15,AN15,AP15,AR15,AT15,AV15) -> 0 | BB15: =COUNT(B15,D15,F15,H15,J15,L15,N15,P15,R15,T15,V15,X15,Z15,AB15,AD15,AF15,AH15,AJ15,AL15,AN15,AP15,AR15,AT15,AV15) -> 0 | BD15: =IF(BB15>0,1,0) -> 0 | BE15: =P14+R14+T14+V14+X14+Z14+AB14+AD14+AF14+AH14+AJ14+AL14+AN14+AP14+AR14+AT14+AV14+B15+D15+F15+H15+J15+L15+N15 -> 0 | BG15: =marco!$BE16 -> 0 | BI15: =IF(BH15>0,1,0) -> 0
A16: 8 | AF16: 22.8 | AG16: 30 | AH16: 8.6 | AI16: 50 | AJ16: 0.8 | AK16: 30 | AL16: 1.2 | AM16: 30 | AN16: 3.4 | AO16: 60 | AP16: 3.2 | AQ16: 60 | AR16: 0.7 | AS16: 60 | AT16: 0.8 | AU16: 45 | AV16: 1.2 | AW16: 50 | AX16: 8 | AY16: =B16+D16+F16+H16+J16+L16+N16+P16+R16+T16+V16+X16+Z16+AB16+AD16+AF16+AH16+AJ16+AL16+AN16+AP16+AR16+AT16+AV16 -> 42.7 | AZ16: =C16+E16+G16+I16+K16+M16+O16+Q16+S16+U16+W16+Y16+AA16+AC16+AE16+AG16+AI16+AK16+AM16+AO16+AQ16+AS16+AU16+AW16 -> 415 | BA16: =MAX(B16,D16,F16,H16,J16,L16,N16,P16,R16,T16,V16,X16,Z16,AB16,AD16,AF16,AH16,AJ16,AL16,AN16,AP16,AR16,AT16,AV16) -> 22.8 | BB16: =COUNT(B16,D16,F16,H16,J16,L16,N16,P16,R16,T16,V16,X16,Z16,AB16,AD16,AF16,AH16,AJ16,AL16,AN16,AP16,AR16,AT16,AV16) -> 9 | BD16: =IF(BB16>0,1,0) -> 1 | BE16: =P15+R15+T15+V15+X15+Z15+AB15+AD15+AF15+AH15+AJ15+AL15+AN15+AP15+AR15+AT15+AV15+B16+D16+F16+H16+J16+L16+N16 -> 0 | BG16: =marco!$BE17 -> 44.4 | BI16: =IF(BH16>0,1,0) -> 0
